Workbook

Sheet 0_안내
A1: 반려견 행동채점표 · 사용 안내
A3: 02는 AI·사람이 채점하고 수정하는 유일한 원본입니다. 1~20번 점수·관찰 근거·평가자 판정·행사 의견은 이 파일에 기록합니다. 02b·02c는 이 파일을 읽는 보기용이며 별도로 채점하지 않습니다.
A6: 어디에 기록하고 확인하나요
A8: 여러쌍비교 | B8: A열 번호에 맞춰 B열 반려견 이름·C열 견종·나이를 기록합니다. 기존 계산 열 위치를 유지한 전체 대상 비교·리포트 연결표입니다.
A9: 1_바디시그널 | B9: 각 항목의 관찰 시간과 눈금에 따라 J~AC열에 기록합니다. 꼬리 형태·발성·행동 횟수를 서로 다른 관찰로 보존합니다.
A10: 2_개행동 | B10: J~AC열에 행동을 기록합니다. 자동 계산 칸은 직접 입력하지 않습니다. 하단의 애착유형·근거·평가자 기록도 유지합니다.
A11: 3_보호자행동 | B11: 앞에서 당김·뒤처짐 대처를 분리 기록합니다. 유형 배점과 세 유형 근거 비율, 자동 초안, 선택적 수동 판정을 함께 보존합니다.
A12: 6_행사전문가의견 | B12: 대상별 여섯 영역의 의견과 입장 판단을 한 곳에 기록합니다. 작성 후 관찰자·일자와 완료 표시를 확인합니다.
A13: 한마리상세 | B13: B3에서 대상 번호를 고릅니다. 리포트 우선 근거, 기본 유형·수치, 내부 기록, 117개 원항목을 순서대로 확인합니다. 조회 화면에서 점수를 고치지 않습니다.
A14: 성향문장 | B14: 기존 문장 자료와 분리 25개 조합 문장을 관리합니다. 문장은 검토·수정용이며 그 자체로 검증된 유형 판정 기준은 아닙니다.
A17: 촬영·채점 순서
A19: 1 입장 ~30초 1-1 방 문 → 비닐 바닥(폭 전체) → 1-2 새 물건 곁(5초 멈춤) → 의자로 · 물건은 칸막이 뒤라 의자에서 안 보인다 · 의자에서 목줄을 푼다
A20: 2 기준 20초: 목줄을 푼 직후 보호자는 의자에서 안내책자를 읽습니다. 먼저 부르거나 만지지 않고 개가 접촉해 오면 수동적으로 받습니다. 지시된 상태에서의 초기 관찰이며 평소 안정 상태가 아닙니다.오늘 실험 행동의 몸신호의 기준이 된다.
A21: 3 혼자 1분 일어나 문을 열고 나가 문 밖에 있는다 · 1분이 끝나면 바로 돌아온다 (2026-09-26 — 전에는 낯선 사람 구간까지 나가 있었다 · 2026-09-27 — 문이 있어 가림막을 쓰지 않는다)
A22: 4 재회 30초: 문을 연 순간 0초. 0~15초 천천히 이동·착석·대기, 15~30초 무선 신호 뒤 이름 부르기·접촉. 개18은 후반 15초의 몸 상태. 착석 지연·접촉 불성립은 기록.
A23: 5 무시 20초 만져 준 뒤 반응을 끊는다 · 개를 보지 않음 · 말도 걸지 않음
A24: 6 걷기 약 30초: 무시 종료 뒤 이름 1회 후 S로 이동(전환·채점 제외). 리드줄 없이 S→A 4걸음·5초 정지→C 8걸음·5초 정지→S 4걸음·5초 정지. 본 구간에는 말·손짓 없이 걷고 마지막 정지 후 의자에 앉습니다.
A25: 7 낯선 사람 목표 30초: 보호자 착석 후 전환 대기 5초(채점 제외). 안전문 밖 10초 → 문 열기 2초 → 정지선까지 4초 → 이름 1회·제자리 대기 4초 → 접촉 3초+대기 2초 또는 미접촉 대기 5초 → 퇴장 5초. 실제 시각 기록.
A26: 8 퇴장 ~30초 입장 코스를 되짚어 나감 · 새 물건 곁에서 다시 5초 멈춤(두 번째 지나감) → 비닐 바닥 → 방 문
A29: 기록과 해석 규칙
A31: 빈칸은 미관찰·미실시·판독 불가입니다. 0은 실제로 해당 코드나 발생 없음이 관찰된 값입니다. 이유·실제 시각·구간 단축·가림·접촉 미성립은 개59 및 관련 메모에 기록합니다.
A32: 양쪽 코드는 각 행의 행동 범주입니다. 0이 항상 적정 상태인 것은 아니며 코드 간격은 같은 감정의 양을 뜻하지 않습니다. −와 +는 상쇄하지 않고 각각 표시합니다.
... A55: 02b는 구간순, 02c는 구간순·주제별 보기입니다. 원점수·메모·기준·계산 결과를 02에서 읽습니다. 세 파일을 같은 폴더에 두고 02를 먼저 엽니다. 02를 닫고 볼 때는 먼저 저장하고, 보기 파일에서 통합 문서 연결 업데이트를 허용합니다.

Sheet 1_바디시그널
A2: 몸으로 나타나는 신호. 5~13행은 꼬리 · 발성(각성 축)과 「직후 5초」 몸 털기 횟수(8 · 10행), 14~37행은 구간마다 몸 털기 · 하품 · 코 핥기 횟수입니다(참고 · 점수 아님).
A3: J~AC는 1~20번 입력. 열 머리 −2~+2는 양쪽 항목에만 적용. 발성·조건·횟수·초·경로는 각 행의 별도 눈금을 따릅니다. 0과 빈칸을 구분하고 맥락을 기록합니다.
A4: 구간 | B4: 관찰 항목 | C4: −2 | D4: −1 | E4: 0 | F4: +1 | G4: +2 | H4: 영역 | I4: 척도·축 | J4: 1번 | K4: 2번 | L4: 3번 | M4: 4번 | N4: 5번 | O4: 6번 | P4: 7번 | Q4: 8번 | R4: 9번 | S4: 10번 | T4: 11번 | U4: 12번 | V4: 13번 | W4: 14번 | X4: 15번 | Y4: 16번 | Z4: 17번 | AA4: 18번 | AB4: 19번 | AC4: 20번 | AD4: 영역코드 | AY4: 척도
A5: 입장 | B5: [입장] 꼬리 — 위치 ※형태 관찰. 기준 20초(바38)와 원값을 나란히 봄. 기준도 낯선 장소에서의 상태이며 평소 꼬리가 아님. 가림·단미 등 판독 불가면 빈칸. | C5: 다리 사이로 말아 넣음 | D5: 등선보다 아래로 늘어뜨림 — 꼬리끝이 바닥을 가리킴 | E5: 등선 높이 — 꼬리끝이 바닥보다 위 | F5: 등선보다 높이 올라옴 | G5: 등 위로 높이 세우거나 말아 올림 | H5: 별도 관찰 · 꼬리 형태 | I5: 양쪽·위치 | AE5: =0 -> 0 | AF5: =0 -> 0 | AG5: =0 -> 0 | AH5: =0 -> 0 | AI5: =0 -> 0 | AJ5: =0 -> 0 | AK5: =0 -> 0 | AL5: =0 -> 0 | ... AX5: =0 -> 0
A6: 입장 | B6: [입장] 발성량 ※0~3 시간 비중 · 입장 전체. 못 들으면 빈칸; 0은 들었으나 없음. 종류·시각·관찰 초는 메모. 꼬리로 소리 의미를 정하지 않음. | C6: 0 — 발성 없음 | D6: 1 — 발성 누적 비중 0 초과~1/3 이하 | E6: 2 — 1/3 초과~2/3 이하 | F6: 3 — 2/3 초과 | H6: 별도 관찰 · 발성 | I6: 한쪽·발성량 | AE6: =0 -> 0 | AF6: =0 -> 0 | AG6: =0 -> 0 | AH6: =0 -> 0 | AI6: =0 -> 0 | AJ6: =0 -> 0 | AK6: =0 -> 0 | AL6: =0 -> 0 | ... AX6: =0 -> 0 | AY6: ONE
A7: 입장 | B7: [입장] 낯선 바닥 — 꼬리 위치 ※형태 관찰. 기준 20초(바38)와 원값을 나란히 봄. 기준도 낯선 장소에서의 상태이며 평소 꼬리가 아님. 가림·단미 등 판독 불가면 빈칸. | C7: 다리 사이로 말아 넣음 | D7: 등선보다 아래로 늘어뜨림 — 꼬리끝이 바닥을 가리킴 | E7: 등선 높이 — 꼬리끝이 바닥보다 위 | F7: 등선보다 높이 올라옴 | G7: 등 위로 높이 세우거나 말아 올림 | H7: 별도 관찰 · 꼬리 형태 | I7: 양쪽·위치 | AE7: =0 -> 0 | AF7: =0 -> 0 | AG7: =0 -> 0 | AH7: =0 -> 0 | AI7: =0 -> 0 | AJ7: =0 -> 0 | AK7: =0 -> 0 | AL7: =0 -> 0 | ... AX7: =0 -> 0
A8: 입장 | B8: 낯선 바닥 — 몸 털기 ※횟수 · 점수가 아닙니다 | C8: 바닥을 처음 밟은 순간부터 5초 안에 개가 몸을 턴 횟수를 셉니다. 물기를 털듯 온몸을 흔드는 동작입니다. 하품 · 코 핥기는 여기서 세지 않고 아래 구간별 횟수 칸(14~37행)에 적습니다. | H8: — 참고 · 횟수 | I8: 참고 | AE8: =0 -> 0 | AF8: =0 -> 0 | AG8: =0 -> 0 | AH8: =0 -> 0 | AI8: =0 -> 0 | AJ8: =0 -> 0 | AK8: =0 -> 0 | AL8: =0 -> 0 | ... AX8: =0 -> 0
A9: 혼자 | B9: [혼자] 꼬리 — 위치 ※형태 관찰. 기준 20초(바38)와 원값을 나란히 봄. 기준도 낯선 장소에서의 상태이며 평소 꼬리가 아님. 가림·단미 등 판독 불가면 빈칸. | C9: 다리 사이로 말아 넣음 | D9: 등선보다 아래로 늘어뜨림 — 꼬리끝이 바닥을 가리킴 | E9: 등선 높이 — 꼬리끝이 바닥보다 위 | F9: 등선보다 높이 올라옴 | G9: 등 위로 높이 세우거나 말아 올림 | H9: 별도 관찰 · 꼬리 형태 | I9: 양쪽·위치 | AE9: =0 -> 0 | AF9: =0 -> 0 | AG9: =0 -> 0 | AH9: =0 -> 0 | AI9: =0 -> 0 | AJ9: =0 -> 0 | AK9: =0 -> 0 | AL9: =0 -> 0 | ... AX9: =0 -> 0
A10: 혼자 | B10: 분리 — 몸 털기 ※횟수 · 점수가 아닙니다 | C10: 보호자가 나간 순간부터 5초 안에 개가 몸을 턴 횟수를 셉니다. 물기를 털듯 온몸을 흔드는 동작입니다. 하품 · 코 핥기는 여기서 세지 않고 아래 구간별 횟수 칸(14~37행)에 적습니다. | H10: — 참고 · 횟수 | I10: 참고 | AE10: =0 -> 0 | AF10: =0 -> 0 | AG10: =0 -> 0 | AH10: =0 -> 0 | AI10: =0 -> 0 | AJ10: =0 -> 0 | AK10: =0 -> 0 | AL10: =0 -> 0 | ... AX10: =0 -> 0
A11: 낯선 | B11: [낯선] 꼬리 — 위치 ※형태 관찰. 기준 20초(바38)와 원값을 나란히 봄. 기준도 낯선 장소에서의 상태이며 평소 꼬리가 아님. 가림·단미 등 판독 불가면 빈칸. | C11: 다리 사이로 말아 넣음 | D11: 등선보다 아래로 늘어뜨림 — 꼬리끝이 바닥을 가리킴 | E11: 등선 높이 — 꼬리끝이 바닥보다 위 | F11: 등선보다 높이 올라옴 | G11: 등 위로 높이 세우거나 말아 올림 | H11: 별도 관찰 · 꼬리 형태 | I11: 양쪽·위치 | AE11: =0 -> 0 | AF11: =0 -> 0 | AG11: =0 -> 0 | AH11: =0 -> 0 | AI11: =0 -> 0 | AJ11: =0 -> 0 | AK11: =0 -> 0 | AL11: =0 -> 0 | ... AX11: =0 -> 0
A12: 걷기 | B12: [걷기] 꼬리 — 위치 ※형태 관찰. 기준 20초(바38)와 원값을 나란히 봄. 기준도 낯선 장소에서의 상태이며 평소 꼬리가 아님. 가림·단미 등 판독 불가면 빈칸. | C12: 다리 사이로 말아 넣음 | D12: 등선보다 아래로 늘어뜨림 — 꼬리끝이 바닥을 가리킴 | E12: 등선 높이 — 꼬리끝이 바닥보다 위 | F12: 등선보다 높이 올라옴 | G12: 등 위로 높이 세우거나 말아 올림 | H12: 별도 관찰 · 꼬리 형태 | I12: 양쪽·위치 | AE12: =0 -> 0 | AF12: =0 -> 0 | AG12: =0 -> 0 | AH12: =0 -> 0 | AI12: =0 -> 0 | AJ12: =0 -> 0 | AK12: =0 -> 0 | AL12: =0 -> 0 | ... AX12: =0 -> 0
A13: 퇴장 | B13: [퇴장] 꼬리 — 위치 ※형태 관찰. 기준 20초(바38)와 원값을 나란히 봄. 기준도 낯선 장소에서의 상태이며 평소 꼬리가 아님. 가림·단미 등 판독 불가면 빈칸. | C13: 다리 사이로 말아 넣음 | D13: 등선보다 아래로 늘어뜨림 — 꼬리끝이 바닥을 가리킴 | E13: 등선 높이 — 꼬리끝이 바닥보다 위 | F13: 등선보다 높이 올라옴 | G13: 등 위로 높이 세우거나 말아 올림 | H13: 별도 관찰 · 꼬리 형태 | I13: 양쪽·위치 | AE13: =0 -> 0 | AF13: =0 -> 0 | AG13: =0 -> 0 | AH13: =0 -> 0 | AI13: =0 -> 0 | AJ13: =0 -> 0 | AK13: =0 -> 0 | AL13: =0 -> 0 | ... AX13: =0 -> 0
A14: 입장 | B14: [입장] 몸 털기 횟수 ※구간 전체 ~30초 · 참고 | C14: 온몸을 좌우로 빠르게 턴 횟수를 셉니다. 머리만 흔든 것은 빼고, 몸이 안 보인 구간이면 빈칸(0 과 다름). | H14: 별도 관찰 · 행동 횟수 | I14: 참고 | AE14: =0 -> 0 | AF14: =0 -> 0 | AG14: =0 -> 0 | AH14: =0 -> 0 | AI14: =0 -> 0 | AJ14: =0 -> 0 | AK14: =0 -> 0 | AL14: =0 -> 0 | ... AX14: =0 -> 0
A15: 입장 | B15: [입장] 하품 횟수 ※구간 전체 ~30초 · 참고 | C15: 입을 크게 벌렸다 닫은 횟수를 셉니다. 짖음 · 헐떡임과 구분하고, 얼굴이 안 보인 구간이면 빈칸(0 과 다름). | H15: 별도 관찰 · 행동 횟수 | I15: 참고 | AE15: =0 -> 0 | AF15: =0 -> 0 | AG15: =0 -> 0 | AH15: =0 -> 0 | AI15: =0 -> 0 | AJ15: =0 -> 0 | AK15: =0 -> 0 | AL15: =0 -> 0 | ... AX15: =0 -> 0
A16: 입장 | B16: [입장] 코 핥기 횟수 ※구간 전체 ~30초 · 참고 | C16: 혀가 나와 코나 윗입술을 스친 횟수를 셉니다. 1초 이상 떨어져야 따로 세고, 먹이를 먹은 뒤 30초는 세지 않습니다. 얼굴이 안 보이면 빈칸. | H16: 별도 관찰 · 행동 횟수 | I16: 참고 | AE16: =0 -> 0 | AF16: =0 -> 0 | AG16: =0 -> 0 | AH16: =0 -> 0 | AI16: =0 -> 0 | AJ16: =0 -> 0 | AK16: =0 -> 0 | AL16: =0 -> 0 | ... AX16: =0 -> 0
A17: 기준 | B17: [기준] 몸 털기 횟수 ※구간 전체 20초 · 참고 | C17: 온몸을 좌우로 빠르게 턴 횟수를 셉니다. 머리만 흔든 것은 빼고, 몸이 안 보인 구간이면 빈칸(0 과 다름). | H17: 별도 관찰 · 행동 횟수 | I17: 참고 | AE17: =0 -> 0 | AF17: =0 -> 0 | AG17: =0 -> 0 | AH17: =0 -> 0 | AI17: =0 -> 0 | AJ17: =0 -> 0 | AK17: =0 -> 0 | AL17: =0 -> 0 | ... AX17: =0 -> 0
A18: 기준 | B18: [기준] 하품 횟수 ※구간 전체 20초 · 참고 | C18: 입을 크게 벌렸다 닫은 횟수를 셉니다. 짖음 · 헐떡임과 구분하고, 얼굴이 안 보인 구간이면 빈칸(0 과 다름). | H18: 별도 관찰 · 행동 횟수 | I18: 참고 | AE18: =0 -> 0 | AF18: =0 -> 0 | AG18: =0 -> 0 | AH18: =0 -> 0 | AI18: =0 -> 0 | AJ18: =0 -> 0 | AK18: =0 -> 0 | AL18: =0 -> 0 | ... AX18: =0 -> 0
A19: 기준 | B19: [기준] 코 핥기 횟수 ※구간 전체 20초 · 참고 | C19: 혀가 나와 코나 윗입술을 스친 횟수를 셉니다. 1초 이상 떨어져야 따로 세고, 먹이를 먹은 뒤 30초는 세지 않습니다. 얼굴이 안 보이면 빈칸. | H19: 별도 관찰 · 행동 횟수 | I19: 참고 | AE19: =0 -> 0 | AF19: =0 -> 0 | AG19: =0 -> 0 | AH19: =0 -> 0 | AI19: =0 -> 0 | AJ19: =0 -> 0 | AK19: =0 -> 0 | AL19: =0 -> 0 | ... AX19: =0 -> 0
A20: 혼자 | B20: [혼자] 몸 털기 횟수 ※구간 전체 1분 · 참고 | C20: 온몸을 좌우로 빠르게 턴 횟수를 셉니다. 머리만 흔든 것은 빼고, 몸이 안 보인 구간이면 빈칸(0 과 다름). | H20: 별도 관찰 · 행동 횟수 | I20: 참고 | AE20: =0 -> 0 | AF20: =0 -> 0 | AG20: =0 -> 0 | AH20: =0 -> 0 | AI20: =0 -> 0 | AJ20: =0 -> 0 | AK20: =0 -> 0 | AL20: =0 -> 0 | ... AX20: =0 -> 0
A21: 혼자 | B21: [혼자] 하품 횟수 ※구간 전체 1분 · 참고 | C21: 입을 크게 벌렸다 닫은 횟수를 셉니다. 짖음 · 헐떡임과 구분하고, 얼굴이 안 보인 구간이면 빈칸(0 과 다름). | H21: 별도 관찰 · 행동 횟수 | I21: 참고 | AE21: =0 -> 0 | AF21: =0 -> 0 | AG21: =0 -> 0 | AH21: =0 -> 0 | AI21: =0 -> 0 | AJ21: =0 -> 0 | AK21: =0 -> 0 | AL21: =0 -> 0 | ... AX21: =0 -> 0
A22: 혼자 | B22: [혼자] 코 핥기 횟수 ※구간 전체 1분 · 참고 | C22: 혀가 나와 코나 윗입술을 스친 횟수를 셉니다. 1초 이상 떨어져야 따로 세고, 먹이를 먹은 뒤 30초는 세지 않습니다. 얼굴이 안 보이면 빈칸. | H22: 별도 관찰 · 행동 횟수 | I22: 참고 | AE22: =0 -> 0 | AF22: =0 -> 0 | AG22: =0 -> 0 | AH22: =0 -> 0 | AI22: =0 -> 0 | AJ22: =0 -> 0 | AK22: =0 -> 0 | AL22: =0 -> 0 | ... AX22: =0 -> 0
A23: 낯선 | B23: [낯선 사람] 몸 털기 횟수 ※구간 전체 30초 · 참고 | C23: 온몸을 좌우로 빠르게 턴 횟수를 셉니다. 머리만 흔든 것은 빼고, 몸이 안 보인 구간이면 빈칸(0 과 다름). | H23: 별도 관찰 · 행동 횟수 | I23: 참고 | AE23: =0 -> 0 | AF23: =0 -> 0 | AG23: =0 -> 0 | AH23: =0 -> 0 | AI23: =0 -> 0 | AJ23: =0 -> 0 | AK23: =0 -> 0 | AL23: =0 -> 0 | ... AX23: =0 -> 0
A24: 낯선 | B24: [낯선 사람] 하품 횟수 ※구간 전체 30초 · 참고 | C24: 입을 크게 벌렸다 닫은 횟수를 셉니다. 짖음 · 헐떡임과 구분하고, 얼굴이 안 보인 구간이면 빈칸(0 과 다름). | H24: 별도 관찰 · 행동 횟수 | I24: 참고 | AE24: =0 -> 0 | AF24: =0 -> 0 | AG24: =0 -> 0 | AH24: =0 -> 0 | AI24: =0 -> 0 | AJ24: =0 -> 0 | AK24: =0 -> 0 | AL24: =0 -> 0 | ... AX24: =0 -> 0
A25: 낯선 | B25: [낯선 사람] 코 핥기 횟수 ※구간 전체 30초 · 참고 | C25: 혀가 나와 코나 윗입술을 스친 횟수를 셉니다. 1초 이상 떨어져야 따로 세고, 먹이를 먹은 뒤 30초는 세지 않습니다. 얼굴이 안 보이면 빈칸. | H25: 별도 관찰 · 행동 횟수 | I25: 참고 | AE25: =0 -> 0 | AF25: =0 -> 0 | AG25: =0 -> 0 | AH25: =0 -> 0 | AI25: =0 -> 0 | AJ25: =0 -> 0 | AK25: =0 -> 0 | AL25: =0 -> 0 | ... AX25: =0 -> 0
... A37: 퇴장 | B37: [퇴장] 코 핥기 횟수 ※구간 전체 ~30초 · 참고 | C37: 혀가 나와 코나 윗입술을 스친 횟수를 셉니다. 1초 이상 떨어져야 따로 세고, 먹이를 먹은 뒤 30초는 세지 않습니다. 얼굴이 안 보이면 빈칸. | H37: 별도 관찰 · 행동 횟수 | I37: 참고 | AE37: =0 -> 0 | AF37: =0 -> 0 | AG37: =0 -> 0 | AH37: =0 -> 0 | AI37: =0 -> 0 | AJ37: =0 -> 0 | AK37: =0 -> 0 | AL37: =0 -> 0 | ... AX37: =0 -> 0
A38: 기준 | B38: [기준] 꼬리 위치 ※낯선 장소의 기준 20초. 평소 꼬리의 대표값이 아님. 다른 구간과 형태만 비교하며 꼬리 형태·단미·가림은 메모. | C38: 다리 사이로 말아 넣음 | D38: 등선보다 아래로 늘어뜨림 — 꼬리끝이 바닥을 가리킴 | E38: 등선 높이 — 꼬리끝이 바닥보다 위 | F38: 등선보다 높이 올라옴 | G38: 등 위로 높이 세우거나 말아 올림 | H38: 별도 관찰 · 꼬리 형태 | I38: 양쪽·위치 | AE38: =0 -> 0 | AF38: =0 -> 0 | AG38: =0 -> 0 | AH38: =0 -> 0 | AI38: =0 -> 0 | AJ38: =0 -> 0 | AK38: =0 -> 0 | AL38: =0 -> 0 | ... AX38: =0 -> 0
A39: 무시 | B39: [무시] 꼬리 — 위치 ※형태 관찰. 기준 20초(바38)와 원값을 나란히 봄. 기준도 낯선 장소에서의 상태이며 평소 꼬리가 아님. 가림·단미 등 판독 불가면 빈칸. | C39: 다리 사이로 말아 넣음 | D39: 등선보다 아래로 늘어뜨림 — 꼬리끝이 바닥을 가리킴 | E39: 등선 높이 — 꼬리끝이 바닥보다 위 | F39: 등선보다 높이 올라옴 | G39: 등 위로 높이 세우거나 말아 올림 | H39: 별도 관찰 · 꼬리 형태 | I39: 양쪽·위치 | AE39: =0 -> 0 | AF39: =0 -> 0 | AG39: =0 -> 0 | AH39: =0 -> 0 | AI39: =0 -> 0 | AJ39: =0 -> 0 | AK39: =0 -> 0 | AL39: =0 -> 0 | ... AX39: =0 -> 0
A40: 기준 | B40: [기준] 꼬리 움직임 ※낯선 장소의 기준 20초. 원속도 연속 영상으로 관찰. 평소 흔들림·감정의 확정값이 아님. | C40: 몸도 굳고 꼬리 움직임도 멎은 상태가 주된 모습 | D40: 몸은 굳지 않았으나 작은 꼬리 움직임만 간헐적으로 보임 | E40: 편안한 자세로 꼬리가 멈춰 있거나 느리고 넓게 움직임 | F40: 빠른 좌우 움직임이 주된 모습 | G40: 짧은 진폭으로 떨듯 빠른 움직임이 주된 모습 | H40: 별도 관찰 · 꼬리 움직임 | I40: 양쪽·움직임 | AE40: =0 -> 0 | AF40: =0 -> 0 | AG40: =0 -> 0 | AH40: =0 -> 0 | AI40: =0 -> 0 | AJ40: =0 -> 0 | AK40: =0 -> 0 | AL40: =0 -> 0 | ... AX40: =0 -> 0
A41: 낯선 | B41: [낯선] 꼬리 — 흔들림 ※원속도 영상에서 관찰. 빠르기는 영상의 연속 움직임으로 확인하며 초당 5장 추출만으로 판단하지 않음. 감정 확정 금지. | C41: 몸도 굳고 꼬리 움직임도 멎은 상태가 주된 모습 | D41: 몸은 굳지 않았으나 작은 꼬리 움직임만 간헐적으로 보임 | E41: 편안한 자세로 꼬리가 멈춰 있거나 느리고 넓게 움직임 | F41: 빠른 좌우 움직임이 주된 모습 | G41: 짧은 진폭으로 떨듯 빠른 움직임이 주된 모습 | H41: 별도 관찰 · 꼬리 움직임 | I41: 양쪽·움직임 | AE41: =0 -> 0 | AF41: =0 -> 0 | AG41: =0 -> 0 | AH41: =0 -> 0 | AI41: =0 -> 0 | AJ41: =0 -> 0 | AK41: =0 -> 0 | AL41: =0 -> 0 | ... AX41: =0 -> 0
A42: 재회 | B42: [재회 접촉] 꼬리 — 흔들림 ※원속도 영상에서 관찰. 빠르기는 영상의 연속 움직임으로 확인하며 초당 5장 추출만으로 판단하지 않음. 감정 확정 금지. | C42: 몸도 굳고 꼬리 움직임도 멎은 상태가 주된 모습 | D42: 몸은 굳지 않았으나 작은 꼬리 움직임만 간헐적으로 보임 | E42: 편안한 자세로 꼬리가 멈춰 있거나 느리고 넓게 움직임 | F42: 빠른 좌우 움직임이 주된 모습 | G42: 짧은 진폭으로 떨듯 빠른 움직임이 주된 모습 | H42: 별도 관찰 · 꼬리 움직임 | I42: 양쪽·움직임 | AE42: =0 -> 0 | AF42: =0 -> 0 | AG42: =0 -> 0 | AH42: =0 -> 0 | AI42: =0 -> 0 | AJ42: =0 -> 0 | AK42: =0 -> 0 | AL42: =0 -> 0 | ... AX42: =0 -> 0
A43: 재회 | B43: [재회 접촉] 꼬리 — 위치 ※형태 관찰. 기준 20초(바38)와 원값을 나란히 봄. 기준도 낯선 장소에서의 상태이며 평소 꼬리가 아님. 가림·단미 등 판독 불가면 빈칸. | C43: 다리 사이로 말아 넣음 | D43: 등선보다 아래로 늘어뜨림 — 꼬리끝이 바닥을 가리킴 | E43: 등선 높이 — 꼬리끝이 바닥보다 위 | F43: 등선보다 높이 올라옴 | G43: 등 위로 높이 세우거나 말아 올림 | H43: 별도 관찰 · 꼬리 형태 | I43: 양쪽·위치 | AE43: =0 -> 0 | AF43: =0 -> 0 | AG43: =0 -> 0 | AH43: =0 -> 0 | AI43: =0 -> 0 | AJ43: =0 -> 0 | AK43: =0 -> 0 | AL43: =0 -> 0 | ... AX43: =0 -> 0
A44: 입장 | B44: [입장] 새 물건 곁 — 꼬리 위치 ※형태 관찰. 기준 20초(바38)와 원값을 나란히 봄. 기준도 낯선 장소에서의 상태이며 평소 꼬리가 아님. 가림·단미 등 판독 불가면 빈칸. | C44: 다리 사이로 말아 넣음 | D44: 등선보다 아래로 늘어뜨림 — 꼬리끝이 바닥을 가리킴 | E44: 등선 높이 — 꼬리끝이 바닥보다 위 | F44: 등선보다 높이 올라옴 | G44: 등 위로 높이 세우거나 말아 올림 | H44: 별도 관찰 · 꼬리 형태 | I44: 양쪽·위치 | AE44: =0 -> 0 | AF44: =0 -> 0 | AG44: =0 -> 0 | AH44: =0 -> 0 | AI44: =0 -> 0 | AJ44: =0 -> 0 | AK44: =0 -> 0 | AL44: =0 -> 0 | ... AX44: =0 -> 0
A45: 낯선 | B45: [낯선 접촉] 꼬리 — 위치 ※형태 관찰. 기준 20초(바38)와 원값을 나란히 봄. 기준도 낯선 장소에서의 상태이며 평소 꼬리가 아님. 가림·단미 등 판독 불가면 빈칸. | C45: 다리 사이로 말아 넣음 | D45: 등선보다 아래로 늘어뜨림 — 꼬리끝이 바닥을 가리킴 | E45: 등선 높이 — 꼬리끝이 바닥보다 위 | F45: 등선보다 높이 올라옴 | G45: 등 위로 높이 세우거나 말아 올림 | H45: 별도 관찰 · 꼬리 형태 | I45: 양쪽·위치 | AE45: =0 -> 0 | AF45: =0 -> 0 | AG45: =0 -> 0 | AH45: =0 -> 0 | AI45: =0 -> 0 | AJ45: =0 -> 0 | AK45: =0 -> 0 | AL45: =0 -> 0 | ... AX45: =0 -> 0

Sheet 2_개행동
A2: 자극 상황에 대해 실제로 한 행동. 구간마다 방향 하나와 각성 하나를 봅니다.
A3: J~AC는 1~20번 입력. 열 머리 −2~+2는 양쪽 항목에만 적용. 발성·조건·횟수·초·경로는 각 행의 별도 눈금을 따릅니다. 0과 빈칸을 구분하고 맥락을 기록합니다.
A4: 구간 | B4: 관찰 항목 | C4: −2 | D4: −1 | E4: 0 | F4: +1 | G4: +2 | H4: 영역 | I4: 척도·축 | J4: 1번 | K4: 2번 | L4: 3번 | M4: 4번 | N4: 5번 | O4: 6번 | P4: 7번 | Q4: 8번 | R4: 9번 | S4: 10번 | T4: 11번 | U4: 12번 | V4: 13번 | W4: 14번 | X4: 15번 | Y4: 16번 | Z4: 17번 | AA4: 18번 | AB4: 19번 | AC4: 20번 | AD4: 영역코드 | AY4: 척도
A5: 입장 | B5: [입장] 방 문 통과 — 보호자보다 앞서는가 | C5: 문턱 앞 버팀·두번 이상의 유도 및 안기, ·당김은 별도 기록 | D5: 1회 이상의 유도. 자발 통과했으나 보호자 뒤에서 문턱을 넘음 | E5: 보호자와 나란히 문턱을 넘음. 보호자와 약간 뒤나 앞에 있음 | F5: 보호자보다 앞서 걸어 문턱을 넘음 | G5: 앞서 뛰거나 줄이 당겨진 채 문턱을 넘음 | H5: 환경 관찰 | I5: 양쪽·통과 | AD5: SOC_E | AE5: =IF(COUNT(J5)=0,0,J5+3) -> 0 | AF5: =IF(COUNT(K5)=0,0,K5+3) -> 0 | AG5: =IF(COUNT(L5)=0,0,L5+3) -> 0 | AH5: =IF(COUNT(M5)=0,0,M5+3) -> 0 | AI5: =IF(COUNT(N5)=0,0,N5+3) -> 0 | AJ5: =IF(COUNT(O5)=0,0,O5+3) -> 0 | AK5: =IF(COUNT(P5)=0,0,P5+3) -> 0 | AL5: =IF(COUNT(Q5)=0,0,Q5+3) -> 0 | ... AX5: =IF(COUNT(AC5)=0,0,AC5+3) -> 0 | AY5: BI
A6: 입장 | B6: [입장] 비닐 바닥 통과 ※눈에 보인 움직임만 기록. 뛰어서 지난 이유·바닥을 인식했는지는 단정하지 않음. | C6: 바닥 앞 버팀, 두번 이상의 유도 및 안기 | D6: 멈춰 머뭇거린 뒤 천천히 밟음 | E6: 바닥을 살핀 뒤 멈춤 없이 스스로 걸어감 | F6: 바닥을 살피는 모습 없이 걸어감 | G6: 달리거나 뛰어 바닥을 통과 | H6: 환경 관찰 | I6: 양쪽·살핌 | AD6: SOC_E | AE6: =IF(COUNT(J6)=0,0,J6+3) -> 0 | AF6: =IF(COUNT(K6)=0,0,K6+3) -> 0 | AG6: =IF(COUNT(L6)=0,0,L6+3) -> 0 | AH6: =IF(COUNT(M6)=0,0,M6+3) -> 0 | AI6: =IF(COUNT(N6)=0,0,N6+3) -> 0 | AJ6: =IF(COUNT(O6)=0,0,O6+3) -> 0 | AK6: =IF(COUNT(P6)=0,0,P6+3) -> 0 | AL6: =IF(COUNT(Q6)=0,0,Q6+3) -> 0 | ... AX6: =IF(COUNT(AC6)=0,0,AC6+3) -> 0 | AY6: BI
A7: 입장 | B7: [입장] 냄새 — 코를 쓰는가 | C7: 0 — 냄새 맡는 모습 관찰 | D7: 1 — 구간을 볼 수 있었으나 냄새 맡는 모습 없음 | H7: — 참고 · 입장↔퇴장 비교용 | I7: 범주 0/1 | AE7: =0 -> 0 | AF7: =0 -> 0 | AG7: =0 -> 0 | AH7: =0 -> 0 | AI7: =0 -> 0 | AJ7: =0 -> 0 | AK7: =0 -> 0 | AL7: =0 -> 0 | ... AX7: =0 -> 0
A8: 기준 | B8: [기준] 몸 상태 ※목줄을 푼 뒤 20초. 낯선 실험실의 초기 상태이며 평소 안정 상태로 간주하지 않음. | C8: 관찰 가능 시간의 절반 초과 동안 움직임이 멎고 몸이 뻣뻣함 | D8: 절반 초과 동안 낮춘 자세·조심스러운 움직임, 지속 굳음은 없음 | E8: 어느 극단도 절반을 넘지 않음; 주로 자연스러운 자세·이동. 반대 반응 혼재는 메모 | F8: 절반 초과 동안 같은 경로를 반복 이동하거나 자세를 자주 바꿈; 지속 뛰기 수준은 아님 | G8: 절반 초과 동안 뛰기·몸 부딪치기·급한 반복 이동이 이어짐 | H8: — 참고 (기준선) | I8: 양쪽·몸상태 | AE8: =0 -> 0 | AF8: =0 -> 0 | AG8: =0 -> 0 | AH8: =0 -> 0 | AI8: =0 -> 0 | AJ8: =0 -> 0 | AK8: =0 -> 0 | AL8: =0 -> 0 | ... AX8: =0 -> 0
A9: 혼자 | B9: [혼자 초기] 나간 문 쪽 반응 · 보호자의 몸이 완전히 문밖으로 나간 순간부터 처음 10초. C→G 순으로 먼저 해당하는 범주를 선택. 문 지향 반응이며 불안의 단독 증거가 아님. | C9: 문·안전문을 향해 뛰거나 앞발을 걸어 올림 | D9: 위 행동 없이 문을 코·앞발로 건드림 | E9: 접촉 없이 문 앞 몸길이 1개 이내에서 처음 10초 중 합계 5초 초과 머묾 | F9: 문 쪽을 향하거나 다가갔으나 위 행동은 없음 | G9: 문 쪽 방향 전환·접근이 관찰되지 않음 | H9: 분리·재회 · 문 지향 | I9: 양쪽·거리 | AD9: ATT | AE9: =IF(COUNT(J9)=0,0,J9+3) -> 0 | AF9: =IF(COUNT(K9)=0,0,K9+3) -> 0 | AG9: =IF(COUNT(L9)=0,0,L9+3) -> 0 | AH9: =IF(COUNT(M9)=0,0,M9+3) -> 0 | AI9: =IF(COUNT(N9)=0,0,N9+3) -> 0 | AJ9: =IF(COUNT(O9)=0,0,O9+3) -> 0 | AK9: =IF(COUNT(P9)=0,0,P9+3) -> 0 | AL9: =IF(COUNT(Q9)=0,0,Q9+3) -> 0 | ... AX9: =IF(COUNT(AC9)=0,0,AC9+3) -> 0 | AY9: BI
A10: 혼자 | B10: [혼자 이후] 공간 사용 양상 · 처음 10초 이후~60초까지 50초. C→G 순으로 먼저 해당하는 범주를 선택. 아래 초는 이후 50초 안에서 셈. 해당 없음·관찰 불가·구간 단축은 빈칸과 개59 메모. | C10: 문을 긁거나 문·안전문을 넘으려 지속적 시도함 | D10: 가끔씩 코나 앞발로 문을 건들음 | E10: 안전문 앞에 20초 이상 있다가 다른 곳을 둘러봄, 그 뒤 위 두 행동 없이 주로 머물다가 둘러보거나 위치를 바꿈 | F10: 앞선 범주에 해당하지 않고, 안전문 앞에 5초 이상~20초 미만 있다가 다른 곳으로 감. | G10: 위 행동 없이 다른 곳을 살피며 문 쪽으로 돌아오지 않음 | H10: 분리·재회 · 개별 | I10: 범주 · 이후 50초 | AE10: =0 -> 0 | AF10: =0 -> 0 | AG10: =0 -> 0 | AH10: =0 -> 0 | AI10: =0 -> 0 | AJ10: =0 -> 0 | AK10: =0 -> 0 | AL10: =0 -> 0 | ... AX10: =0 -> 0
A11: 혼자 | B11: [혼자] 발성량 ※0~3 시간 비중 · 혼자 실제 구간. 못 들으면 빈칸; 0은 들었으나 없음. 종류·시각·관찰 초는 메모. 꼬리로 소리 의미를 정하지 않음. | C11: 0 — 발성 없음 | D11: 1 — 발성 누적 비중 0 초과~1/3 이하 | E11: 2 — 1/3 초과~2/3 이하 | F11: 3 — 2/3 초과 | H11: 별도 관찰 · 발성 | I11: 한쪽·발성량 | AE11: =0 -> 0 | AF11: =0 -> 0 | AG11: =0 -> 0 | AH11: =0 -> 0 | AI11: =0 -> 0 | AJ11: =0 -> 0 | AK11: =0 -> 0 | AL11: =0 -> 0 | ... AX11: =0 -> 0 | AY11: ONE
A12: 혼자 | B12: [혼자] 탐색 변화 ※보호자 유무의 균형·반복 비교가 아니므로 안전기지 효과의 단독 판정 제외. 실제 탐색 초와 기준·혼자 관찰 가능 초를 개59에 기록. 아래는 참고 범주. | C12: 보호자가 있을 때도 탐색이 거의 없다 | D12: 멀리 떨어지지 않고 탐색한다 | E12: 있을 때 탐색하고 나간 뒤 눈에 띄게 줄어든다 | F12: 잠시 신경 쓰고 탐색한다 | G12: 없어져도 있을 때와 마찬가지로 탐색 | H12: — 참고 (Rehn 2013 · 순서효과) | I12: 참고 | AE12: =0 -> 0 | AF12: =0 -> 0 | AG12: =0 -> 0 | AH12: =0 -> 0 | AI12: =0 -> 0 | AJ12: =0 -> 0 | AK12: =0 -> 0 | AL12: =0 -> 0 | ... AX12: =0 -> 0
A13: 낯선 | B13: [낯선] 안전문 밖 요원 반응 ※첫 10초. 사람 직접 접촉을 채점하지 않음. +2→+1→−2→0→−1 순으로 해당 여부 확인; 반대 반응 혼재는 사건 시각 기록. 이 우선순위는 운영안. 안전문이 불투명하거나 시야가 가리면 미관찰로 기록. | C13: 요원 쪽에서 멀어지거나 뒤로 피하는 반응이 나타남 | D13: 접근하지 않고 시작 위치 부근에서 지켜봄 | E13: 안전문 쪽으로 접근·머묾, 앞발을 걸거나 뛰지 않음 | F13: 안전문에 앞발을 걸거나 1~2회 뛰어오름 | G13: 안전문을 향해 3회 이상 뛰어오름 | H13: 사회성 — 사람 | I13: 양쪽·인사 | AD13: SOC_H | AE13: =IF(COUNT(J13)=0,0,J13+3) -> 0 | AF13: =IF(COUNT(K13)=0,0,K13+3) -> 0 | AG13: =IF(COUNT(L13)=0,0,L13+3) -> 0 | AH13: =IF(COUNT(M13)=0,0,M13+3) -> 0 | AI13: =IF(COUNT(N13)=0,0,N13+3) -> 0 | AJ13: =IF(COUNT(O13)=0,0,O13+3) -> 0 | AK13: =IF(COUNT(P13)=0,0,P13+3) -> 0 | AL13: =IF(COUNT(Q13)=0,0,Q13+3) -> 0 | ... AX13: =IF(COUNT(AC13)=0,0,AC13+3) -> 0 | AY13: BI
A14: 낯선 | B14: [낯선] 몸 상태 ※요원 등장~퇴장 전체의 주된 모습. 접근·접촉·퇴장 단계에서 반대 반응이 있었으면 메모. | C14: 관찰 가능 시간의 절반 초과 동안 움직임이 멎고 몸이 뻣뻣함 | D14: 절반 초과 동안 낮춘 자세·조심스러운 움직임, 지속 굳음은 없음 | E14: 어느 극단도 절반을 넘지 않음; 주로 자연스러운 자세·이동. 반대 반응 혼재는 메모 | F14: 절반 초과 동안 같은 경로를 반복 이동하거나 자세를 자주 바꿈; 지속 뛰기 수준은 아님 | G14: 절반 초과 동안 뛰기·몸 부딪치기·급한 반복 이동이 이어짐 | H14: 사회성 — 사람 | I14: 양쪽·몸상태 | AD14: SOC_H | AE14: =IF(COUNT(J14)=0,0,J14+3) -> 0 | AF14: =IF(COUNT(K14)=0,0,K14+3) -> 0 | AG14: =IF(COUNT(L14)=0,0,L14+3) -> 0 | AH14: =IF(COUNT(M14)=0,0,M14+3) -> 0 | AI14: =IF(COUNT(N14)=0,0,N14+3) -> 0 | AJ14: =IF(COUNT(O14)=0,0,O14+3) -> 0 | AK14: =IF(COUNT(P14)=0,0,P14+3) -> 0 | AL14: =IF(COUNT(Q14)=0,0,Q14+3) -> 0 | ... AX14: =IF(COUNT(AC14)=0,0,AC14+3) -> 0 | AY14: BI
A15: 낯선 | B15: [낯선] 부름 뒤 반응 ※정지선에서 이름 1회 후 4초. 요원은 움직이지 않음. 접근했다면 +1/+2, 접근하지 않았다면 반응 잠재기로 −2/−1/0. 부르기 전 이미 곁에 있으면 접근 변화는 메모. | C15: 4초 안에 고개·몸 방향 전환이나 접근이 없음 | D15: 접근 없이, 부름 후 3초 초과~4초 이내에 처음 고개·몸을 돌림 | E15: 접근 없이, 3초 이내 고개·몸을 돌림 | F15: 요원 쪽으로 다가오되 뛰어오르거나 매달리지 않음 | G15: 다가와 뛰어오르거나 몸·앞발을 올림 | H15: 사회성 — 사람 | I15: 양쪽·인사 | AD15: SOC_H | AE15: =IF(COUNT(J15)=0,0,J15+3) -> 0 | AF15: =IF(COUNT(K15)=0,0,K15+3) -> 0 | AG15: =IF(COUNT(L15)=0,0,L15+3) -> 0 | AH15: =IF(COUNT(M15)=0,0,M15+3) -> 0 | AI15: =IF(COUNT(N15)=0,0,N15+3) -> 0 | AJ15: =IF(COUNT(O15)=0,0,O15+3) -> 0 | AK15: =IF(COUNT(P15)=0,0,P15+3) -> 0 | AL15: =IF(COUNT(Q15)=0,0,Q15+3) -> 0 | ... AX15: =IF(COUNT(AC15)=0,0,AC15+3) -> 0 | AY15: BI
A16: 낯선 | B16: [낯선] 거리 확보·위협 관련 신호 ※0~4 범주. 여러 신호는 가장 큰 코드와 나머지 시각을 기록. 강도의 등간 척도·합산값으로 사용하지 않음. 단독 고개 돌림을 두려움으로 확정하지 않음. | C16: 0 — 아래 신호가 관찰되지 않음; 편안함의 확정은 아님 | D16: 1 — 고개를 돌림 | E16: 2 — 몸을 빼거나 뒤로 물러남 | F16: 3 — 돌아서서 벗어남 · 보호자 뒤나 구석으로 감 | G16: 4 — 으르렁거림 또는 굳은 채 노려봄 | H16: 사회성 — 사람 | I16: 범주 · 신호 | AE16: =0 -> 0 | AF16: =0 -> 0 | AG16: =0 -> 0 | AH16: =0 -> 0 | AI16: =0 -> 0 | AJ16: =0 -> 0 | AK16: =0 -> 0 | AL16: =0 -> 0 | ... AX16: =0 -> 0
A17: 재회 | B17: [재회] 접근·거리 ※문 열림 0~15초, 보호자 이동·착석·대기 중 먼저 부르거나 만지지 않음. 앉는 시점과 관계없이 15초로 고정. | C17: 걸어가는 내내 매달려 떨어지지 않음 | D17: 바로 다가와 몸을 붙임 | E17: 다가와 같이 의자로 걸어감 | F17: 한 번 쳐다보고 만다 | G17: 본체만체 · 오지 않음 | H17: 애착·관계 관찰 | I17: 양쪽·거리 | AD17: ATT | AE17: =IF(COUNT(J17)=0,0,J17+3) -> 0 | AF17: =IF(COUNT(K17)=0,0,K17+3) -> 0 | AG17: =IF(COUNT(L17)=0,0,L17+3) -> 0 | AH17: =IF(COUNT(M17)=0,0,M17+3) -> 0 | AI17: =IF(COUNT(N17)=0,0,N17+3) -> 0 | AJ17: =IF(COUNT(O17)=0,0,O17+3) -> 0 | AK17: =IF(COUNT(P17)=0,0,P17+3) -> 0 | AL17: =IF(COUNT(Q17)=0,0,Q17+3) -> 0 | ... AX17: =IF(COUNT(AC17)=0,0,AC17+3) -> 0 | AY17: BI
A18: 재회 | B18: [재회] 후반 몸 상태 ※문 열림 15~30초, 접촉 지시 구간 전체. 실제 접촉 여부를 별도 기록. 개58과 같은 눈금의 기술적 변화만 계산. | C18: 관찰 가능 시간의 절반 초과 동안 움직임이 멎고 몸이 뻣뻣함 | D18: 절반 초과 동안 낮춘 자세·조심스러운 움직임, 지속 굳음은 없음 | E18: 어느 극단도 절반을 넘지 않음; 주로 자연스러운 자세·이동. 반대 반응 혼재는 메모 | F18: 절반 초과 동안 같은 경로를 반복 이동하거나 자세를 자주 바꿈; 지속 뛰기 수준은 아님 | G18: 절반 초과 동안 뛰기·몸 부딪치기·급한 반복 이동이 이어짐 | H18: 애착·관계 관찰 | I18: 양쪽·몸상태 | AD18: ATT | AE18: =IF(COUNT(J18)=0,0,J18+3) -> 0 | AF18: =IF(COUNT(K18)=0,0,K18+3) -> 0 | AG18: =IF(COUNT(L18)=0,0,L18+3) -> 0 | AH18: =IF(COUNT(M18)=0,0,M18+3) -> 0 | AI18: =IF(COUNT(N18)=0,0,N18+3) -> 0 | AJ18: =IF(COUNT(O18)=0,0,O18+3) -> 0 | AK18: =IF(COUNT(P18)=0,0,P18+3) -> 0 | AL18: =IF(COUNT(Q18)=0,0,Q18+3) -> 0 | ... AX18: =IF(COUNT(AC18)=0,0,AC18+3) -> 0 | AY18: BI
A19: 재회 | B19: [재회 접촉] 몸의 중심 ※15~30초 실제 접촉이 이루어진 시간만. 미접촉이면 빈칸. 낯선 접촉과 부호 방향은 반대이며 시간·자세도 달라 직접 점수 차이를 애착으로 해석하지 않음. | C19: 몸을 얹거나 무릎에 올라감 · 기대어 떨어지지 않음 | D19: 몸이 닿을 만큼 앞으로 붙임 | E19: 앞으로 살짝 기울여 손을 받음 | F19: 선 자리를 지킴 · 몸을 앞으로 옮기지 않음 | G19: 뒤로 물러남 · 옆으로 피함 · 등을 돌림 | H19: 애착·관계 관찰 | I19: 양쪽·거리 | AD19: ATT | AE19: =IF(COUNT(J19)=0,0,J19+3) -> 0 | AF19: =IF(COUNT(K19)=0,0,K19+3) -> 0 | AG19: =IF(COUNT(L19)=0,0,L19+3) -> 0 | AH19: =IF(COUNT(M19)=0,0,M19+3) -> 0 | AI19: =IF(COUNT(N19)=0,0,N19+3) -> 0 | AJ19: =IF(COUNT(O19)=0,0,O19+3) -> 0 | AK19: =IF(COUNT(P19)=0,0,P19+3) -> 0 | AL19: =IF(COUNT(Q19)=0,0,Q19+3) -> 0 | ... AX19: =IF(COUNT(AC19)=0,0,AC19+3) -> 0 | AY19: BI
A20: 재회 | B20: [재회 접촉] 꼬리 ※사용하지 않습니다 (2026-09-22) — 바43(재회 꼬리 — 위치)으로 옮겼습니다 | H20: — 사용 안 함 | I20: 미사용 | AE20: =0 -> 0 | AF20: =0 -> 0 | AG20: =0 -> 0 | AH20: =0 -> 0 | AI20: =0 -> 0 | AJ20: =0 -> 0 | AK20: =0 -> 0 | AL20: =0 -> 0 | ... AX20: =0 -> 0 | AY20: BI
A21: 재회 | B21: [재회] 접근 변화 사건 횟수 ※멈춤·고개 돌림·지나침·되돌아섬·굳음을 사건으로 기록. 연속 동작은 1건, 다시 접근을 시작한 뒤 별도 발생하면 추가. 유형·시각은 메모. 1건으로 전체 분류를 무효화하지 않음. | C21: 0은 관찰 가능했으나 해당 사건 없음. 빈칸은 판독 불가. 횟수는 개별 검토 근거이며 애착 혼란의 진단 기준이 아님. | H21: 별도 관찰 · 사건 횟수 | I21: 참고 | AE21: =0 -> 0 | AF21: =0 -> 0 | AG21: =0 -> 0 | AH21: =0 -> 0 | AI21: =0 -> 0 | AJ21: =0 -> 0 | AK21: =0 -> 0 | AL21: =0 -> 0 | ... AX21: =0 -> 0
A22: 무시 | B22: [무시] 보호자와의 거리·확인 ※접촉 종료 뒤 20초. 보12 조건을 함께 확인. 거리 유지와 시선이 함께 든 기존 범주이며 단일 친밀감·애착 강도는 아님. | C22: 무릎에 올라감 · 몸을 얹고 떨어지지 않음 | D22: 몸이 닿는 거리로 붙어 있음 | E22: 주변 1 m 안에 있으며 가끔 확인 | F22: 떨어져 있고 가끔만 쳐다봄 | G22: 한 번도 쳐다보지 않음 · 혼자 다님 | H22: 애착·관계 관찰 | I22: 양쪽·거리 | AD22: ATT | AE22: =IF(COUNT(J22)=0,0,J22+3) -> 0 | AF22: =IF(COUNT(K22)=0,0,K22+3) -> 0 | AG22: =IF(COUNT(L22)=0,0,L22+3) -> 0 | AH22: =IF(COUNT(M22)=0,0,M22+3) -> 0 | AI22: =IF(COUNT(N22)=0,0,N22+3) -> 0 | AJ22: =IF(COUNT(O22)=0,0,O22+3) -> 0 | AK22: =IF(COUNT(P22)=0,0,P22+3) -> 0 | AL22: =IF(COUNT(Q22)=0,0,Q22+3) -> 0 | ... AX22: =IF(COUNT(AC22)=0,0,AC22+3) -> 0 | AY22: BI
A23: 무시 | B23: [무시] 몸 상태 ※접촉 종료 뒤 20초. 개8과 같은 눈금. 실험 이력·무시 지시의 영향이 함께 포함됨. | C23: 관찰 가능 시간의 절반 초과 동안 움직임이 멎고 몸이 뻣뻣함 | D23: 절반 초과 동안 낮춘 자세·조심스러운 움직임, 지속 굳음은 없음 | E23: 어느 극단도 절반을 넘지 않음; 주로 자연스러운 자세·이동. 반대 반응 혼재는 메모 | F23: 절반 초과 동안 같은 경로를 반복 이동하거나 자세를 자주 바꿈; 지속 뛰기 수준은 아님 | G23: 절반 초과 동안 뛰기·몸 부딪치기·급한 반복 이동이 이어짐 | H23: 애착·관계 관찰 | I23: 양쪽·몸상태 | AD23: ATT | AE23: =IF(COUNT(J23)=0,0,J23+3) -> 0 | AF23: =IF(COUNT(K23)=0,0,K23+3) -> 0 | AG23: =IF(COUNT(L23)=0,0,L23+3) -> 0 | AH23: =IF(COUNT(M23)=0,0,M23+3) -> 0 | AI23: =IF(COUNT(N23)=0,0,N23+3) -> 0 | AJ23: =IF(COUNT(O23)=0,0,O23+3) -> 0 | AK23: =IF(COUNT(P23)=0,0,P23+3) -> 0 | AL23: =IF(COUNT(Q23)=0,0,Q23+3) -> 0 | ... AX23: =IF(COUNT(AC23)=0,0,AC23+3) -> 0 | AY23: BI
A24: 걷기 | B24: [걷기] 주된 거리 ※구간 시간 절반 초과를 차지한 범주. 한 번 멀어진 것만으로 전체 +1로 정하지 않음. 동률이면 시작 범주·혼재 사유 기록. | C24: 접촉하며 다리에 매달리거나 몸을 얹은 상태가 주됨 | D24: 비접촉이나 몸길이 1개 미만으로 붙어 이동 | E24: 몸길이 1개 이상~2개 이내 | F24: 몸길이 2개 초과~5개 이내 | G24: 몸길이 5개 초과 | H24: 행동 동조 | I24: 양쪽·거리 | AD24: SYN | AE24: =IF(COUNT(J24)=0,0,J24+3) -> 0 | AF24: =IF(COUNT(K24)=0,0,K24+3) -> 0 | AG24: =IF(COUNT(L24)=0,0,L24+3) -> 0 | AH24: =IF(COUNT(M24)=0,0,M24+3) -> 0 | AI24: =IF(COUNT(N24)=0,0,N24+3) -> 0 | AJ24: =IF(COUNT(O24)=0,0,O24+3) -> 0 | AK24: =IF(COUNT(P24)=0,0,P24+3) -> 0 | AL24: =IF(COUNT(Q24)=0,0,Q24+3) -> 0 | ... AX24: =IF(COUNT(AC24)=0,0,AC24+3) -> 0 | AY24: BI
A25: 걷기 | B25: [걷기] 보호자 확인 ※시선 관찰만. 개24·근접 비율에 합산하지 않음. 친밀감·의존의 직접 판정으로 사용하지 않음. | C25: 계속 올려다봄 · 앞을 보지 않음 | D25: 자주 올려다보며 걸음 | E25: 이동 중 여러 번 확인하고 다시 앞을 봄 | F25: 한두 번 힐끗 | G25: 한 번도 쳐다보지 않음 | H25: 행동 동조 — 참고 | I25: 양쪽·살핌 | AE25: =0 -> 0 | AF25: =0 -> 0 | AG25: =0 -> 0 | AH25: =0 -> 0 | AI25: =0 -> 0 | AJ25: =0 -> 0 | AK25: =0 -> 0 | AL25: =0 -> 0 | ... AX25: =0 -> 0 | AY25: BI
A26: 걷기 | B26: [걷기] 이동 — 곁에 있던 국면 수 ※자동 계산 · 입력하지 마세요 | C26: 이동 3국면(38 · 40 · 42행) 가운데 거리 등급이 1 이하였던 국면 수(0~3). 몸길이 2개 안에서 함께 이동한 국면입니다. | H26: — 참고 (영역 집계 제외) | I26: 참고 | J26: =IF(COUNT(J38,J40,J42)<3,"",IF(J38<=1,1,0)+IF(J40<=1,1,0)+IF(J42<=1,1,0)) | K26: =IF(COUNT(K38,K40,K42)<3,"",IF(K38<=1,1,0)+IF(K40<=1,1,0)+IF(K42<=1,1,0)) | L26: =IF(COUNT(L38,L40,L42)<3,"",IF(L38<=1,1,0)+IF(L40<=1,1,0)+IF(L42<=1,1,0)) | M26: =IF(COUNT(M38,M40,M42)<3,"",IF(M38<=1,1,0)+IF(M40<=1,1,0)+IF(M42<=1,1,0)) | N26: =IF(COUNT(N38,N40,N42)<3,"",IF(N38<=1,1,0)+IF(N40<=1,1,0)+IF(N42<=1,1,0)) | O26: =IF(COUNT(O38,O40,O42)<3,"",IF(O38<=1,1,0)+IF(O40<=1,1,0)+IF(O42<=1,1,0)) | P26: =IF(COUNT(P38,P40,P42)<3,"",IF(P38<=1,1,0)+IF(P40<=1,1,0)+IF(P42<=1,1,0)) | Q26: =IF(COUNT(Q38,Q40,Q42)<3,"",IF(Q38<=1,1,0)+IF(Q40<=1,1,0)+IF(Q42<=1,1,0)) | ... AC26: =IF(COUNT(AC38,AC40,AC42)<3,"",IF(AC38<=1,1,0)+IF(AC40<=1,1,0)+IF(AC42<=1,1,0)) | AE26: =0 -> 0 | AF26: =0 -> 0 | AG26: =0 -> 0 | AH26: =0 -> 0 | AI26: =0 -> 0 | AJ26: =0 -> 0 | AK26: =0 -> 0 | AL26: =0 -> 0 | ... AX26: =0 -> 0
A27: 걷기 | B27: [걷기] 근접 국면 비율 ※자동. 사람·AI 공통 항목으로 사용 가능. 상태 전환 동조율과 다름. | C27: 이동·정지 6국면 중 거리 등급 0/1인 국면 ÷ 6. 6칸 모두 관찰되고 보13이 1/2일 때 산출. 보13=3이면 무효, 미입력이면 보류. | H27: — 참고 (영역 집계 제외) | I27: 참고 | J27: =IF(COUNT('3_보호자행동'!J13)=0,"",IF('3_보호자행동'!J13=3,"무효",IF(COUNT(J26,J36)<2,"",(J26+J36)/6))) | K27: =IF(COUNT('3_보호자행동'!K13)=0,"",IF('3_보호자행동'!K13=3,"무효",IF(COUNT(K26,K36)<2,"",(K26+K36)/6))) | L27: =IF(COUNT('3_보호자행동'!L13)=0,"",IF('3_보호자행동'!L13=3,"무효",IF(COUNT(L26,L36)<2,"",(L26+L36)/6))) | M27: =IF(COUNT('3_보호자행동'!M13)=0,"",IF('3_보호자행동'!M13=3,"무효",IF(COUNT(M26,M36)<2,"",(M26+M36)/6))) | N27: =IF(COUNT('3_보호자행동'!N13)=0,"",IF('3_보호자행동'!N13=3,"무효",IF(COUNT(N26,N36)<2,"",(N26+N36)/6))) | O27: =IF(COUNT('3_보호자행동'!O13)=0,"",IF('3_보호자행동'!O13=3,"무효",IF(COUNT(O26,O36)<2,"",(O26+O36)/6))) | P27: =IF(COUNT('3_보호자행동'!P13)=0,"",IF('3_보호자행동'!P13=3,"무효",IF(COUNT(P26,P36)<2,"",(P26+P36)/6))) | Q27: =IF(COUNT('3_보호자행동'!Q13)=0,"",IF('3_보호자행동'!Q13=3,"무효",IF(COUNT(Q26,Q36)<2,"",(Q26+Q36)/6))) | ... AC27: =IF(COUNT('3_보호자행동'!AC13)=0,"",IF('3_보호자행동'!AC13=3,"무효",IF(COUNT(AC26,AC36)<2,"",(AC26+AC36)/6))) | AE27: =0 -> 0 | AF27: =0 -> 0 | AG27: =0 -> 0 | AH27: =0 -> 0 | AI27: =0 -> 0 | AJ27: =0 -> 0 | AK27: =0 -> 0 | AL27: =0 -> 0 | ... AX27: =0 -> 0
A28: 퇴장 | B28: [퇴장] 문 통과 ※입장 개5와 같은 관찰 기준. 앞서 나감의 이유나 환경 적응을 이 한 항목으로 정하지 않음. | C28: 문턱 앞 버팀·우회로 자발 통과하지 못함; 유도·안기·당김은 별도 기록 | D28: 자발 통과했으나 보호자 뒤에서 문턱을 넘음 | E28: 보호자와 나란히 문턱을 넘음 | F28: 보호자보다 앞서 걸어 문턱을 넘음 | G28: 앞서 뛰거나 줄이 당겨진 채 문턱을 넘음 | H28: 퇴장 — 환경 적응 | I28: 양쪽·통과 | AD28: EXIT | AE28: =IF(COUNT(J28)=0,0,J28+3) -> 0 | AF28: =IF(COUNT(K28)=0,0,K28+3) -> 0 | AG28: =IF(COUNT(L28)=0,0,L28+3) -> 0 | AH28: =IF(COUNT(M28)=0,0,M28+3) -> 0 | AI28: =IF(COUNT(N28)=0,0,N28+3) -> 0 | AJ28: =IF(COUNT(O28)=0,0,O28+3) -> 0 | AK28: =IF(COUNT(P28)=0,0,P28+3) -> 0 | AL28: =IF(COUNT(Q28)=0,0,Q28+3) -> 0 | ... AX28: =IF(COUNT(AC28)=0,0,AC28+3) -> 0 | AY28: BI
A29: 퇴장 | B29: [퇴장] 냄새 — 나가면서 코를 쓰는가 | C29: 0 — 냄새 맡는 모습 관찰 | D29: 1 — 구간을 볼 수 있었으나 냄새 맡는 모습 없음 | H29: — 참고 · 입장↔퇴장 비교용 | I29: 범주 0/1 | AE29: =0 -> 0 | AF29: =0 -> 0 | AG29: =0 -> 0 | AH29: =0 -> 0 | AI29: =0 -> 0 | AJ29: =0 -> 0 | AK29: =0 -> 0 | AL29: =0 -> 0 | ... AX29: =0 -> 0
A30: 입장 | B30: [입장] 새 물건 반응 ※5초 정지+통과. +2→−2→−1→0→+1 순으로 확인. 여러 반응이면 순서·시각 기록. 정지 신호와 목줄 유도 조건은 보14 확인. | C30: 버티거나 뒷걸음·큰 우회로 물건에서 거리를 벌림 | D30: 위 행동 없이 목을 길게 빼 살피거나 머뭇거리지만 코 접촉 없음 | E30: 위 행동 없이 살피거나 코 접촉 후 정지 시간을 함께 보내고 보호자가 이동하면 따라감 | F30: 위 행동 없이 곧장 코 접촉하고 정지 시간 중 물건을 지나쳐 이동함 | G30: 물건을 향해 뛰거나 당겨 발·몸·입으로 강하게 접촉함 | H30: 환경 관찰 | I30: 양쪽·살핌 | AD30: SOC_E | AE30: =IF(COUNT(J30)=0,0,J30+3) -> 0 | AF30: =IF(COUNT(K30)=0,0,K30+3) -> 0 | AG30: =IF(COUNT(L30)=0,0,L30+3) -> 0 | AH30: =IF(COUNT(M30)=0,0,M30+3) -> 0 | AI30: =IF(COUNT(N30)=0,0,N30+3) -> 0 | AJ30: =IF(COUNT(O30)=0,0,O30+3) -> 0 | AK30: =IF(COUNT(P30)=0,0,P30+3) -> 0 | AL30: =IF(COUNT(Q30)=0,0,Q30+3) -> 0 | ... AX30: =IF(COUNT(AC30)=0,0,AC30+3) -> 0 | AY30: BI
A31: 입장 | B31: [입장] 개 모양 물체 곁 지나감 ※장면 1-3 · 낯선 개 반응이 아닙니다 ※사용하지 않습니다 (2026-09-22) — 개 모양 물체를 절차에서 뺐습니다 | H31: — 사용 안 함 | I31: 미사용 | AE31: =0 -> 0 | AF31: =0 -> 0 | AG31: =0 -> 0 | AH31: =0 -> 0 | AI31: =0 -> 0 | AJ31: =0 -> 0 | AK31: =0 -> 0 | AL31: =0 -> 0 | ... AX31: =0 -> 0 | AY31: BI
A32: 입장 | B32: [입장] 새 물건 — 첫 코 접촉 ※초 · 참고 | C32: 물건 1 m 앞에 들어선 순간부터 코가 처음 닿기까지 걸린 초를 적습니다. 멈춘 5초가 끝날 때까지 닿지 않으면 99. | H32: — 참고 (영역 집계 제외) | I32: 참고 | AE32: =0 -> 0 | AF32: =0 -> 0 | AG32: =0 -> 0 | AH32: =0 -> 0 | AI32: =0 -> 0 | AJ32: =0 -> 0 | AK32: =0 -> 0 | AL32: =0 -> 0 | ... AX32: =0 -> 0
A33: 입장 | B33: [입장] 개 모양 물체 — 첫 코 접촉 ※초 · 참고 ※사용하지 않습니다 (2026-09-22) — 개 모양 물체를 절차에서 뺐습니다 | H33: — 사용 안 함 | I33: 미사용 | AE33: =0 -> 0 | AF33: =0 -> 0 | AG33: =0 -> 0 | AH33: =0 -> 0 | AI33: =0 -> 0 | AJ33: =0 -> 0 | AK33: =0 -> 0 | AL33: =0 -> 0 | ... AX33: =0 -> 0
A34: 퇴장 | B34: [퇴장] 새 물건 반응 ※5초 정지+통과. +2→−2→−1→0→+1 순으로 확인. 여러 반응이면 순서·시각 기록. 정지 신호와 목줄 유도 조건은 보14 확인. | C34: 버티거나 뒷걸음·큰 우회로 물건에서 거리를 벌림 | D34: 위 행동 없이 목을 길게 빼 살피거나 머뭇거리지만 코 접촉 없음 | E34: 위 행동 없이 살피거나 코 접촉 후 정지 시간을 함께 보내고 보호자가 이동하면 따라감 | F34: 위 행동 없이 곧장 코 접촉하고 정지 시간 중 물건을 지나쳐 이동함 | G34: 물건을 향해 뛰거나 당겨 발·몸·입으로 강하게 접촉함 | H34: 퇴장 — 환경 적응 | I34: 양쪽·살핌 | AD34: EXIT | AE34: =IF(COUNT(J34)=0,0,J34+3) -> 0 | AF34: =IF(COUNT(K34)=0,0,K34+3) -> 0 | AG34: =IF(COUNT(L34)=0,0,L34+3) -> 0 | AH34: =IF(COUNT(M34)=0,0,M34+3) -> 0 | AI34: =IF(COUNT(N34)=0,0,N34+3) -> 0 | AJ34: =IF(COUNT(O34)=0,0,O34+3) -> 0 | AK34: =IF(COUNT(P34)=0,0,P34+3) -> 0 | AL34: =IF(COUNT(Q34)=0,0,Q34+3) -> 0 | ... AX34: =IF(COUNT(AC34)=0,0,AC34+3) -> 0 | AY34: BI
A35: 퇴장 | B35: [퇴장] 개 모양 물체 — 두 번째 곁 지나감 ※입장과 같게 5초 멈춤 ※사용하지 않습니다 (2026-09-22) — 개 모양 물체를 절차에서 뺐습니다 | H35: — 사용 안 함 | I35: 미사용 | AE35: =0 -> 0 | AF35: =0 -> 0 | AG35: =0 -> 0 | AH35: =0 -> 0 | AI35: =0 -> 0 | AJ35: =0 -> 0 | AK35: =0 -> 0 | AL35: =0 -> 0 | ... AX35: =0 -> 0 | AY35: BI
A36: 걷기 | B36: [걷기] 정지 — 곁에 있던 국면 수 ※자동 계산 · 입력하지 마세요 | C36: 정지 3국면(39 · 41 · 43행) 가운데 거리 등급이 1 이하였던 국면 수(0~3). 보호자가 멈춘 동안 곁에 있던 국면입니다. | H36: — 참고 (영역 집계 제외) | I36: 참고 | J36: =IF(COUNT(J39,J41,J43)<3,"",IF(J39<=1,1,0)+IF(J41<=1,1,0)+IF(J43<=1,1,0)) | K36: =IF(COUNT(K39,K41,K43)<3,"",IF(K39<=1,1,0)+IF(K41<=1,1,0)+IF(K43<=1,1,0)) | L36: =IF(COUNT(L39,L41,L43)<3,"",IF(L39<=1,1,0)+IF(L41<=1,1,0)+IF(L43<=1,1,0)) | M36: =IF(COUNT(M39,M41,M43)<3,"",IF(M39<=1,1,0)+IF(M41<=1,1,0)+IF(M43<=1,1,0)) | N36: =IF(COUNT(N39,N41,N43)<3,"",IF(N39<=1,1,0)+IF(N41<=1,1,0)+IF(N43<=1,1,0)) | O36: =IF(COUNT(O39,O41,O43)<3,"",IF(O39<=1,1,0)+IF(O41<=1,1,0)+IF(O43<=1,1,0)) | P36: =IF(COUNT(P39,P41,P43)<3,"",IF(P39<=1,1,0)+IF(P41<=1,1,0)+IF(P43<=1,1,0)) | Q36: =IF(COUNT(Q39,Q41,Q43)<3,"",IF(Q39<=1,1,0)+IF(Q41<=1,1,0)+IF(Q43<=1,1,0)) | ... AC36: =IF(COUNT(AC39,AC41,AC43)<3,"",IF(AC39<=1,1,0)+IF(AC41<=1,1,0)+IF(AC43<=1,1,0)) | AE36: =0 -> 0 | AF36: =0 -> 0 | AG36: =0 -> 0 | AH36: =0 -> 0 | AI36: =0 -> 0 | AJ36: =0 -> 0 | AK36: =0 -> 0 | AL36: =0 -> 0 | ... AX36: =0 -> 0
A37: 걷기 | B37: [걷기] 0 시작 — 첫 걸음 직전 ※거리 등급 0~3 | C37: 0 실제 신체 접촉 / 1 비접촉~개 몸길이 2개 이내 / 2 몸길이 2개 초과~5개 이내 / 3 몸길이 5개 초과. 사람 양발 중점과 개 몸통 중심을 기준으로 원근 보정. 이동·정지는 주된 시간의 범주, 시작은 첫걸음 직전. 가려 못 보면 빈칸. | H37: — 참고 (영역 집계 제외) | I37: 참고 | AE37: =0 -> 0 | AF37: =0 -> 0 | AG37: =0 -> 0 | AH37: =0 -> 0 | AI37: =0 -> 0 | AJ37: =0 -> 0 | AK37: =0 -> 0 | AL37: =0 -> 0 | ... AX37: =0 -> 0
A38: 걷기 | B38: [걷기] 1 이동 S→A (오른쪽 4걸음) ※거리 등급 0~3 | C38: 0 실제 신체 접촉 / 1 비접촉~개 몸길이 2개 이내 / 2 몸길이 2개 초과~5개 이내 / 3 몸길이 5개 초과. 사람 양발 중점과 개 몸통 중심을 기준으로 원근 보정. 이동·정지는 주된 시간의 범주, 시작은 첫걸음 직전. 가려 못 보면 빈칸. | H38: — 참고 (영역 집계 제외) | I38: 참고 | AE38: =0 -> 0 | AF38: =0 -> 0 | AG38: =0 -> 0 | AH38: =0 -> 0 | AI38: =0 -> 0 | AJ38: =0 -> 0 | AK38: =0 -> 0 | AL38: =0 -> 0 | ... AX38: =0 -> 0
A39: 걷기 | B39: [걷기] 2 정지 A — 다시 걷기 전까지 ※거리 등급 0~3 | C39: 0 실제 신체 접촉 / 1 비접촉~개 몸길이 2개 이내 / 2 몸길이 2개 초과~5개 이내 / 3 몸길이 5개 초과. 사람 양발 중점과 개 몸통 중심을 기준으로 원근 보정. 이동·정지는 주된 시간의 범주, 시작은 첫걸음 직전. 가려 못 보면 빈칸. | H39: — 참고 (영역 집계 제외) | I39: 참고 | AE39: =0 -> 0 | AF39: =0 -> 0 | AG39: =0 -> 0 | AH39: =0 -> 0 | AI39: =0 -> 0 | AJ39: =0 -> 0 | AK39: =0 -> 0 | AL39: =0 -> 0 | ... AX39: =0 -> 0
A40: 걷기 | B40: [걷기] 3 이동 A→C (왼쪽 8걸음 · S 지나감) ※거리 등급 0~3 | C40: 0 실제 신체 접촉 / 1 비접촉~개 몸길이 2개 이내 / 2 몸길이 2개 초과~5개 이내 / 3 몸길이 5개 초과. 사람 양발 중점과 개 몸통 중심을 기준으로 원근 보정. 이동·정지는 주된 시간의 범주, 시작은 첫걸음 직전. 가려 못 보면 빈칸. | H40: — 참고 (영역 집계 제외) | I40: 참고 | AE40: =0 -> 0 | AF40: =0 -> 0 | AG40: =0 -> 0 | AH40: =0 -> 0 | AI40: =0 -> 0 | AJ40: =0 -> 0 | AK40: =0 -> 0 | AL40: =0 -> 0 | ... AX40: =0 -> 0
A41: 걷기 | B41: [걷기] 4 정지 C — 다시 걷기 전까지 ※거리 등급 0~3 | C41: 0 실제 신체 접촉 / 1 비접촉~개 몸길이 2개 이내 / 2 몸길이 2개 초과~5개 이내 / 3 몸길이 5개 초과. 사람 양발 중점과 개 몸통 중심을 기준으로 원근 보정. 이동·정지는 주된 시간의 범주, 시작은 첫걸음 직전. 가려 못 보면 빈칸. | H41: — 참고 (영역 집계 제외) | I41: 참고 | AE41: =0 -> 0 | AF41: =0 -> 0 | AG41: =0 -> 0 | AH41: =0 -> 0 | AI41: =0 -> 0 | AJ41: =0 -> 0 | AK41: =0 -> 0 | AL41: =0 -> 0 | ... AX41: =0 -> 0
...

Sheet 3_보호자행동
A1: 아스트라 전체 수정안 · 보호자 상호작용·3유형 기록 · 2026-09-28
A2: 보호자 행동은 항목별로 채점합니다. 유형은 아래 44~49행의 기준을 보고 51~70행에서 허용형·조율형·통제형 중 선택하고 근거를 적습니다. 보22는 회피 신호, 보24는 개가 찾아온 기회가 있을 때만 채점합니다.
A3: J~AC는 1~20번 입력. 열 머리 −2~+2는 양쪽 항목에만 적용. 발성·조건·횟수·초·경로는 각 행의 별도 눈금을 따릅니다. 0과 빈칸을 구분하고 맥락을 기록합니다.
A4: 구간 | B4: 관찰 항목 | C4: −2 | D4: −1 | E4: 0 | F4: +1 | G4: +2 | H4: 영역 | I4: 척도·축 | J4: 1번 | K4: 2번 | L4: 3번 | M4: 4번 | N4: 5번 | O4: 6번 | P4: 7번 | Q4: 8번 | R4: 9번 | S4: 10번 | T4: 11번 | U4: 12번 | V4: 13번 | W4: 14번 | X4: 15번 | Y4: 16번 | Z4: 17번 | AA4: 18번 | AB4: 19번 | AC4: 20번 | AD4: 영역코드 | AY4: 척도
A5: 앞 당김 | B5: 앞에서 줄을 당길 때의 요청 표현. 실제 발화로 −1/0/+1 분류. 음량·어조·반복은 별도 메모. 발화 없음·요청 없음·판독 불가·기회 없음은 빈칸+사유. 여러 사건의 건수·시각은 개59에 기록. | C5: −2 미사용 | D5: −1 부탁·제안: 질문·청유·부탁으로 행동 요청. 예: “와 줄래?”, “같이 가자”. 같은 사건에서 직접 지시 없음. | E5: 0 혼합: 같은 당김 사건에서 부탁·제안과 직접 지시가 모두 확인됨. 순서 기록. 미발화·모호함을 0으로 넣지 않음. | F5: +1 직접 지시: 할 행동·멈출 행동을 직접 말함. 예: “기다려”, “이리 와”, “당기지 마”. 같은 사건에서 부탁·제안 없음. | G5: +2 미사용 | H5: 보호자 상호작용 · 보조 근거 | I5: 범주 · 요청 표현 | AE5: =0 -> 0 | AF5: =0 -> 0 | AG5: =0 -> 0 | AH5: =0 -> 0 | AI5: =0 -> 0 | AJ5: =0 -> 0 | AK5: =0 -> 0 | AL5: =0 -> 0 | ... AX5: =0 -> 0 | AY5: BI
A6: 전 구간 | B6: 앞에서 당기는 개에 대한 줄 대처 ※당김이 발생한 사건. 줄 팽팽함의 원인을 보호자 힘으로 추정하지 않음. 복수 사건은 개59 또는 보25~27에 시각·상반 반응 기록. | C6: 개가 가는 쪽으로 보호자가 이동해 줄 길이·거리를 맞춤 | D6: 현 위치에서 멈추어 기다림; 보호자가 줄을 당겨 이동시키지 않음 | E6: 멈추어 부르거나 유도한 뒤 개가 돌아오면 이동 | F6: 줄을 짧게 당긴 뒤 즉시 풀어 줌 | G6: 당긴 줄을 유지하거나 반복 당겨 개 몸을 이동시킴 | H6: 보호자 상호작용 · 개별 | I6: 양쪽 · 개입 정도 | AE6: =0 -> 0 | AF6: =0 -> 0 | AG6: =0 -> 0 | AH6: =0 -> 0 | AI6: =0 -> 0 | AJ6: =0 -> 0 | AK6: =0 -> 0 | AL6: =0 -> 0 | ... AX6: =0 -> 0 | AY6: BI
A7: 전 구간 | I7: 미사용 | AE7: =IF($J7="",0,IF(INDEX($C7:$G7,$J7+3)="",0,$J7+3)) -> 0 | AF7: =IF($K7="",0,IF(INDEX($C7:$G7,$K7+3)="",0,$K7+3)) -> 0 | AG7: =IF($L7="",0,IF(INDEX($C7:$G7,$L7+3)="",0,$L7+3)) -> 0 | AH7: =IF($M7="",0,IF(INDEX($C7:$G7,$M7+3)="",0,$M7+3)) -> 0 | AI7: =IF($N7="",0,IF(INDEX($C7:$G7,$N7+3)="",0,$N7+3)) -> 0 | AJ7: =IF($O7="",0,IF(INDEX($C7:$G7,$O7+3)="",0,$O7+3)) -> 0 | AK7: =IF($P7="",0,IF(INDEX($C7:$G7,$P7+3)="",0,$P7+3)) -> 0 | AL7: =IF($Q7="",0,IF(INDEX($C7:$G7,$Q7+3)="",0,$Q7+3)) -> 0 | AM7: =IF($R7="",0,IF(INDEX($C7:$G7,$R7+3)="",0,$R7+3)) -> 0 | AN7: =IF($S7="",0,IF(INDEX($C7:$G7,$S7+3)="",0,$S7+3)) -> 0 | AO7: =IF($T7="",0,IF(INDEX($C7:$G7,$T7+3)="",0,$T7+3)) -> 0 | AP7: =IF($U7="",0,IF(INDEX($C7:$G7,$U7+3)="",0,$U7+3)) -> 0 | AQ7: =IF($V7="",0,IF(INDEX($C7:$G7,$V7+3)="",0,$V7+3)) -> 0 | AR7: =IF($W7="",0,IF(INDEX($C7:$G7,$W7+3)="",0,$W7+3)) -> 0 | AS7: =IF($X7="",0,IF(INDEX($C7:$G7,$X7+3)="",0,$X7+3)) -> 0 | AT7: =IF($Y7="",0,IF(INDEX($C7:$G7,$Y7+3)="",0,$Y7+3)) -> 0 | AU7: =IF($Z7="",0,IF(INDEX($C7:$G7,$Z7+3)="",0,$Z7+3)) -> 0 | AV7: =IF($AA7="",0,IF(INDEX($C7:$G7,$AA7+3)="",0,$AA7+3)) -> 0 | AW7: =IF($AB7="",0,IF(INDEX($C7:$G7,$AB7+3)="",0,$AB7+3)) -> 0 | AX7: =IF($AC7="",0,IF(INDEX($C7:$G7,$AC7+3)="",0,$AC7+3)) -> 0
A8: 전 구간 | I8: 미사용 | AE8: =IF($J8="",0,IF(INDEX($C8:$G8,$J8+3)="",0,$J8+3)) -> 0 | AF8: =IF($K8="",0,IF(INDEX($C8:$G8,$K8+3)="",0,$K8+3)) -> 0 | AG8: =IF($L8="",0,IF(INDEX($C8:$G8,$L8+3)="",0,$L8+3)) -> 0 | AH8: =IF($M8="",0,IF(INDEX($C8:$G8,$M8+3)="",0,$M8+3)) -> 0 | AI8: =IF($N8="",0,IF(INDEX($C8:$G8,$N8+3)="",0,$N8+3)) -> 0 | AJ8: =IF($O8="",0,IF(INDEX($C8:$G8,$O8+3)="",0,$O8+3)) -> 0 | AK8: =IF($P8="",0,IF(INDEX($C8:$G8,$P8+3)="",0,$P8+3)) -> 0 | AL8: =IF($Q8="",0,IF(INDEX($C8:$G8,$Q8+3)="",0,$Q8+3)) -> 0 | AM8: =IF($R8="",0,IF(INDEX($C8:$G8,$R8+3)="",0,$R8+3)) -> 0 | AN8: =IF($S8="",0,IF(INDEX($C8:$G8,$S8+3)="",0,$S8+3)) -> 0 | AO8: =IF($T8="",0,IF(INDEX($C8:$G8,$T8+3)="",0,$T8+3)) -> 0 | AP8: =IF($U8="",0,IF(INDEX($C8:$G8,$U8+3)="",0,$U8+3)) -> 0 | AQ8: =IF($V8="",0,IF(INDEX($C8:$G8,$V8+3)="",0,$V8+3)) -> 0 | AR8: =IF($W8="",0,IF(INDEX($C8:$G8,$W8+3)="",0,$W8+3)) -> 0 | AS8: =IF($X8="",0,IF(INDEX($C8:$G8,$X8+3)="",0,$X8+3)) -> 0 | AT8: =IF($Y8="",0,IF(INDEX($C8:$G8,$Y8+3)="",0,$Y8+3)) -> 0 | AU8: =IF($Z8="",0,IF(INDEX($C8:$G8,$Z8+3)="",0,$Z8+3)) -> 0 | AV8: =IF($AA8="",0,IF(INDEX($C8:$G8,$AA8+3)="",0,$AA8+3)) -> 0 | AW8: =IF($AB8="",0,IF(INDEX($C8:$G8,$AB8+3)="",0,$AB8+3)) -> 0 | AX8: =IF($AC8="",0,IF(INDEX($C8:$G8,$AC8+3)="",0,$AC8+3)) -> 0
A9: 전 구간 | B9: 뒤처지거나 버티는 개에 대한 줄 대처 ※버팀 사건이 있을 때. 안아 옮김은 이 축과 별도 메모. 복수 반응은 사건별 시각을 남기고 주된 반응을 선택. | C9: 개 쪽으로 되돌아가 줄을 느슨하게 함 | D9: 현 위치에서 줄을 느슨하게 두고 기다림 | E9: 줄이 느슨한 상태에서 말·허용된 유도 수단으로 이동을 요청 | F9: 줄을 짧게 당겼다 풀어 이동을 요청 | G9: 줄을 당긴 상태로 유지해 개 몸을 이동시킴 | H9: 보호자 상호작용 · 개별 | I9: 양쪽 · 개입 정도 | AE9: =0 -> 0 | AF9: =0 -> 0 | AG9: =0 -> 0 | AH9: =0 -> 0 | AI9: =0 -> 0 | AJ9: =0 -> 0 | AK9: =0 -> 0 | AL9: =0 -> 0 | ... AX9: =0 -> 0 | AY9: BI
A10: 혼자 | B10: [분리] 출입문으로 나가기 전 상호작용 · G→C 순으로 먼저 해당하는 범주 선택. 말·접촉 동시 또는 연속 상호작용은 1회, 멈췄다가 다시 시작하면 새 1회. 횟수·시각은 개59 메모. 숫자는 행동 종류 코드임. | C10: -2 (범주): 개를 바라보거나 말·접촉을 하지 않고 나감 | D10: -1 (범주): 개를 바라보지만 말·접촉 없이 나감 | E10: 0 (범주): 말 또는 접촉을 1회 하고 나감 | F10: +1 (범주): 말 또는 접촉을 2회 하고 나감 | G10: +2 (범주): 말 또는 접촉을 3회 이상 하거나, 이동 중 멈추거나 되돌아와 다시 상호작용함 | H10: 보호자 유형 판정 근거 (점수 합계 제외) | I10: 범주 · 유형 근거 | AE10: =0 -> 0 | AF10: =0 -> 0 | AG10: =0 -> 0 | AH10: =0 -> 0 | AI10: =0 -> 0 | AJ10: =0 -> 0 | AK10: =0 -> 0 | AL10: =0 -> 0 | ... AX10: =0 -> 0
A11: 재회 | B11: [재회] 신체접촉 방식 · 후반 15초. G→C 순으로 먼저 해당하는 범주 선택. 칭찬 톤·횟수, 밀어 내려보냄, 접촉이 없었던 이유는 개59 메모. 보22 회피 후 대응과 함께 유형 판단에 사용. 숫자는 행동 종류 코드임. | C11: -2 (범주): 손으로 만지거나 몸을 밀착하는 인사 접촉이 관찰되지 않음 | D11: -1 (범주): 상체를 크게 기울이지 않고 손으로 만짐 | E11: 0 (범주): 개 쪽으로 상체를 기울여 가까이에서 만짐 | F11: +1 (범주): 개가 먼저 몸을 기대거나 앞발을 올리는 등 밀착을 시도하면 받아주거나 받쳐 줌 | G11: +2 (범주): 개의 밀착 시도 전에 보호자가 먼저 안아 올리거나 끌어안아 몸·얼굴을 밀착함 | H11: 보호자 유형 판정 근거 (점수 합계 제외) | I11: 범주 · 유형 근거 | AE11: =0 -> 0 | AF11: =0 -> 0 | AG11: =0 -> 0 | AH11: =0 -> 0 | AI11: =0 -> 0 | AJ11: =0 -> 0 | AK11: =0 -> 0 | AL11: =0 -> 0 | ... AX11: =0 -> 0
A12: 무시 | B12: [무시] 지시 준수 ※참고 · 조건 준수 확인 · 이 칸만 1~3 입니다 | C12: 20초 동안 말·시선·접촉 없음 — 유효 | D12: 한 번 보거나 말함 — 유효(주의) | E12: 두 번 이상 · 만짐 — 이 시행의 무시 항목 무효 | H12: — 참고 (영역 집계 제외) | I12: 참고 | AE12: =0 -> 0 | AF12: =0 -> 0 | AG12: =0 -> 0 | AH12: =0 -> 0 | AI12: =0 -> 0 | AJ12: =0 -> 0 | AK12: =0 -> 0 | AL12: =0 -> 0 | ... AX12: =0 -> 0
A13: 걷기 | B13: [걷기] 시행 유효성 ※참고 · 조건 준수 확인 · 이 칸만 1~3 입니다 | C13: 걷기 구간(약 30초) 동안 말·손짓 없음 — 유효 | D13: 한 번 부르거나 손짓함 — 유효(주의) | E13: 두 번 이상 — 이 시행의 걷기 항목과 동조율 무효 | H13: — 참고 (영역 집계 제외) | I13: 참고 | AE13: =0 -> 0 | AF13: =0 -> 0 | AG13: =0 -> 0 | AH13: =0 -> 0 | AI13: =0 -> 0 | AJ13: =0 -> 0 | AK13: =0 -> 0 | AL13: =0 -> 0 | ... AX13: =0 -> 0
A14: 입장 | B14: [물건] 조건 준수 ※입장·퇴장 각 5초. 복지 중단과 단순 지시 이탈은 메모로 구분. 코드3이면 물건 비교 보류. 제외된 개 모양 물체 항목은 채점하지 않음. | C14: 입장·퇴장 모두 물건 앞에서 5초 · 말·손짓·끌기 없이 멈춤 — 유효 | D14: 한 번 말하거나 짧게 멈춤 — 유효(주의) | E14: 멈춤 미실시·유도/끌기 등 조건 이탈 — 개30·32·34 비교 보류 | H14: — 참고 (영역 집계 제외) | I14: 참고 | AE14: =0 -> 0 | AF14: =0 -> 0 | AG14: =0 -> 0 | AH14: =0 -> 0 | AI14: =0 -> 0 | AJ14: =0 -> 0 | AK14: =0 -> 0 | AL14: =0 -> 0 | ... AX14: =0 -> 0
A15: 보16·17·18은 실제 행동 발생 기록입니다. 보19·20·21은 삭제했습니다. 보22는 재회 회피 대응, 보23은 앉은 상태의 지시, 보24는 개가 찾아온 뒤 접촉 대응입니다. | AE15: 0 | AF15: 0 | AG15: 0 | AH15: 0 | AI15: 0 | AJ15: 0 | AK15: 0 | AL15: 0 | AM15: 0 | AN15: 0 | AO15: 0 | AP15: 0 | AQ15: 0 | AR15: 0 | AS15: 0 | AT15: 0 | AU15: 0 | AV15: 0 | AW15: 0 | AX15: 0
A16: 낯선 | B16: [낯선] 보호자 — 개에게 말을 걸거나 이름을 불렀다 ※0 또는 1 · 발생 기록 · 해당하면 1 | C16: 0 — 하지 않았다 | D16: 1 — 했다 | H16: 발생 기록 · 보23·24의 근거 | I16: 참고 | AE16: =0 -> 0 | AF16: =0 -> 0 | AG16: =0 -> 0 | AH16: =0 -> 0 | AI16: =0 -> 0 | AJ16: =0 -> 0 | AK16: =0 -> 0 | AL16: =0 -> 0 | ... AX16: =0 -> 0
A17: 낯선 | B17: [낯선] 보호자 — 개를 붙잡거나 안아 올렸다 ※0 또는 1 · 발생 기록 · 해당하면 1 | C17: 0 — 하지 않았다 | D17: 1 — 했다 | H17: 발생 기록 · 보23·24의 근거 | I17: 참고 | AE17: =0 -> 0 | AF17: =0 -> 0 | AG17: =0 -> 0 | AH17: =0 -> 0 | AI17: =0 -> 0 | AJ17: =0 -> 0 | AK17: =0 -> 0 | AL17: =0 -> 0 | ... AX17: =0 -> 0
A18: 낯선 | B18: [낯선] 보호자 — 일어서거나 자리를 옮겼다 (개 앞으로 몸을 옮긴 것 포함) ※0 또는 1 · 발생 기록 · 해당하면 1 | C18: 0 — 하지 않았다 | D18: 1 — 했다 | H18: 발생 기록 · 착석 상태 확인 | I18: 조건 기록 | AE18: =0 -> 0 | AF18: =0 -> 0 | AG18: =0 -> 0 | AH18: =0 -> 0 | AI18: =0 -> 0 | AJ18: =0 -> 0 | AK18: =0 -> 0 | AL18: =0 -> 0 | ... AX18: =0 -> 0
A22: 재회 | B22: [재회] 회피 뒤 접촉 변화 ※후반 15초 중 개가 고개·몸을 돌리거나 물러난 첫 명확한 사건 뒤 대응. 보38=2/3일 때만. 접근만 있었다면 채점하지 않음. | C22: 손을 완전히 거두고 상체도 뒤로 옮겨 거리를 넓힘 | D22: 손 움직임·접촉을 멈추거나 손을 떼되 상체 위치 유지 | E22: 손을 기존 위치에 둔 채 접촉 방식을 바꾸지 않음 | F22: 물러나는 개를 따라 손을 뻗어 접촉을 이어감 | G22: 개 몸을 붙잡거나 안아 움직임을 제한하며 접촉 지속 | H22: 상호작용 · 시범 핵심 | I22: 양쪽 · 개입 정도 | AE22: =0 -> 0 | AF22: =0 -> 0 | AG22: =0 -> 0 | AH22: =0 -> 0 | AI22: =0 -> 0 | AJ22: =0 -> 0 | AK22: =0 -> 0 | AL22: =0 -> 0 | ... AX22: =0 -> 0
A23: 낯선 | B23: [낯선] 앉은 상태의 지시 방식. 말·손짓으로 행동을 요청한 정도. G→C 순으로 선택. 반복은 같은 행동을 다시 요청한 횟수. 전 구간 관찰 시만 무지시 선택. 직원 지시·안전 조치는 별도 메모. | C23: −2: 개에게 행동을 요청하는 말·손짓 없이 개의 행동을 지켜봄 | D23: −1: 말·손짓으로 한 번 요청한 뒤 같은 요청을 반복하지 않음 | E23: 0: 같은 행동을 두 번 요청함. 목소리·손짓의 강도를 높이지 않음 | F23: +1: 같은 행동을 세 번 이상 요청함. 목소리·손짓의 강도를 높이지 않음 | G23: +2: 요청을 반복하면서 목소리를 높이거나 손짓을 더 크게·급하게 함 | H23: 보호자 유형 판정 근거 (점수 합계 제외) | I23: 양쪽 · 지시 정도 | AE23: =0 -> 0 | AF23: =0 -> 0 | AG23: =0 -> 0 | AH23: =0 -> 0 | AI23: =0 -> 0 | AJ23: =0 -> 0 | AK23: =0 -> 0 | AL23: =0 -> 0 | ... AX23: =0 -> 0
A24: 낯선 | B24: [낯선] 찾아온 개에 대한 접촉 대응 v0.2. 보40=1/2일 때. 개가 먼저 시작한 접촉·움직임을 따르는지, 이후 접근·회피 신호에 따라 대응을 바꾸는지 구분. 해당 근거가 없으면 빈칸+사유. | C24: -2 (범주): 다가온 개를 밀어내거나 몸을 옮겨 접촉을 피함 | D24: −1: 개가 먼저 기대거나 앞발을 올리는 접촉을 받아 주고, 개가 움직이는 대로 몸·손 위치를 맞춤. 보호자가 새 접촉 형태·방향을 요구하지 않음. | E24: 0: 개의 추가 접근·회피·멈춤을 확인한 뒤 접촉을 시작·멈추거나 방법을 바꿈. 변화 전후의 개 신호와 대응을 보27에 기록. | F24: +1 (범주): 개가 머무는 동안 보호자가 반복해서 쓰다듬거나 접촉 유지 | G24: +2 (범주): 개를 붙잡거나 안아 올려 보호자 곁에 머물게 함 | H24: 보호자 유형 판정 근거 (점수 합계 제외) | I24: 범주 · 유형 근거 | AE24: =0 -> 0 | AF24: =0 -> 0 | AG24: =0 -> 0 | AH24: =0 -> 0 | AI24: =0 -> 0 | AJ24: =0 -> 0 | AK24: =0 -> 0 | AL24: =0 -> 0 | ... AX24: =0 -> 0
A25: 기록 | B25: 보22 사유・시각 | C25: 재회 회피·접근 사건 시각 / 개 신호 → 보호자 대응. 보39=1·2를 가른 근거와 보22와 같은 사건인지 기록. 접근 기회·판독 불가 사유. | AE25: =0 -> 0 | AF25: =0 -> 0 | AG25: =0 -> 0 | AH25: =0 -> 0 | AI25: =0 -> 0 | AJ25: =0 -> 0 | AK25: =0 -> 0 | AL25: =0 -> 0 | ... AX25: =0 -> 0
A26: 기록 | B26: 보23 사유・시각 | C26: 실제 말·손짓, 요청 횟수·시각, 직전 개 행동과 반응 후 지시를 멈추거나 바꿨는지 기록. 지시가 필요할 상황이 없었는지도 구분. 관찰 불가면 보23 빈칸. | AE26: =0 -> 0 | AF26: =0 -> 0 | AG26: =0 -> 0 | AH26: =0 -> 0 | AI26: =0 -> 0 | AJ26: =0 -> 0 | AK26: =0 -> 0 | AL26: =0 -> 0 | ... AX26: =0 -> 0
A27: 기록 | B27: 보24 사유・시각 | C27: 첫 접근 시각 / 개가 요구한 접촉 / 보호자가 그대로 맞춘 행동 / 이후 신호에 따라 바꾼 행동. 단순 접촉 수용을 조율로 간주하지 않음. −1과 0이 함께 있으면 신호와 대응 변화가 확인된 0을 우선. | AE27: =0 -> 0 | AF27: =0 -> 0 | AG27: =0 -> 0 | AH27: =0 -> 0 | AI27: =0 -> 0 | AJ27: =0 -> 0 | AK27: =0 -> 0 | AL27: =0 -> 0 | ... AX27: =0 -> 0
A29: 보22·24는 기회가 있는 첫 명확한 사건의 대응을 기록하는 운영안입니다. 이후 다른 반응은 사유에 기록. 양쪽 코드는 움직임 방향·접촉 관여이며 좋고 나쁨 또는 등간 척도로 검증되지 않았습니다.
A30: 보38: 0 접근·회피 모두 없음 / 1 접근만 / 2 회피만 / 3 둘 다. 보22는 2 또는 3인 경우만 입력합니다. 기회 없음·판독 불가를 0점으로 넣지 않습니다.
A31: 보22는 첫 회피 사건 직후부터 다음 분명한 개 행동 전까지의 대응. 여러 행동이 이어지면 가장 마지막에 도달한 범주를 기록하고 전체 순서를 시각과 함께 남깁니다. 이 기록 규칙은 예비 채점에서 확인해야 합니다.
A32: 보23은 직접 입력합니다. 옛 차단·유도 보41·42와 자동 차감 수식은 삭제했습니다. 숫자 0은 조율형을 뜻하지 않으며, 지시할 상황이 없었던 무지시를 허용형 근거로 단정하지 않습니다.
A33: 보40: 0 찾아오지 않음 / 1 찾아와 머물며 회피 없음 / 2 찾아온 뒤 접촉 중 회피 / 3 판독 불가. 보24는 1 또는 2만 입력. 보24의 +값은 접촉량·제한 방식이며 과잉이나 나쁜 태도의 판정이 아닙니다.
A34: 안전 확보·복지 중단 목적의 행동은 그 맥락을 반드시 남깁니다. 중단 뒤 조치는 태도 점수에서 제외. 보호자의 자연스러운 행동과 지시된 행동을 혼동하지 않습니다.
A35: 재회 지시: 신호 뒤 이름을 한 번 부르고 평소처럼 만져 주세요. 개가 명확히 회피·굳음·으르렁을 보이면 접촉을 멈춥니다. 보22는 지시 전부터 자발적으로 발생한 대응만 관찰하며 직원 중단 신호 뒤 행동은 제외합니다.
A36: 낯선 사람은 보호자 착석·전환 대기 5초 뒤 시작(운영 제안). 보호자는 앉아서 자연스럽게 반응합니다. 개입은 원관찰에 남기되 통합 비교 조건과 구분합니다.
A37: 보5는 앞 당김 사건의 요청 표현(−1/0/+1)입니다. 어조·반복은 개59 메모. 보6 앞 당김과 보9 뒤처짐·버팀은 별도 항목으로 유지합니다. 보5를 부호 합계로 유형 점수에 직접 더하지 않습니다.
A38: 재회 | B38: 보22 관찰 기회 ※0~3. 개가 보인 사건, 보호자의 좋고 나쁨 아님. | C38: 0 — 접근·회피 모두 없음 | D38: 1 — 접근만 있었음 | E38: 2 — 회피만 있었음 | F38: 3 — 접근·회피 모두 있었음 | H38: 조건 기록 | I38: 기회 | AE38: =0 -> 0 | AF38: =0 -> 0 | AG38: =0 -> 0 | AH38: =0 -> 0 | AI38: =0 -> 0 | AJ38: =0 -> 0 | AK38: =0 -> 0 | AL38: =0 -> 0 | ... AX38: =0 -> 0
A39: 재회 | B39: [재회] 자발적 접근 뒤 접촉 대응 v0.2. 보38=1/3일 때. 개가 먼저 시작한 접촉에 맞춤과 이후 신호에 따른 대응 변화를 구분. 보22와 같은 사건이면 같은 재회 장면 안에서 평균. | C39: 0 — 접근을 막거나 피함 | D39: 1 — 개가 기대거나 올라오는 접촉을 받아 주고, 개 움직임에 몸·손 위치를 맞춤. 보호자가 다른 접촉 형태·방향을 요구하지 않음 | E39: 2 — 개의 추가 접근·회피·멈춤 신호를 확인한 뒤 접촉을 시작·멈추거나 방법을 바꿈. 신호와 대응 변화 기록 | F39: 3 — 붙잡거나 안아 올림 | H39: 보호자 유형 배점 근거 | I39: 범주 | AE39: =0 -> 0 | AF39: =0 -> 0 | AG39: =0 -> 0 | AH39: =0 -> 0 | AI39: =0 -> 0 | AJ39: =0 -> 0 | AK39: =0 -> 0 | AL39: =0 -> 0 | ... AX39: =0 -> 0
A40: 낯선 | B40: 보24 관찰 기회 ※0~3. 찾아온 뒤 개의 반응을 먼저 기록. | C40: 0 — 보호자에게 찾아오지 않음 | D40: 1 — 찾아와 머물며 접촉 회피 없음 | E40: 2 — 찾아온 뒤 접촉 중 회피가 있었음 | F40: 3 — 개의 반응 판독 불가 | H40: 조건 기록 | I40: 기회 | AE40: =0 -> 0 | AF40: =0 -> 0 | AG40: =0 -> 0 | AH40: =0 -> 0 | AI40: =0 -> 0 | AJ40: =0 -> 0 | AK40: =0 -> 0 | AL40: =0 -> 0 | ... AX40: =0 -> 0
A44: 보호자 3유형 · 자동 초안이 먼저 나오고, 채점자가 고르면 그것이 이깁니다
A45: 허용형 | C45: 개의 선택을 주로 따르며 행동 방향을 정하거나 제한하는 개입이 적게 관찰됨. 보10·11의 상호작용·접촉 방식과 줄 대처·재회 대응을 함께 봅니다. 접촉이 많다는 이유만으로 허용형으로 정하지 않으며, 개입할 기회와 지시된 무반응을 구분합니다.
A46: 조율형 | C46: 개의 접근·회피·멈춤 등 신호에 맞춰 기다림·안내·제한을 바꾸는 모습이 관찰됨. 보10·11의 상호작용 시작·접촉 방식에 보22·38·39의 대응을 대조해 “개 신호 → 보호자 대응 변화”를 기록합니다. 중간 코드나 반대 점수의 혼합을 뜻하지 않습니다.
A47: 통제형 | C47: 보호자가 정한 방향으로 개의 이동·접촉을 유도하거나 제한하는 개입이 주로 관찰됨. 보10·11의 상호작용 주도와 줄·회피 대응을 함께 봅니다. 먼저 안아 올림·큰 목소리 하나만으로 정하지 않으며, 안전 확보와 실험 지시를 구분합니다.
...

Sheet 6_행사전문가의견
A1: 행사 관찰 의견
A2: 관찰한 영역만 적고 관찰자·일자와 완료 표시를 남깁니다. 완료된 의견은 해당 영역의 리포트에 우선 반영하며, 빈 영역은 기존 AI 관찰 근거를 사용합니다. 입장 판단도 각 대상의 같은 입력란에서 작성합니다.
A5: 번호 | B5: 반려견 | C5: 기록 상태 | D5: 입력 위치 | E5: 관찰자·일자 | F5: 입장 판단
A6: 1 | B6: =IF(LEN(TRIM(여러쌍비교!B6&""))=0,"",여러쌍비교!B6) | C6: =E40 -> 미작성 | D6: =HYPERLINK("#'6_행사전문가의견'!A30","1번 작성") -> 1번 작성 | E6: =IF(LEN(TRIM(C31&""))=0,"",C31) | F6: =IF(LEN(TRIM(B42&""))=0,"미입력",IF(E40<>"완료","작성 중",IF(AND(OR(B42="주저함 · 거리를 벌림",B42="뚜렷한 치우침 없음",B42="살피지 않고 들이닥침",B42="자극에 따라 다름",B42="판단보류"),LEN(TRIM(B43&""))>0),"반영","입력 확인"))) -> 미입력
A7: 2 | B7: =IF(LEN(TRIM(여러쌍비교!B7&""))=0,"",여러쌍비교!B7) | C7: =E56 -> 미작성 | D7: =HYPERLINK("#'6_행사전문가의견'!A46","2번 작성") -> 2번 작성 | E7: =IF(LEN(TRIM(C47&""))=0,"",C47) | F7: =IF(LEN(TRIM(B58&""))=0,"미입력",IF(E56<>"완료","작성 중",IF(AND(OR(B58="주저함 · 거리를 벌림",B58="뚜렷한 치우침 없음",B58="살피지 않고 들이닥침",B58="자극에 따라 다름",B58="판단보류"),LEN(TRIM(B59&""))>0),"반영","입력 확인"))) -> 미입력
A8: 3 | B8: =IF(LEN(TRIM(여러쌍비교!B8&""))=0,"",여러쌍비교!B8) | C8: =E72 -> 미작성 | D8: =HYPERLINK("#'6_행사전문가의견'!A62","3번 작성") -> 3번 작성 | E8: =IF(LEN(TRIM(C63&""))=0,"",C63) | F8: =IF(LEN(TRIM(B74&""))=0,"미입력",IF(E72<>"완료","작성 중",IF(AND(OR(B74="주저함 · 거리를 벌림",B74="뚜렷한 치우침 없음",B74="살피지 않고 들이닥침",B74="자극에 따라 다름",B74="판단보류"),LEN(TRIM(B75&""))>0),"반영","입력 확인"))) -> 미입력
A9: 4 | B9: =IF(LEN(TRIM(여러쌍비교!B9&""))=0,"",여러쌍비교!B9) | C9: =E88 -> 미작성 | D9: =HYPERLINK("#'6_행사전문가의견'!A78","4번 작성") -> 4번 작성 | E9: =IF(LEN(TRIM(C79&""))=0,"",C79) | F9: =IF(LEN(TRIM(B90&""))=0,"미입력",IF(E88<>"완료","작성 중",IF(AND(OR(B90="주저함 · 거리를 벌림",B90="뚜렷한 치우침 없음",B90="살피지 않고 들이닥침",B90="자극에 따라 다름",B90="판단보류"),LEN(TRIM(B91&""))>0),"반영","입력 확인"))) -> 미입력
A10: 5 | B10: =IF(LEN(TRIM(여러쌍비교!B10&""))=0,"",여러쌍비교!B10) | C10: =E104 -> 미작성 | D10: =HYPERLINK("#'6_행사전문가의견'!A94","5번 작성") -> 5번 작성 | E10: =IF(LEN(TRIM(C95&""))=0,"",C95) | F10: =IF(LEN(TRIM(B106&""))=0,"미입력",IF(E104<>"완료","작성 중",IF(AND(OR(B106="주저함 · 거리를 벌림",B106="뚜렷한 치우침 없음",B106="살피지 않고 들이닥침",B106="자극에 따라 다름",B106="판단보류"),LEN(TRIM(B107&""))>0),"반영","입력 확인"))) -> 미입력
A11: 6 | B11: =IF(LEN(TRIM(여러쌍비교!B11&""))=0,"",여러쌍비교!B11) | C11: =E120 -> 미작성 | D11: =HYPERLINK("#'6_행사전문가의견'!A110","6번 작성") -> 6번 작성 | E11: =IF(LEN(TRIM(C111&""))=0,"",C111) | F11: =IF(LEN(TRIM(B122&""))=0,"미입력",IF(E120<>"완료","작성 중",IF(AND(OR(B122="주저함 · 거리를 벌림",B122="뚜렷한 치우침 없음",B122="살피지 않고 들이닥침",B122="자극에 따라 다름",B122="판단보류"),LEN(TRIM(B123&""))>0),"반영","입력 확인"))) -> 미입력
A12: 7 | B12: =IF(LEN(TRIM(여러쌍비교!B12&""))=0,"",여러쌍비교!B12) | C12: =E136 -> 미작성 | D12: =HYPERLINK("#'6_행사전문가의견'!A126","7번 작성") -> 7번 작성 | E12: =IF(LEN(TRIM(C127&""))=0,"",C127) | F12: =IF(LEN(TRIM(B138&""))=0,"미입력",IF(E136<>"완료","작성 중",IF(AND(OR(B138="주저함 · 거리를 벌림",B138="뚜렷한 치우침 없음",B138="살피지 않고 들이닥침",B138="자극에 따라 다름",B138="판단보류"),LEN(TRIM(B139&""))>0),"반영","입력 확인"))) -> 미입력
A13: 8 | B13: =IF(LEN(TRIM(여러쌍비교!B13&""))=0,"",여러쌍비교!B13) | C13: =E152 -> 미작성 | D13: =HYPERLINK("#'6_행사전문가의견'!A142","8번 작성") -> 8번 작성 | E13: =IF(LEN(TRIM(C143&""))=0,"",C143) | F13: =IF(LEN(TRIM(B154&""))=0,"미입력",IF(E152<>"완료","작성 중",IF(AND(OR(B154="주저함 · 거리를 벌림",B154="뚜렷한 치우침 없음",B154="살피지 않고 들이닥침",B154="자극에 따라 다름",B154="판단보류"),LEN(TRIM(B155&""))>0),"반영","입력 확인"))) -> 미입력
A14: 9 | B14: =IF(LEN(TRIM(여러쌍비교!B14&""))=0,"",여러쌍비교!B14) | C14: =E168 -> 미작성 | D14: =HYPERLINK("#'6_행사전문가의견'!A158","9번 작성") -> 9번 작성 | E14: =IF(LEN(TRIM(C159&""))=0,"",C159) | F14: =IF(LEN(TRIM(B170&""))=0,"미입력",IF(E168<>"완료","작성 중",IF(AND(OR(B170="주저함 · 거리를 벌림",B170="뚜렷한 치우침 없음",B170="살피지 않고 들이닥침",B170="자극에 따라 다름",B170="판단보류"),LEN(TRIM(B171&""))>0),"반영","입력 확인"))) -> 미입력
A15: 10 | B15: =IF(LEN(TRIM(여러쌍비교!B15&""))=0,"",여러쌍비교!B15) | C15: =E184 -> 미작성 | D15: =HYPERLINK("#'6_행사전문가의견'!A174","10번 작성") -> 10번 작성 | E15: =IF(LEN(TRIM(C175&""))=0,"",C175) | F15: =IF(LEN(TRIM(B186&""))=0,"미입력",IF(E184<>"완료","작성 중",IF(AND(OR(B186="주저함 · 거리를 벌림",B186="뚜렷한 치우침 없음",B186="살피지 않고 들이닥침",B186="자극에 따라 다름",B186="판단보류"),LEN(TRIM(B187&""))>0),"반영","입력 확인"))) -> 미입력
A16: 11 | B16: =IF(LEN(TRIM(여러쌍비교!B16&""))=0,"",여러쌍비교!B16) | C16: =E200 -> 미작성 | D16: =HYPERLINK("#'6_행사전문가의견'!A190","11번 작성") -> 11번 작성 | E16: =IF(LEN(TRIM(C191&""))=0,"",C191) | F16: =IF(LEN(TRIM(B202&""))=0,"미입력",IF(E200<>"완료","작성 중",IF(AND(OR(B202="주저함 · 거리를 벌림",B202="뚜렷한 치우침 없음",B202="살피지 않고 들이닥침",B202="자극에 따라 다름",B202="판단보류"),LEN(TRIM(B203&""))>0),"반영","입력 확인"))) -> 미입력
A17: 12 | B17: =IF(LEN(TRIM(여러쌍비교!B17&""))=0,"",여러쌍비교!B17) | C17: =E216 -> 미작성 | D17: =HYPERLINK("#'6_행사전문가의견'!A206","12번 작성") -> 12번 작성 | E17: =IF(LEN(TRIM(C207&""))=0,"",C207) | F17: =IF(LEN(TRIM(B218&""))=0,"미입력",IF(E216<>"완료","작성 중",IF(AND(OR(B218="주저함 · 거리를 벌림",B218="뚜렷한 치우침 없음",B218="살피지 않고 들이닥침",B218="자극에 따라 다름",B218="판단보류"),LEN(TRIM(B219&""))>0),"반영","입력 확인"))) -> 미입력
A18: 13 | B18: =IF(LEN(TRIM(여러쌍비교!B18&""))=0,"",여러쌍비교!B18) | C18: =E232 -> 미작성 | D18: =HYPERLINK("#'6_행사전문가의견'!A222","13번 작성") -> 13번 작성 | E18: =IF(LEN(TRIM(C223&""))=0,"",C223) | F18: =IF(LEN(TRIM(B234&""))=0,"미입력",IF(E232<>"완료","작성 중",IF(AND(OR(B234="주저함 · 거리를 벌림",B234="뚜렷한 치우침 없음",B234="살피지 않고 들이닥침",B234="자극에 따라 다름",B234="판단보류"),LEN(TRIM(B235&""))>0),"반영","입력 확인"))) -> 미입력
A19: 14 | B19: =IF(LEN(TRIM(여러쌍비교!B19&""))=0,"",여러쌍비교!B19) | C19: =E248 -> 미작성 | D19: =HYPERLINK("#'6_행사전문가의견'!A238","14번 작성") -> 14번 작성 | E19: =IF(LEN(TRIM(C239&""))=0,"",C239) | F19: =IF(LEN(TRIM(B250&""))=0,"미입력",IF(E248<>"완료","작성 중",IF(AND(OR(B250="주저함 · 거리를 벌림",B250="뚜렷한 치우침 없음",B250="살피지 않고 들이닥침",B250="자극에 따라 다름",B250="판단보류"),LEN(TRIM(B251&""))>0),"반영","입력 확인"))) -> 미입력
A20: 15 | B20: =IF(LEN(TRIM(여러쌍비교!B20&""))=0,"",여러쌍비교!B20) | C20: =E264 -> 미작성 | D20: =HYPERLINK("#'6_행사전문가의견'!A254","15번 작성") -> 15번 작성 | E20: =IF(LEN(TRIM(C255&""))=0,"",C255) | F20: =IF(LEN(TRIM(B266&""))=0,"미입력",IF(E264<>"완료","작성 중",IF(AND(OR(B266="주저함 · 거리를 벌림",B266="뚜렷한 치우침 없음",B266="살피지 않고 들이닥침",B266="자극에 따라 다름",B266="판단보류"),LEN(TRIM(B267&""))>0),"반영","입력 확인"))) -> 미입력
A21: 16 | B21: =IF(LEN(TRIM(여러쌍비교!B21&""))=0,"",여러쌍비교!B21) | C21: =E280 -> 미작성 | D21: =HYPERLINK("#'6_행사전문가의견'!A270","16번 작성") -> 16번 작성 | E21: =IF(LEN(TRIM(C271&""))=0,"",C271) | F21: =IF(LEN(TRIM(B282&""))=0,"미입력",IF(E280<>"완료","작성 중",IF(AND(OR(B282="주저함 · 거리를 벌림",B282="뚜렷한 치우침 없음",B282="살피지 않고 들이닥침",B282="자극에 따라 다름",B282="판단보류"),LEN(TRIM(B283&""))>0),"반영","입력 확인"))) -> 미입력
A22: 17 | B22: =IF(LEN(TRIM(여러쌍비교!B22&""))=0,"",여러쌍비교!B22) | C22: =E296 -> 미작성 | D22: =HYPERLINK("#'6_행사전문가의견'!A286","17번 작성") -> 17번 작성 | E22: =IF(LEN(TRIM(C287&""))=0,"",C287) | F22: =IF(LEN(TRIM(B298&""))=0,"미입력",IF(E296<>"완료","작성 중",IF(AND(OR(B298="주저함 · 거리를 벌림",B298="뚜렷한 치우침 없음",B298="살피지 않고 들이닥침",B298="자극에 따라 다름",B298="판단보류"),LEN(TRIM(B299&""))>0),"반영","입력 확인"))) -> 미입력
A23: 18 | B23: =IF(LEN(TRIM(여러쌍비교!B23&""))=0,"",여러쌍비교!B23) | C23: =E312 -> 미작성 | D23: =HYPERLINK("#'6_행사전문가의견'!A302","18번 작성") -> 18번 작성 | E23: =IF(LEN(TRIM(C303&""))=0,"",C303) | F23: =IF(LEN(TRIM(B314&""))=0,"미입력",IF(E312<>"완료","작성 중",IF(AND(OR(B314="주저함 · 거리를 벌림",B314="뚜렷한 치우침 없음",B314="살피지 않고 들이닥침",B314="자극에 따라 다름",B314="판단보류"),LEN(TRIM(B315&""))>0),"반영","입력 확인"))) -> 미입력
A24: 19 | B24: =IF(LEN(TRIM(여러쌍비교!B24&""))=0,"",여러쌍비교!B24) | C24: =E328 -> 미작성 | D24: =HYPERLINK("#'6_행사전문가의견'!A318","19번 작성") -> 19번 작성 | E24: =IF(LEN(TRIM(C319&""))=0,"",C319) | F24: =IF(LEN(TRIM(B330&""))=0,"미입력",IF(E328<>"완료","작성 중",IF(AND(OR(B330="주저함 · 거리를 벌림",B330="뚜렷한 치우침 없음",B330="살피지 않고 들이닥침",B330="자극에 따라 다름",B330="판단보류"),LEN(TRIM(B331&""))>0),"반영","입력 확인"))) -> 미입력
A25: 20 | B25: =IF(LEN(TRIM(여러쌍비교!B25&""))=0,"",여러쌍비교!B25) | C25: =E344 -> 미작성 | D25: =HYPERLINK("#'6_행사전문가의견'!A334","20번 작성") -> 20번 작성 | E25: =IF(LEN(TRIM(C335&""))=0,"",C335) | F25: =IF(LEN(TRIM(B346&""))=0,"미입력",IF(E344<>"완료","작성 중",IF(AND(OR(B346="주저함 · 거리를 벌림",B346="뚜렷한 치우침 없음",B346="살피지 않고 들이닥침",B346="자극에 따라 다름",B346="판단보류"),LEN(TRIM(B347&""))>0),"반영","입력 확인"))) -> 미입력
A30: ="1번 "&IF(LEN(TRIM(여러쌍비교!B6&""))=0,"이름 미입력",여러쌍비교!B6) -> 1번 이름 미입력
A31: 관찰자·일자
A32: 영역 | B32: 관찰할 내용 | D32: 관찰 의견
A33: 애착·관계 | B33: 분리 초기·이후, 재회·접촉, 보호자와 함께 있을 때의 모습
A34: 보호자 교육태도 | B34: 개 행동에 맞춤, 신호에 따른 대응 변화, 지시·제한
A35: 사람에 대한 사회성 | B35: 낯선 사람의 접근·부름·접촉·퇴장에 대한 반응
A36: 비사회적 두려움 | B36: 바닥·물건·소리 등 비사회적 자극에 보인 두려움 반응
A37: 환경 적응·회복 | B37: 첫 반응 이후의 변화와 도움이 된 대응. 실제 시각 확인
A38: 개의 성향 | B38: 이번 시행의 활동·접근·차분함 등. 고정된 성격으로 단정하지 않음
A39: 가장 먼저 도와줄 부분
A40: 작성 표시 | D40: 기록 상태 | E40: =IF(B40="완료",IF(LEN(TRIM(C31&""))=0,"관찰자·일자 미기록",IF(OR(LEN(TRIM(D33&""))+LEN(TRIM(D34&""))+LEN(TRIM(D35&""))+LEN(TRIM(D36&""))+LEN(TRIM(D37&""))+LEN(TRIM(D38&""))>0,AND(OR(B42="주저함 · 거리를 벌림",B42="뚜렷한 치우침 없음",B42="살피지 않고 들이닥침",B42="자극에 따라 다름",B42="판단보류"),LEN(TRIM(B43&""))>0)),"완료","의견·입장 근거 미기록")),IF(OR(B40="작성 중",LEN(TRIM(D33&""))+LEN(TRIM(D34&""))+LEN(TRIM(D35&""))+LEN(TRIM(D36&""))+LEN(TRIM(D37&""))+LEN(TRIM(D38&""))>0,LEN(TRIM(C31&""))>0,LEN(TRIM(B42&""))>0,LEN(TRIM(B43&""))>0),"작성 중","미작성")) -> 미작성
A41: 빈 영역은 AI 근거를 사용합니다. 원점수와 기본 유형은 보존하고 리포트 해석에서 의견을 우선 반영합니다.
A42: 입장 판단 (선택) | D42: 선택 시 아래 근거·시각도 기록
A43: 입장 근거·시각
A46: ="2번 "&IF(LEN(TRIM(여러쌍비교!B7&""))=0,"이름 미입력",여러쌍비교!B7) -> 2번 이름 미입력
A47: 관찰자·일자
A48: 영역 | B48: 관찰할 내용 | D48: 관찰 의견
...

Sheet 한마리상세
A1: 한 마리 결과와 원항목 조회
A3: 대상 번호 | B3: 1 | D3: 반려견 | E3: =IF(LEN(TRIM(INDEX(여러쌍비교!$B$6:$B$25,$B$3)&""))=0,"이름 미입력",INDEX(여러쌍비교!$B$6:$B$25,$B$3)) -> 이름 미입력
A5: 리포트에 사용할 우선 근거
A6: 입장 판단 | B6: =IF(LEN(TRIM(INDEX(여러쌍비교!$CC$6:$CC$25,$B$3)&""))=0,"",INDEX(여러쌍비교!$CC$6:$CC$25,$B$3)) -> 자료 부족
A7: 애착·관계 | B7: =IF(LEN(TRIM(INDEX(여러쌍비교!$CL$6:$CL$25,$B$3)&""))=0,"",INDEX(여러쌍비교!$CL$6:$CL$25,$B$3)) -> 분리 초기: 자료 부족 / 분리 이후: 자료 부족 / 변화: 미채점 / 분리·재회·무시 보조: 조건 미확인 / 재회·무시 패턴: 조건 미확인
A8: 보호자 교육태도 | B8: =IF(LEN(TRIM(INDEX(여러쌍비교!$CM$6:$CM$25,$B$3)&""))=0,"",INDEX(여러쌍비교!$CM$6:$CM$25,$B$3)) -> 판정보류 (자동 초안 · 근거 비율 미산출)
A9: 사람에 대한 사회성 | B9: =IF(LEN(TRIM(INDEX(여러쌍비교!$CN$6:$CN$25,$B$3)&""))=0,"",INDEX(여러쌍비교!$CN$6:$CN$25,$B$3)) -> 자료 부족
A10: 비사회적 두려움 | B10: =IF(LEN(TRIM(INDEX(여러쌍비교!$CS$6:$CS$25,$B$3)&""))=0,"",INDEX(여러쌍비교!$CS$6:$CS$25,$B$3))
A11: 환경 적응·회복 | B11: =IF(LEN(TRIM(INDEX(여러쌍비교!$CO$6:$CO$25,$B$3)&""))=0,"",INDEX(여러쌍비교!$CO$6:$CO$25,$B$3)) -> 조건 미확인
A12: 개의 성향 | B12: =IF(LEN(TRIM(INDEX(여러쌍비교!$CT$6:$CT$25,$B$3)&""))=0,"",INDEX(여러쌍비교!$CT$6:$CT$25,$B$3))
A13: 가장 먼저 도와줄 부분 | B13: =IF(LEN(TRIM(INDEX(여러쌍비교!$CP$6:$CP$25,$B$3)&""))=0,"",INDEX(여러쌍비교!$CP$6:$CP$25,$B$3))
A15: 기본 유형과 관찰 수치
A16: 기본 애착유형 | B16: =INDEX(여러쌍비교!$M$6:$M$25,$B$3) -> 미판정
A17: 기본 보호자 유형 | B17: =INDEX(여러쌍비교!$AQ$6:$AQ$25,$B$3)&" / "&INDEX(여러쌍비교!$CU$6:$CU$25,$B$3) -> 판정보류 / 자동 초안
A18: 보호자 유형 근거 비율 | B18: =IF(COUNT(INDEX('3_보호자행동'!$P$51:$P$70,$B$3))=0,"자료 부족","허용 "&TEXT(INDEX('3_보호자행동'!$P$51:$P$70,$B$3),"0%")&" / 조율 "&TEXT(INDEX('3_보호자행동'!$Q$51:$Q$70,$B$3),"0%")&" / 통제 "&TEXT(INDEX('3_보호자행동'!$R$51:$R$70,$B$3),"0%")&" (성격 확률이 아닌 근거 구성비)") -> 자료 부족
A19: 걷기 근접 국면 비율 | B19: =IF(COUNT(INDEX(여러쌍비교!$Z$6:$Z$25,$B$3))=0,"자료 부족",TEXT(INDEX(여러쌍비교!$Z$6:$Z$25,$B$3),"0%")&" / 6국면 중 거리 등급 0·1의 비율") -> 자료 부족
A20: 분리 관찰 순서 | B20: =INDEX(여러쌍비교!$CK$6:$CK$25,$B$3) -> 미채점
A21: 몸 상태 원점수와 변화 | B21: ="분리 개58: "&IF(COUNT(INDEX('2_개행동'!$J$58:$AC$58,1,$B$3))=0,"미관찰",TEXT(INDEX('2_개행동'!$J$58:$AC$58,1,$B$3),"+0;-0;0"))&" → 재회 개18: "&IF(COUNT(INDEX('2_개행동'!$J$18:$AC$18,1,$B$3))=0,"미관찰",TEXT(INDEX('2_개행동'!$J$18:$AC$18,1,$B$3),"+0;-0;0"))&" / 변화 "&IF(COUNT(INDEX(여러쌍비교!$W$6:$W$25,$B$3))=0,"미산출",TEXT(INDEX(여러쌍비교!$W$6:$W$25,$B$3),"+0;-0;0"))&CHAR(10)&"기준 개8: "&IF(COUNT(INDEX('2_개행동'!$J$8:$AC$8,1,$B$3))=0,"미관찰",TEXT(INDEX('2_개행동'!$J$8:$AC$8,1,$B$3),"+0;-0;0"))&" → 무시 개23: "&IF(COUNT(INDEX('2_개행동'!$J$23:$AC$23,1,$B$3))=0,"미관찰",TEXT(INDEX('2_개행동'!$J$23:$AC$23,1,$B$3),"+0;-0;0"))&" / 변화 "&IF(COUNT(INDEX(여러쌍비교!$V$6:$V$25,$B$3))=0,"미산출",TEXT(INDEX(여러쌍비교!$V$6:$V$25,$B$3),"+0;-0;0"))&CHAR(10)&"변화 = 앞 원점수의 절대값 − 뒤 원점수의 절대값. 0→0과 −2→+2는 변화값이 같아도 행동이 다릅니다. 중앙범주·혼재 여부와 실제 장면을 함께 봅니다." -> 분리 개58: 미관찰 → 재회 개18: 미관찰 / 변화 미산출 기준 개8: 미관찰 → 무시 개23: 미관찰 / 변화 미산출 변화 = 앞 원점수의 절대값 − 뒤 원점수의 절대값. 0→0과 −2→+2는 변화값이 같아도 행동이 다릅니다. 중앙범주·혼재 여부와 실제 장면을 함께 봅니다.
A22: 재회·무시 방향별 합 | B22: =IF(COUNT(INDEX(여러쌍비교!$AE$6:$AE$25,$B$3),INDEX(여러쌍비교!$AF$6:$AF$25,$B$3))<2,"자료 부족·조건 확인","접촉 쪽 "&INDEX(여러쌍비교!$AE$6:$AE$25,$B$3)&" / 거리 쪽 "&INDEX(여러쌍비교!$AF$6:$AF$25,$B$3)&". 두 방향을 상쇄하지 않고 별도 표시.") -> 자료 부족·조건 확인
A23: 환경 원관찰 방향별 합 | B23: =IF(INDEX(여러쌍비교!$BC$6:$BC$25,$B$3)=0,"자료 부족","−절댓값 "&INDEX(여러쌍비교!$BA$6:$BA$25,$B$3)&" / +합 "&INDEX(여러쌍비교!$BB$6:$BB$25,$B$3)&" / 관찰 "&INDEX(여러쌍비교!$BC$6:$BC$25,$B$3)&"개. 조건 적용 전 원관찰 분포.") -> 자료 부족
A24: 사람 원관찰 방향별 합 | B24: =IF(INDEX(여러쌍비교!$BF$6:$BF$25,$B$3)=0,"자료 부족","−절댓값 "&INDEX(여러쌍비교!$BD$6:$BD$25,$B$3)&" / +합 "&INDEX(여러쌍비교!$BE$6:$BE$25,$B$3)&" / 관찰 "&INDEX(여러쌍비교!$BF$6:$BF$25,$B$3)&"개. 조건 적용 전 원관찰 분포.") -> 자료 부족
A25: 시행 조건 | B25: ="무시: "&IF(COUNT(INDEX('3_보호자행동'!$J$12:$AC$12,1,$B$3))=0,"미기록",INDEX('3_보호자행동'!$C$12:$E$12,1,INDEX('3_보호자행동'!$J$12:$AC$12,1,$B$3)))&" / 걷기: "&IF(COUNT(INDEX('3_보호자행동'!$J$13:$AC$13,1,$B$3))=0,"미기록",INDEX('3_보호자행동'!$C$13:$E$13,1,INDEX('3_보호자행동'!$J$13:$AC$13,1,$B$3))) -> 무시: 미기록 / 걷기: 미기록
A27: 내부 확인 기록
A28: 관찰 의견 기록 상태 | B28: =INDEX(여러쌍비교!$CJ$6:$CJ$25,$B$3) -> 미작성
