Workbook

Sheet 0_안내
A1: 반려견–보호자 관계 AI 분석 — 행동 채점표
A2: 2026년 10월 프로토콜 (약 2분 20초) · 20마리 단위
A4: ■ 촬영 순서
A5: 1 입장 ~15초 방 문 → 비닐 바닥(폭 전체) → 의자로 · 목줄을 푼다
A6: 2 기준 10초 목줄을 푼 직후 · 앉아서 자연스럽게 (부르거나 만지지 않음) · 모든 해석의 바탕
A7: 3 혼자 15초 일어나 문을 열고 나가 블라인드 뒤로
A8: 4 낯선 사람 20초 안내인이 들어와 이름을 부르고 움직인 뒤 나감 (대본 미확정)
A9: 5 재회 20초 보호자가 들어와 의자까지 걸어가 앉는다 · 앉을 때까지 개를 보지 않음 · 앉은 뒤 이름을 부르고 만짐
A10: 6 무시 15초 만져 준 뒤 반응을 끊는다 · 개를 보지 않음 · 말도 걸지 않음
A11: 7 걷기 30초 리드줄 없이 · 말·손짓 없이 · 6국면
A12: 8 퇴장 ~15초 입장 코스를 되짚어 나감
A14: ■ 축이 넷입니다 — 방향 셋, 각성 하나
... A40: 자세한 근거는 docs/16_프로토콜_측정지표_근거.md

Sheet 1_바디시그널
A1: 바디시그널
A2: 몸으로 나타나는 신호. 꼬리와 발성만 봅니다. 전부 각성 축입니다.
A3: J열부터 오른쪽으로 1번~20번 강아지 칸입니다. 각 칸에 1~5 중 하나를 넣습니다. ★ 3점이 안정이고 1과 5, 2와 4가 서로 대치됩니다. 축이 넷입니다 — 「애착」 1 과잉↔5 없음 / 「우호」 1 경계↔5 과한 우호 / 「사회화」 1 회피↔5 살피지 않음 / 「각성」 1 위축↔5 흥분. I열에 적어 두었습니다. 회색 칸은 해당 단계가 없으며, 그 번호를 넣으면 무효 처리됩니다.
A4: 구간 | B4: 관찰 항목 | C4: 1 | D4: 2 | E4: 3 | F4: 4 | G4: 5 | H4: 영역 | I4: 척도·축 | J4: 1번 | K4: 2번 | L4: 3번 | M4: 4번 | N4: 5번 | O4: 6번 | P4: 7번 | Q4: 8번 | R4: 9번 | S4: 10번 | T4: 11번 | U4: 12번 | V4: 13번 | W4: 14번 | X4: 15번 | Y4: 16번 | Z4: 17번 | AA4: 18번 | AB4: 19번 | AC4: 20번 | AD4: 영역코드 | AY4: 척도
A5: 입장 | B5: 꼬리 | C5: 다리 사이로 말아 넣음 | D5: 꼬리 아랫부분이 바닥을 가리킴 · 짧게 흔들림 | E5: 등선 높이 · 꼬리끝이 바닥보다 위 · 부드러운 움직임 | F5: 등선보다 높이 올라옴 | G5: 높이 들고 경직 · 짧고 빠른 흔들림 | H5: 사회성 — 환경 | I5: 양쪽·각성 | AD5: SOC_E | AE5: =IF($J5="",0,IF(INDEX($C5:$G5,$J5)="",0,$J5)) | AF5: =IF($K5="",0,IF(INDEX($C5:$G5,$K5)="",0,$K5)) | AG5: =IF($L5="",0,IF(INDEX($C5:$G5,$L5)="",0,$L5)) | AH5: =IF($M5="",0,IF(INDEX($C5:$G5,$M5)="",0,$M5)) | AI5: =IF($N5="",0,IF(INDEX($C5:$G5,$N5)="",0,$N5)) | AJ5: =IF($O5="",0,IF(INDEX($C5:$G5,$O5)="",0,$O5)) | AK5: =IF($P5="",0,IF(INDEX($C5:$G5,$P5)="",0,$P5)) | AL5: =IF($Q5="",0,IF(INDEX($C5:$G5,$Q5)="",0,$Q5)) | AM5: =IF($R5="",0,IF(INDEX($C5:$G5,$R5)="",0,$R5)) | AN5: =IF($S5="",0,IF(INDEX($C5:$G5,$S5)="",0,$S5)) | AO5: =IF($T5="",0,IF(INDEX($C5:$G5,$T5)="",0,$T5)) | AP5: =IF($U5="",0,IF(INDEX($C5:$G5,$U5)="",0,$U5)) | AQ5: =IF($V5="",0,IF(INDEX($C5:$G5,$V5)="",0,$V5)) | AR5: =IF($W5="",0,IF(INDEX($C5:$G5,$W5)="",0,$W5)) | AS5: =IF($X5="",0,IF(INDEX($C5:$G5,$X5)="",0,$X5)) | AT5: =IF($Y5="",0,IF(INDEX($C5:$G5,$Y5)="",0,$Y5)) | AU5: =IF($Z5="",0,IF(INDEX($C5:$G5,$Z5)="",0,$Z5)) | AV5: =IF($AA5="",0,IF(INDEX($C5:$G5,$AA5)="",0,$AA5)) | AW5: =IF($AB5="",0,IF(INDEX($C5:$G5,$AB5)="",0,$AB5)) | AX5: =IF($AC5="",0,IF(INDEX($C5:$G5,$AC5)="",0,$AC5)) | AY5: BI
A6: 입장 | B6: 발성 ※입장 구간 | C6: 지속적인 낑낑소리 | D6: 가끔 낑낑 | E6: 없음 | F6: 한두 번 짖음 | G6: 여러 번 짖음 | H6: 사회성 — 환경 | I6: 양쪽·각성 | AD6: SOC_E | AE6: =IF($J6="",0,IF(INDEX($C6:$G6,$J6)="",0,$J6)) | AF6: =IF($K6="",0,IF(INDEX($C6:$G6,$K6)="",0,$K6)) | AG6: =IF($L6="",0,IF(INDEX($C6:$G6,$L6)="",0,$L6)) | AH6: =IF($M6="",0,IF(INDEX($C6:$G6,$M6)="",0,$M6)) | AI6: =IF($N6="",0,IF(INDEX($C6:$G6,$N6)="",0,$N6)) | AJ6: =IF($O6="",0,IF(INDEX($C6:$G6,$O6)="",0,$O6)) | AK6: =IF($P6="",0,IF(INDEX($C6:$G6,$P6)="",0,$P6)) | AL6: =IF($Q6="",0,IF(INDEX($C6:$G6,$Q6)="",0,$Q6)) | AM6: =IF($R6="",0,IF(INDEX($C6:$G6,$R6)="",0,$R6)) | AN6: =IF($S6="",0,IF(INDEX($C6:$G6,$S6)="",0,$S6)) | AO6: =IF($T6="",0,IF(INDEX($C6:$G6,$T6)="",0,$T6)) | AP6: =IF($U6="",0,IF(INDEX($C6:$G6,$U6)="",0,$U6)) | AQ6: =IF($V6="",0,IF(INDEX($C6:$G6,$V6)="",0,$V6)) | AR6: =IF($W6="",0,IF(INDEX($C6:$G6,$W6)="",0,$W6)) | AS6: =IF($X6="",0,IF(INDEX($C6:$G6,$X6)="",0,$X6)) | AT6: =IF($Y6="",0,IF(INDEX($C6:$G6,$Y6)="",0,$Y6)) | AU6: =IF($Z6="",0,IF(INDEX($C6:$G6,$Z6)="",0,$Z6)) | AV6: =IF($AA6="",0,IF(INDEX($C6:$G6,$AA6)="",0,$AA6)) | AW6: =IF($AB6="",0,IF(INDEX($C6:$G6,$AB6)="",0,$AB6)) | AX6: =IF($AC6="",0,IF(INDEX($C6:$G6,$AC6)="",0,$AC6)) | AY6: BI
A7: 입장 | B7: 낯선 바닥 — 꼬리 ※바닥을 밟는 동안 | C7: 다리 사이로 말아 넣음 | D7: 꼬리 아랫부분이 바닥을 가리킴 · 짧게 흔들림 | E7: 등선 높이 · 꼬리끝이 바닥보다 위 · 부드러운 움직임 | F7: 등선보다 높이 올라옴 | G7: 높이 들고 경직 · 짧고 빠른 흔들림 | H7: 사회성 — 환경 | I7: 양쪽·각성 | AD7: SOC_E | AE7: =IF($J7="",0,IF(INDEX($C7:$G7,$J7)="",0,$J7)) | AF7: =IF($K7="",0,IF(INDEX($C7:$G7,$K7)="",0,$K7)) | AG7: =IF($L7="",0,IF(INDEX($C7:$G7,$L7)="",0,$L7)) | AH7: =IF($M7="",0,IF(INDEX($C7:$G7,$M7)="",0,$M7)) | AI7: =IF($N7="",0,IF(INDEX($C7:$G7,$N7)="",0,$N7)) | AJ7: =IF($O7="",0,IF(INDEX($C7:$G7,$O7)="",0,$O7)) | AK7: =IF($P7="",0,IF(INDEX($C7:$G7,$P7)="",0,$P7)) | AL7: =IF($Q7="",0,IF(INDEX($C7:$G7,$Q7)="",0,$Q7)) | AM7: =IF($R7="",0,IF(INDEX($C7:$G7,$R7)="",0,$R7)) | AN7: =IF($S7="",0,IF(INDEX($C7:$G7,$S7)="",0,$S7)) | AO7: =IF($T7="",0,IF(INDEX($C7:$G7,$T7)="",0,$T7)) | AP7: =IF($U7="",0,IF(INDEX($C7:$G7,$U7)="",0,$U7)) | AQ7: =IF($V7="",0,IF(INDEX($C7:$G7,$V7)="",0,$V7)) | AR7: =IF($W7="",0,IF(INDEX($C7:$G7,$W7)="",0,$W7)) | AS7: =IF($X7="",0,IF(INDEX($C7:$G7,$X7)="",0,$X7)) | AT7: =IF($Y7="",0,IF(INDEX($C7:$G7,$Y7)="",0,$Y7)) | AU7: =IF($Z7="",0,IF(INDEX($C7:$G7,$Z7)="",0,$Z7)) | AV7: =IF($AA7="",0,IF(INDEX($C7:$G7,$AA7)="",0,$AA7)) | AW7: =IF($AB7="",0,IF(INDEX($C7:$G7,$AB7)="",0,$AB7)) | AX7: =IF($AC7="",0,IF(INDEX($C7:$G7,$AC7)="",0,$AC7)) | AY7: BI
A8: 입장 | B8: 낯선 바닥 — 몸 털기 ※횟수 · 점수가 아닙니다 | C8: 바닥을 처음 밟은 순간부터 5초 안에 개가 몸을 턴 횟수를 셉니다. 물기를 털듯 온몸을 흔드는 동작입니다. 하품·코 핥기는 세지 않습니다 — 개가 가까울 때만 보여 채점자마다 달라집니다. | H8: — 참고 · 각성의 보조 | I8: 참고 | AE8: 0 | AF8: 0 | AG8: 0 | AH8: 0 | AI8: 0 | AJ8: 0 | AK8: 0 | AL8: 0 | AM8: 0 | AN8: 0 | AO8: 0 | AP8: 0 | AQ8: 0 | AR8: 0 | AS8: 0 | AT8: 0 | AU8: 0 | AV8: 0 | AW8: 0 | AX8: 0
A9: 혼자 | B9: 꼬리 ※혼자 있는 15초 | C9: 다리 사이로 말아 넣음 | D9: 꼬리 아랫부분이 바닥을 가리킴 · 짧게 흔들림 | E9: 등선 높이 · 꼬리끝이 바닥보다 위 · 부드러운 움직임 | F9: 등선보다 높이 올라옴 | G9: 높이 들고 경직 · 짧고 빠른 흔들림 | H9: 친밀·애착 | I9: 양쪽·각성 | AD9: ATT | AE9: =IF($J9="",0,IF(INDEX($C9:$G9,$J9)="",0,$J9)) | AF9: =IF($K9="",0,IF(INDEX($C9:$G9,$K9)="",0,$K9)) | AG9: =IF($L9="",0,IF(INDEX($C9:$G9,$L9)="",0,$L9)) | AH9: =IF($M9="",0,IF(INDEX($C9:$G9,$M9)="",0,$M9)) | AI9: =IF($N9="",0,IF(INDEX($C9:$G9,$N9)="",0,$N9)) | AJ9: =IF($O9="",0,IF(INDEX($C9:$G9,$O9)="",0,$O9)) | AK9: =IF($P9="",0,IF(INDEX($C9:$G9,$P9)="",0,$P9)) | AL9: =IF($Q9="",0,IF(INDEX($C9:$G9,$Q9)="",0,$Q9)) | AM9: =IF($R9="",0,IF(INDEX($C9:$G9,$R9)="",0,$R9)) | AN9: =IF($S9="",0,IF(INDEX($C9:$G9,$S9)="",0,$S9)) | AO9: =IF($T9="",0,IF(INDEX($C9:$G9,$T9)="",0,$T9)) | AP9: =IF($U9="",0,IF(INDEX($C9:$G9,$U9)="",0,$U9)) | AQ9: =IF($V9="",0,IF(INDEX($C9:$G9,$V9)="",0,$V9)) | AR9: =IF($W9="",0,IF(INDEX($C9:$G9,$W9)="",0,$W9)) | AS9: =IF($X9="",0,IF(INDEX($C9:$G9,$X9)="",0,$X9)) | AT9: =IF($Y9="",0,IF(INDEX($C9:$G9,$Y9)="",0,$Y9)) | AU9: =IF($Z9="",0,IF(INDEX($C9:$G9,$Z9)="",0,$Z9)) | AV9: =IF($AA9="",0,IF(INDEX($C9:$G9,$AA9)="",0,$AA9)) | AW9: =IF($AB9="",0,IF(INDEX($C9:$G9,$AB9)="",0,$AB9)) | AX9: =IF($AC9="",0,IF(INDEX($C9:$G9,$AC9)="",0,$AC9)) | AY9: BI
A10: 혼자 | B10: 분리 — 몸 털기 ※횟수 · 점수가 아닙니다 | C10: 보호자가 나간 순간부터 5초 안에 개가 몸을 턴 횟수를 셉니다. 물기를 털듯 온몸을 흔드는 동작입니다. 하품·코 핥기는 세지 않습니다 — 개가 가까울 때만 보여 채점자마다 달라집니다. | H10: — 참고 · 각성의 보조 | I10: 참고 | AE10: 0 | AF10: 0 | AG10: 0 | AH10: 0 | AI10: 0 | AJ10: 0 | AK10: 0 | AL10: 0 | AM10: 0 | AN10: 0 | AO10: 0 | AP10: 0 | AQ10: 0 | AR10: 0 | AS10: 0 | AT10: 0 | AU10: 0 | AV10: 0 | AW10: 0 | AX10: 0
A11: 낯선 | B11: 꼬리 ※낯선 사람이 있는 동안 | C11: 다리 사이로 말아 넣음 | D11: 꼬리 아랫부분이 바닥을 가리킴 · 짧게 흔들림 | E11: 등선 높이 · 꼬리끝이 바닥보다 위 · 부드러운 움직임 | F11: 등선보다 높이 올라옴 | G11: 높이 들고 경직 · 짧고 빠른 흔들림 | H11: 사회성 — 사람 | I11: 양쪽·각성 | AD11: SOC_H | AE11: =IF($J11="",0,IF(INDEX($C11:$G11,$J11)="",0,$J11)) | AF11: =IF($K11="",0,IF(INDEX($C11:$G11,$K11)="",0,$K11)) | AG11: =IF($L11="",0,IF(INDEX($C11:$G11,$L11)="",0,$L11)) | AH11: =IF($M11="",0,IF(INDEX($C11:$G11,$M11)="",0,$M11)) | AI11: =IF($N11="",0,IF(INDEX($C11:$G11,$N11)="",0,$N11)) | AJ11: =IF($O11="",0,IF(INDEX($C11:$G11,$O11)="",0,$O11)) | AK11: =IF($P11="",0,IF(INDEX($C11:$G11,$P11)="",0,$P11)) | AL11: =IF($Q11="",0,IF(INDEX($C11:$G11,$Q11)="",0,$Q11)) | AM11: =IF($R11="",0,IF(INDEX($C11:$G11,$R11)="",0,$R11)) | AN11: =IF($S11="",0,IF(INDEX($C11:$G11,$S11)="",0,$S11)) | AO11: =IF($T11="",0,IF(INDEX($C11:$G11,$T11)="",0,$T11)) | AP11: =IF($U11="",0,IF(INDEX($C11:$G11,$U11)="",0,$U11)) | AQ11: =IF($V11="",0,IF(INDEX($C11:$G11,$V11)="",0,$V11)) | AR11: =IF($W11="",0,IF(INDEX($C11:$G11,$W11)="",0,$W11)) | AS11: =IF($X11="",0,IF(INDEX($C11:$G11,$X11)="",0,$X11)) | AT11: =IF($Y11="",0,IF(INDEX($C11:$G11,$Y11)="",0,$Y11)) | AU11: =IF($Z11="",0,IF(INDEX($C11:$G11,$Z11)="",0,$Z11)) | AV11: =IF($AA11="",0,IF(INDEX($C11:$G11,$AA11)="",0,$AA11)) | AW11: =IF($AB11="",0,IF(INDEX($C11:$G11,$AB11)="",0,$AB11)) | AX11: =IF($AC11="",0,IF(INDEX($C11:$G11,$AC11)="",0,$AC11)) | AY11: BI
A12: 걷기 | B12: 꼬리 | C12: 다리 사이로 말아 넣음 | D12: 꼬리 아랫부분이 바닥을 가리킴 · 짧게 흔들림 | E12: 등선 높이 · 꼬리끝이 바닥보다 위 · 부드러운 움직임 | F12: 등선보다 높이 올라옴 | G12: 높이 들고 경직 · 짧고 빠른 흔들림 | H12: 행동 동조 | I12: 양쪽·각성 | AD12: SYN | AE12: =IF($J12="",0,IF(INDEX($C12:$G12,$J12)="",0,$J12)) | AF12: =IF($K12="",0,IF(INDEX($C12:$G12,$K12)="",0,$K12)) | AG12: =IF($L12="",0,IF(INDEX($C12:$G12,$L12)="",0,$L12)) | AH12: =IF($M12="",0,IF(INDEX($C12:$G12,$M12)="",0,$M12)) | AI12: =IF($N12="",0,IF(INDEX($C12:$G12,$N12)="",0,$N12)) | AJ12: =IF($O12="",0,IF(INDEX($C12:$G12,$O12)="",0,$O12)) | AK12: =IF($P12="",0,IF(INDEX($C12:$G12,$P12)="",0,$P12)) | AL12: =IF($Q12="",0,IF(INDEX($C12:$G12,$Q12)="",0,$Q12)) | AM12: =IF($R12="",0,IF(INDEX($C12:$G12,$R12)="",0,$R12)) | AN12: =IF($S12="",0,IF(INDEX($C12:$G12,$S12)="",0,$S12)) | AO12: =IF($T12="",0,IF(INDEX($C12:$G12,$T12)="",0,$T12)) | AP12: =IF($U12="",0,IF(INDEX($C12:$G12,$U12)="",0,$U12)) | AQ12: =IF($V12="",0,IF(INDEX($C12:$G12,$V12)="",0,$V12)) | AR12: =IF($W12="",0,IF(INDEX($C12:$G12,$W12)="",0,$W12)) | AS12: =IF($X12="",0,IF(INDEX($C12:$G12,$X12)="",0,$X12)) | AT12: =IF($Y12="",0,IF(INDEX($C12:$G12,$Y12)="",0,$Y12)) | AU12: =IF($Z12="",0,IF(INDEX($C12:$G12,$Z12)="",0,$Z12)) | AV12: =IF($AA12="",0,IF(INDEX($C12:$G12,$AA12)="",0,$AA12)) | AW12: =IF($AB12="",0,IF(INDEX($C12:$G12,$AB12)="",0,$AB12)) | AX12: =IF($AC12="",0,IF(INDEX($C12:$G12,$AC12)="",0,$AC12)) | AY12: BI
A13: 퇴장 | B13: 꼬리 | C13: 다리 사이로 말아 넣음 | D13: 꼬리 아랫부분이 바닥을 가리킴 · 짧게 흔들림 | E13: 등선 높이 · 꼬리끝이 바닥보다 위 · 부드러운 움직임 | F13: 등선보다 높이 올라옴 | G13: 높이 들고 경직 · 짧고 빠른 흔들림 | H13: 퇴장 — 환경 적응 | I13: 양쪽·각성 | AD13: EXIT | AE13: =IF($J13="",0,IF(INDEX($C13:$G13,$J13)="",0,$J13)) | AF13: =IF($K13="",0,IF(INDEX($C13:$G13,$K13)="",0,$K13)) | AG13: =IF($L13="",0,IF(INDEX($C13:$G13,$L13)="",0,$L13)) | AH13: =IF($M13="",0,IF(INDEX($C13:$G13,$M13)="",0,$M13)) | AI13: =IF($N13="",0,IF(INDEX($C13:$G13,$N13)="",0,$N13)) | AJ13: =IF($O13="",0,IF(INDEX($C13:$G13,$O13)="",0,$O13)) | AK13: =IF($P13="",0,IF(INDEX($C13:$G13,$P13)="",0,$P13)) | AL13: =IF($Q13="",0,IF(INDEX($C13:$G13,$Q13)="",0,$Q13)) | AM13: =IF($R13="",0,IF(INDEX($C13:$G13,$R13)="",0,$R13)) | AN13: =IF($S13="",0,IF(INDEX($C13:$G13,$S13)="",0,$S13)) | AO13: =IF($T13="",0,IF(INDEX($C13:$G13,$T13)="",0,$T13)) | AP13: =IF($U13="",0,IF(INDEX($C13:$G13,$U13)="",0,$U13)) | AQ13: =IF($V13="",0,IF(INDEX($C13:$G13,$V13)="",0,$V13)) | AR13: =IF($W13="",0,IF(INDEX($C13:$G13,$W13)="",0,$W13)) | AS13: =IF($X13="",0,IF(INDEX($C13:$G13,$X13)="",0,$X13)) | AT13: =IF($Y13="",0,IF(INDEX($C13:$G13,$Y13)="",0,$Y13)) | AU13: =IF($Z13="",0,IF(INDEX($C13:$G13,$Z13)="",0,$Z13)) | AV13: =IF($AA13="",0,IF(INDEX($C13:$G13,$AA13)="",0,$AA13)) | AW13: =IF($AB13="",0,IF(INDEX($C13:$G13,$AB13)="",0,$AB13)) | AX13: =IF($AC13="",0,IF(INDEX($C13:$G13,$AC13)="",0,$AC13)) | AY13: BI
AE14: 0 | AF14: 0 | AG14: 0 | AH14: 0 | AI14: 0 | AJ14: 0 | AK14: 0 | AL14: 0 | AM14: 0 | AN14: 0 | AO14: 0 | AP14: 0 | AQ14: 0 | AR14: 0 | AS14: 0 | AT14: 0 | AU14: 0 | AV14: 0 | AW14: 0 | AX14: 0
A15: ※ 3점이 안정입니다. 축이 넷입니다 — 애착(1 과잉↔5 없음) · 우호(1 경계↔5 과한 우호) · 사회화(1 회피↔5 살피지 않음) · 각성(1 위축↔5 흥분). 「한쪽」 항목은 1·2가 비어 있습니다. | AE15: 0 | AF15: 0 | AG15: 0 | AH15: 0 | AI15: 0 | AJ15: 0 | AK15: 0 | AL15: 0 | AM15: 0 | AN15: 0 | AO15: 0 | AP15: 0 | AQ15: 0 | AR15: 0 | AS15: 0 | AT15: 0 | AU15: 0 | AV15: 0 | AW15: 0 | AX15: 0
AE16: 0 | AF16: 0 | AG16: 0 | AH16: 0 | AI16: 0 | AJ16: 0 | AK16: 0 | AL16: 0 | AM16: 0 | AN16: 0 | AO16: 0 | AP16: 0 | AQ16: 0 | AR16: 0 | AS16: 0 | AT16: 0 | AU16: 0 | AV16: 0 | AW16: 0 | AX16: 0

Sheet 2_개행동
A1: 개행동
A2: 자극 상황에 대해 실제로 한 행동. 구간마다 방향 하나와 각성 하나를 봅니다.
A3: J열부터 오른쪽으로 1번~20번 강아지 칸입니다. 각 칸에 1~5 중 하나를 넣습니다. ★ 3점이 안정이고 1과 5, 2와 4가 서로 대치됩니다. 축이 넷입니다 — 「애착」 1 과잉↔5 없음 / 「우호」 1 경계↔5 과한 우호 / 「사회화」 1 회피↔5 살피지 않음 / 「각성」 1 위축↔5 흥분. I열에 적어 두었습니다. 회색 칸은 해당 단계가 없으며, 그 번호를 넣으면 무효 처리됩니다.
A4: 구간 | B4: 관찰 항목 | C4: 1 | D4: 2 | E4: 3 | F4: 4 | G4: 5 | H4: 영역 | I4: 척도·축 | J4: 1번 | K4: 2번 | L4: 3번 | M4: 4번 | N4: 5번 | O4: 6번 | P4: 7번 | Q4: 8번 | R4: 9번 | S4: 10번 | T4: 11번 | U4: 12번 | V4: 13번 | W4: 14번 | X4: 15번 | Y4: 16번 | Z4: 17번 | AA4: 18번 | AB4: 19번 | AC4: 20번 | AD4: 영역코드 | AY4: 척도
A5: 입장 | B5: [입장] 방 문 통과 — 보호자보다 앞서는가 | C5: 들어가지 않으려 버팀 · 보호자의 강한유도(끌거나, 5초이상) | D5: 뒤처져 따라 들어옴, 보호자의 약한유도(5초 이내) | E5: 보호자와 나란히 들어옴 | F5: 앞서 들어옴 | G5: 끌고 들어옴 · 뛰어 들어옴 | H5: 사회성 — 환경 | I5: 양쪽·각성 | AD5: SOC_E | AE5: =IF($J5="",0,IF(INDEX($C5:$G5,$J5)="",0,$J5)) | AF5: =IF($K5="",0,IF(INDEX($C5:$G5,$K5)="",0,$K5)) | AG5: =IF($L5="",0,IF(INDEX($C5:$G5,$L5)="",0,$L5)) | AH5: =IF($M5="",0,IF(INDEX($C5:$G5,$M5)="",0,$M5)) | AI5: =IF($N5="",0,IF(INDEX($C5:$G5,$N5)="",0,$N5)) | AJ5: =IF($O5="",0,IF(INDEX($C5:$G5,$O5)="",0,$O5)) | AK5: =IF($P5="",0,IF(INDEX($C5:$G5,$P5)="",0,$P5)) | AL5: =IF($Q5="",0,IF(INDEX($C5:$G5,$Q5)="",0,$Q5)) | AM5: =IF($R5="",0,IF(INDEX($C5:$G5,$R5)="",0,$R5)) | AN5: =IF($S5="",0,IF(INDEX($C5:$G5,$S5)="",0,$S5)) | AO5: =IF($T5="",0,IF(INDEX($C5:$G5,$T5)="",0,$T5)) | AP5: =IF($U5="",0,IF(INDEX($C5:$G5,$U5)="",0,$U5)) | AQ5: =IF($V5="",0,IF(INDEX($C5:$G5,$V5)="",0,$V5)) | AR5: =IF($W5="",0,IF(INDEX($C5:$G5,$W5)="",0,$W5)) | AS5: =IF($X5="",0,IF(INDEX($C5:$G5,$X5)="",0,$X5)) | AT5: =IF($Y5="",0,IF(INDEX($C5:$G5,$Y5)="",0,$Y5)) | AU5: =IF($Z5="",0,IF(INDEX($C5:$G5,$Z5)="",0,$Z5)) | AV5: =IF($AA5="",0,IF(INDEX($C5:$G5,$AA5)="",0,$AA5)) | AW5: =IF($AB5="",0,IF(INDEX($C5:$G5,$AB5)="",0,$AB5)) | AX5: =IF($AC5="",0,IF(INDEX($C5:$G5,$AC5)="",0,$AC5)) | AY5: BI
A6: 입장 | B6: [입장] 비닐 바닥 통과 — 스스로 밟는가 | C6: 올라가지 않음 · 돌아서 감 · 버팀 | D6: 머뭇거리다 뒤처져 밟음 | E6: 잠깐 살피고 스스로 지나감 | F6: 살피지 않고 그냥 지나감 | G6: 뛰어서 통과 · 밟는 줄도 모름 | H6: 사회성 — 환경 | I6: 양쪽·사회화 | AD6: SOC_E | AE6: =IF($J6="",0,IF(INDEX($C6:$G6,$J6)="",0,$J6)) | AF6: =IF($K6="",0,IF(INDEX($C6:$G6,$K6)="",0,$K6)) | AG6: =IF($L6="",0,IF(INDEX($C6:$G6,$L6)="",0,$L6)) | AH6: =IF($M6="",0,IF(INDEX($C6:$G6,$M6)="",0,$M6)) | AI6: =IF($N6="",0,IF(INDEX($C6:$G6,$N6)="",0,$N6)) | AJ6: =IF($O6="",0,IF(INDEX($C6:$G6,$O6)="",0,$O6)) | AK6: =IF($P6="",0,IF(INDEX($C6:$G6,$P6)="",0,$P6)) | AL6: =IF($Q6="",0,IF(INDEX($C6:$G6,$Q6)="",0,$Q6)) | AM6: =IF($R6="",0,IF(INDEX($C6:$G6,$R6)="",0,$R6)) | AN6: =IF($S6="",0,IF(INDEX($C6:$G6,$S6)="",0,$S6)) | AO6: =IF($T6="",0,IF(INDEX($C6:$G6,$T6)="",0,$T6)) | AP6: =IF($U6="",0,IF(INDEX($C6:$G6,$U6)="",0,$U6)) | AQ6: =IF($V6="",0,IF(INDEX($C6:$G6,$V6)="",0,$V6)) | AR6: =IF($W6="",0,IF(INDEX($C6:$G6,$W6)="",0,$W6)) | AS6: =IF($X6="",0,IF(INDEX($C6:$G6,$X6)="",0,$X6)) | AT6: =IF($Y6="",0,IF(INDEX($C6:$G6,$Y6)="",0,$Y6)) | AU6: =IF($Z6="",0,IF(INDEX($C6:$G6,$Z6)="",0,$Z6)) | AV6: =IF($AA6="",0,IF(INDEX($C6:$G6,$AA6)="",0,$AA6)) | AW6: =IF($AB6="",0,IF(INDEX($C6:$G6,$AB6)="",0,$AB6)) | AX6: =IF($AC6="",0,IF(INDEX($C6:$G6,$AC6)="",0,$AC6)) | AY6: BI
A7: 입장 | B7: [입장] 냄새 — 코를 쓰는가 | E7: 맡음 — 바닥이나 물체에 코를 댐 | G7: 안 맡음 | H7: — 참고 · 입장↔퇴장 비교용 | I7: 참고 | AE7: 0 | AF7: 0 | AG7: 0 | AH7: 0 | AI7: 0 | AJ7: 0 | AK7: 0 | AL7: 0 | AM7: 0 | AN7: 0 | AO7: 0 | AP7: 0 | AQ7: 0 | AR7: 0 | AS7: 0 | AT7: 0 | AU7: 0 | AV7: 0 | AW7: 0 | AX7: 0
A8: 기준 | B8: [기준] 각성 ※목줄을 푼 직후 10초 · 모든 해석의 바탕 | C8: 얼어붙어 움직이지 않음 | D8: 웅크리고 거의 움직이지 않음 | E8: 편안히 앉거나 서서 둘러봄 | F8: 계속 움직임 · 자리를 못 잡음 | G8: 한시도 가만있지 못함 · 심하게 안절부절 | H8: — 참고 (기준선) | I8: 참고 | AE8: 0 | AF8: 0 | AG8: 0 | AH8: 0 | AI8: 0 | AJ8: 0 | AK8: 0 | AL8: 0 | AM8: 0 | AN8: 0 | AO8: 0 | AP8: 0 | AQ8: 0 | AR8: 0 | AS8: 0 | AT8: 0 | AU8: 0 | AV8: 0 | AW8: 0 | AX8: 0
A9: 혼자 | B9: [혼자] 블라인드(나간 쪽) 지향 ★핵심 애착지표 | C9: 문 울타리에 붙어서 긁음, 낑낑거림. | D9: 문앞에서 처다보고 있음 | E9: 문앞까지 따라온 뒤 스스로 시간을 보냄. | F9: 문앞까지 따라오다 말음. 보호자가 나가는것을 늦게발견하고 따라왔다 다시 자기행동을 함 | G9: 나간 것을 알아차린 기색이 전혀 없음 | H9: 친밀·애착 | I9: 양쪽·애착 | AD9: ATT | AE9: =IF($J9="",0,IF(INDEX($C9:$G9,$J9)="",0,$J9)) | AF9: =IF($K9="",0,IF(INDEX($C9:$G9,$K9)="",0,$K9)) | AG9: =IF($L9="",0,IF(INDEX($C9:$G9,$L9)="",0,$L9)) | AH9: =IF($M9="",0,IF(INDEX($C9:$G9,$M9)="",0,$M9)) | AI9: =IF($N9="",0,IF(INDEX($C9:$G9,$N9)="",0,$N9)) | AJ9: =IF($O9="",0,IF(INDEX($C9:$G9,$O9)="",0,$O9)) | AK9: =IF($P9="",0,IF(INDEX($C9:$G9,$P9)="",0,$P9)) | AL9: =IF($Q9="",0,IF(INDEX($C9:$G9,$Q9)="",0,$Q9)) | AM9: =IF($R9="",0,IF(INDEX($C9:$G9,$R9)="",0,$R9)) | AN9: =IF($S9="",0,IF(INDEX($C9:$G9,$S9)="",0,$S9)) | AO9: =IF($T9="",0,IF(INDEX($C9:$G9,$T9)="",0,$T9)) | AP9: =IF($U9="",0,IF(INDEX($C9:$G9,$U9)="",0,$U9)) | AQ9: =IF($V9="",0,IF(INDEX($C9:$G9,$V9)="",0,$V9)) | AR9: =IF($W9="",0,IF(INDEX($C9:$G9,$W9)="",0,$W9)) | AS9: =IF($X9="",0,IF(INDEX($C9:$G9,$X9)="",0,$X9)) | AT9: =IF($Y9="",0,IF(INDEX($C9:$G9,$Y9)="",0,$Y9)) | AU9: =IF($Z9="",0,IF(INDEX($C9:$G9,$Z9)="",0,$Z9)) | AV9: =IF($AA9="",0,IF(INDEX($C9:$G9,$AA9)="",0,$AA9)) | AW9: =IF($AB9="",0,IF(INDEX($C9:$G9,$AB9)="",0,$AB9)) | AX9: =IF($AC9="",0,IF(INDEX($C9:$G9,$AC9)="",0,$AC9)) | AY9: BI
A10: 혼자 | B10: [혼자] 각성 | C10: 한자리에 얼어붙어 움직이지 않음 | D10: 구석 · 매트 한쪽에 웅크려 머묾 | E10: 안정적으로 머물며 가끔 둘러봄 | F10: 왔다갔다 반복 · 안절부절 | G10: 울타리 긁음 · 넘으려 함 · 패닉 (즉시 중단) | H10: 친밀·애착 | I10: 양쪽·각성 | AD10: ATT | AE10: =IF($J10="",0,IF(INDEX($C10:$G10,$J10)="",0,$J10)) | AF10: =IF($K10="",0,IF(INDEX($C10:$G10,$K10)="",0,$K10)) | AG10: =IF($L10="",0,IF(INDEX($C10:$G10,$L10)="",0,$L10)) | AH10: =IF($M10="",0,IF(INDEX($C10:$G10,$M10)="",0,$M10)) | AI10: =IF($N10="",0,IF(INDEX($C10:$G10,$N10)="",0,$N10)) | AJ10: =IF($O10="",0,IF(INDEX($C10:$G10,$O10)="",0,$O10)) | AK10: =IF($P10="",0,IF(INDEX($C10:$G10,$P10)="",0,$P10)) | AL10: =IF($Q10="",0,IF(INDEX($C10:$G10,$Q10)="",0,$Q10)) | AM10: =IF($R10="",0,IF(INDEX($C10:$G10,$R10)="",0,$R10)) | AN10: =IF($S10="",0,IF(INDEX($C10:$G10,$S10)="",0,$S10)) | AO10: =IF($T10="",0,IF(INDEX($C10:$G10,$T10)="",0,$T10)) | AP10: =IF($U10="",0,IF(INDEX($C10:$G10,$U10)="",0,$U10)) | AQ10: =IF($V10="",0,IF(INDEX($C10:$G10,$V10)="",0,$V10)) | AR10: =IF($W10="",0,IF(INDEX($C10:$G10,$W10)="",0,$W10)) | AS10: =IF($X10="",0,IF(INDEX($C10:$G10,$X10)="",0,$X10)) | AT10: =IF($Y10="",0,IF(INDEX($C10:$G10,$Y10)="",0,$Y10)) | AU10: =IF($Z10="",0,IF(INDEX($C10:$G10,$Z10)="",0,$Z10)) | AV10: =IF($AA10="",0,IF(INDEX($C10:$G10,$AA10)="",0,$AA10)) | AW10: =IF($AB10="",0,IF(INDEX($C10:$G10,$AB10)="",0,$AB10)) | AX10: =IF($AC10="",0,IF(INDEX($C10:$G10,$AC10)="",0,$AC10)) | AY10: BI
A11: 혼자 | B11: [혼자] 발성 ※각성의 보조 | C11: 지속적인 낑낑소리 | D11: 가끔 낑낑 | E11: 없음 | F11: 한두 번 짖음 | G11: 여러 번 짖음 | H11: — 참고 · 각성의 보조 | I11: 참고 | AE11: 0 | AF11: 0 | AG11: 0 | AH11: 0 | AI11: 0 | AJ11: 0 | AK11: 0 | AL11: 0 | AM11: 0 | AN11: 0 | AO11: 0 | AP11: 0 | AQ11: 0 | AR11: 0 | AS11: 0 | AT11: 0 | AU11: 0 | AV11: 0 | AW11: 0 | AX11: 0
A12: 혼자 | B12: [혼자] 탐색량 변화 ※균형설계 불가 · 판정 제외 | C12: 보호자가 있을 때도 탐색이 거의 없다 | D12: 멀리 떨어지지 않고 탐색한다 | E12: 있을 때 탐색하고 나간 뒤 눈에 띄게 줄어든다 | F12: 잠시 신경 쓰고 탐색한다 | G12: 없어져도 있을 때와 마찬가지로 탐색 | H12: — 참고 (Rehn 2013 · 순서효과) | I12: 참고 | AE12: 0 | AF12: 0 | AG12: 0 | AH12: 0 | AI12: 0 | AJ12: 0 | AK12: 0 | AL12: 0 | AM12: 0 | AN12: 0 | AO12: 0 | AP12: 0 | AQ12: 0 | AR12: 0 | AS12: 0 | AT12: 0 | AU12: 0 | AV12: 0 | AW12: 0 | AX12: 0
A13: 낯선 | B13: [낯선] 우호성 — 다가가는가 ※거리로만 봅니다 | C13: 2 m 밖에서 벗어나지 않음 · 등을 돌림 | D13: 거리를 두고 지켜보기만 함 | E13: 다가가 냄새 맡고 스스로 물러남 | F13: 계속 붙어 다님 | G13: 뛰어오름 · 매달림 · 떨어지지 않음 | H13: 사회성 — 사람 | I13: 양쪽·우호 | AD13: SOC_H | AE13: =IF($J13="",0,IF(INDEX($C13:$G13,$J13)="",0,$J13)) | AF13: =IF($K13="",0,IF(INDEX($C13:$G13,$K13)="",0,$K13)) | AG13: =IF($L13="",0,IF(INDEX($C13:$G13,$L13)="",0,$L13)) | AH13: =IF($M13="",0,IF(INDEX($C13:$G13,$M13)="",0,$M13)) | AI13: =IF($N13="",0,IF(INDEX($C13:$G13,$N13)="",0,$N13)) | AJ13: =IF($O13="",0,IF(INDEX($C13:$G13,$O13)="",0,$O13)) | AK13: =IF($P13="",0,IF(INDEX($C13:$G13,$P13)="",0,$P13)) | AL13: =IF($Q13="",0,IF(INDEX($C13:$G13,$Q13)="",0,$Q13)) | AM13: =IF($R13="",0,IF(INDEX($C13:$G13,$R13)="",0,$R13)) | AN13: =IF($S13="",0,IF(INDEX($C13:$G13,$S13)="",0,$S13)) | AO13: =IF($T13="",0,IF(INDEX($C13:$G13,$T13)="",0,$T13)) | AP13: =IF($U13="",0,IF(INDEX($C13:$G13,$U13)="",0,$U13)) | AQ13: =IF($V13="",0,IF(INDEX($C13:$G13,$V13)="",0,$V13)) | AR13: =IF($W13="",0,IF(INDEX($C13:$G13,$W13)="",0,$W13)) | AS13: =IF($X13="",0,IF(INDEX($C13:$G13,$X13)="",0,$X13)) | AT13: =IF($Y13="",0,IF(INDEX($C13:$G13,$Y13)="",0,$Y13)) | AU13: =IF($Z13="",0,IF(INDEX($C13:$G13,$Z13)="",0,$Z13)) | AV13: =IF($AA13="",0,IF(INDEX($C13:$G13,$AA13)="",0,$AA13)) | AW13: =IF($AB13="",0,IF(INDEX($C13:$G13,$AB13)="",0,$AB13)) | AX13: =IF($AC13="",0,IF(INDEX($C13:$G13,$AC13)="",0,$AC13)) | AY13: BI
A14: 낯선 | B14: [낯선] 각성 ※들떴는가 굳었는가만 봅니다 | C14: 얼어붙음 · 굳어서 움직이지 않음 | D14: 웅크림 · 조심스럽게 움직임 | E14: 편안히 움직임 | F14: 들떠서 계속 움직임 | G14: 짖음 · 안절부절 · 가만있지 못함 | H14: 사회성 — 사람 | I14: 양쪽·각성 | AD14: SOC_H | AE14: =IF($J14="",0,IF(INDEX($C14:$G14,$J14)="",0,$J14)) | AF14: =IF($K14="",0,IF(INDEX($C14:$G14,$K14)="",0,$K14)) | AG14: =IF($L14="",0,IF(INDEX($C14:$G14,$L14)="",0,$L14)) | AH14: =IF($M14="",0,IF(INDEX($C14:$G14,$M14)="",0,$M14)) | AI14: =IF($N14="",0,IF(INDEX($C14:$G14,$N14)="",0,$N14)) | AJ14: =IF($O14="",0,IF(INDEX($C14:$G14,$O14)="",0,$O14)) | AK14: =IF($P14="",0,IF(INDEX($C14:$G14,$P14)="",0,$P14)) | AL14: =IF($Q14="",0,IF(INDEX($C14:$G14,$Q14)="",0,$Q14)) | AM14: =IF($R14="",0,IF(INDEX($C14:$G14,$R14)="",0,$R14)) | AN14: =IF($S14="",0,IF(INDEX($C14:$G14,$S14)="",0,$S14)) | AO14: =IF($T14="",0,IF(INDEX($C14:$G14,$T14)="",0,$T14)) | AP14: =IF($U14="",0,IF(INDEX($C14:$G14,$U14)="",0,$U14)) | AQ14: =IF($V14="",0,IF(INDEX($C14:$G14,$V14)="",0,$V14)) | AR14: =IF($W14="",0,IF(INDEX($C14:$G14,$W14)="",0,$W14)) | AS14: =IF($X14="",0,IF(INDEX($C14:$G14,$X14)="",0,$X14)) | AT14: =IF($Y14="",0,IF(INDEX($C14:$G14,$Y14)="",0,$Y14)) | AU14: =IF($Z14="",0,IF(INDEX($C14:$G14,$Z14)="",0,$Z14)) | AV14: =IF($AA14="",0,IF(INDEX($C14:$G14,$AA14)="",0,$AA14)) | AW14: =IF($AB14="",0,IF(INDEX($C14:$G14,$AB14)="",0,$AB14)) | AX14: =IF($AC14="",0,IF(INDEX($C14:$G14,$AC14)="",0,$AC14)) | AY14: BI
A15: 낯선 | B15: [낯선] 이름을 불렀을 때 ★보호자 부름과 비교 | C15: 매달림 · 떨어지지 않음 | D15: 바로 와서 몸을 붙임 | E15: 와서 살피고 스스로 물러남 | F15: 고개만 돌림 · 오지 않음 | G15: 반응 없음 · 계속 딴 것을 함 | H15: 사회성 — 사람 | I15: 양쪽·우호 | AD15: SOC_H | AE15: =IF($J15="",0,IF(INDEX($C15:$G15,$J15)="",0,$J15)) | AF15: =IF($K15="",0,IF(INDEX($C15:$G15,$K15)="",0,$K15)) | AG15: =IF($L15="",0,IF(INDEX($C15:$G15,$L15)="",0,$L15)) | AH15: =IF($M15="",0,IF(INDEX($C15:$G15,$M15)="",0,$M15)) | AI15: =IF($N15="",0,IF(INDEX($C15:$G15,$N15)="",0,$N15)) | AJ15: =IF($O15="",0,IF(INDEX($C15:$G15,$O15)="",0,$O15)) | AK15: =IF($P15="",0,IF(INDEX($C15:$G15,$P15)="",0,$P15)) | AL15: =IF($Q15="",0,IF(INDEX($C15:$G15,$Q15)="",0,$Q15)) | AM15: =IF($R15="",0,IF(INDEX($C15:$G15,$R15)="",0,$R15)) | AN15: =IF($S15="",0,IF(INDEX($C15:$G15,$S15)="",0,$S15)) | AO15: =IF($T15="",0,IF(INDEX($C15:$G15,$T15)="",0,$T15)) | AP15: =IF($U15="",0,IF(INDEX($C15:$G15,$U15)="",0,$U15)) | AQ15: =IF($V15="",0,IF(INDEX($C15:$G15,$V15)="",0,$V15)) | AR15: =IF($W15="",0,IF(INDEX($C15:$G15,$W15)="",0,$W15)) | AS15: =IF($X15="",0,IF(INDEX($C15:$G15,$X15)="",0,$X15)) | AT15: =IF($Y15="",0,IF(INDEX($C15:$G15,$Y15)="",0,$Y15)) | AU15: =IF($Z15="",0,IF(INDEX($C15:$G15,$Z15)="",0,$Z15)) | AV15: =IF($AA15="",0,IF(INDEX($C15:$G15,$AA15)="",0,$AA15)) | AW15: =IF($AB15="",0,IF(INDEX($C15:$G15,$AB15)="",0,$AB15)) | AX15: =IF($AC15="",0,IF(INDEX($C15:$G15,$AC15)="",0,$AC15)) | AY15: BI
A16: 재회 | B16: [재회] 다가오는가 ※보호자가 들어와 의자에 앉을 때까지 | C16: 걸어가는 내내 매달려 떨어지지 않음 | D16: 바로 다가와 몸을 붙임 | E16: 다가와 인사하고 스스로 물러남 | F16: 한 번 쳐다보고 만다 | G16: 본체만체 · 오지 않음 | H16: 친밀·애착 | I16: 양쪽·애착 | AD16: ATT | AE16: =IF($J16="",0,IF(INDEX($C16:$G16,$J16)="",0,$J16)) | AF16: =IF($K16="",0,IF(INDEX($C16:$G16,$K16)="",0,$K16)) | AG16: =IF($L16="",0,IF(INDEX($C16:$G16,$L16)="",0,$L16)) | AH16: =IF($M16="",0,IF(INDEX($C16:$G16,$M16)="",0,$M16)) | AI16: =IF($N16="",0,IF(INDEX($C16:$G16,$N16)="",0,$N16)) | AJ16: =IF($O16="",0,IF(INDEX($C16:$G16,$O16)="",0,$O16)) | AK16: =IF($P16="",0,IF(INDEX($C16:$G16,$P16)="",0,$P16)) | AL16: =IF($Q16="",0,IF(INDEX($C16:$G16,$Q16)="",0,$Q16)) | AM16: =IF($R16="",0,IF(INDEX($C16:$G16,$R16)="",0,$R16)) | AN16: =IF($S16="",0,IF(INDEX($C16:$G16,$S16)="",0,$S16)) | AO16: =IF($T16="",0,IF(INDEX($C16:$G16,$T16)="",0,$T16)) | AP16: =IF($U16="",0,IF(INDEX($C16:$G16,$U16)="",0,$U16)) | AQ16: =IF($V16="",0,IF(INDEX($C16:$G16,$V16)="",0,$V16)) | AR16: =IF($W16="",0,IF(INDEX($C16:$G16,$W16)="",0,$W16)) | AS16: =IF($X16="",0,IF(INDEX($C16:$G16,$X16)="",0,$X16)) | AT16: =IF($Y16="",0,IF(INDEX($C16:$G16,$Y16)="",0,$Y16)) | AU16: =IF($Z16="",0,IF(INDEX($C16:$G16,$Z16)="",0,$Z16)) | AV16: =IF($AA16="",0,IF(INDEX($C16:$G16,$AA16)="",0,$AA16)) | AW16: =IF($AB16="",0,IF(INDEX($C16:$G16,$AB16)="",0,$AB16)) | AX16: =IF($AC16="",0,IF(INDEX($C16:$G16,$AC16)="",0,$AC16)) | AY16: BI
A17: 재회 | B17: [재회] 진정 ※앉은 뒤 · 혼자 때와 비교하면 「회복」이 나옵니다 | C17: 굳은 채로 있음 · 위축이 풀리지 않음 | D17: 조심스러운 상태가 이어짐 | E17: 금방 안정을 찾음 | F17: 들뜬 상태가 이어짐 | G17: 과흥분 · 20초 안에 안정 실패 | H17: 친밀·애착 | I17: 양쪽·각성 | AD17: ATT | AE17: =IF($J17="",0,IF(INDEX($C17:$G17,$J17)="",0,$J17)) | AF17: =IF($K17="",0,IF(INDEX($C17:$G17,$K17)="",0,$K17)) | AG17: =IF($L17="",0,IF(INDEX($C17:$G17,$L17)="",0,$L17)) | AH17: =IF($M17="",0,IF(INDEX($C17:$G17,$M17)="",0,$M17)) | AI17: =IF($N17="",0,IF(INDEX($C17:$G17,$N17)="",0,$N17)) | AJ17: =IF($O17="",0,IF(INDEX($C17:$G17,$O17)="",0,$O17)) | AK17: =IF($P17="",0,IF(INDEX($C17:$G17,$P17)="",0,$P17)) | AL17: =IF($Q17="",0,IF(INDEX($C17:$G17,$Q17)="",0,$Q17)) | AM17: =IF($R17="",0,IF(INDEX($C17:$G17,$R17)="",0,$R17)) | AN17: =IF($S17="",0,IF(INDEX($C17:$G17,$S17)="",0,$S17)) | AO17: =IF($T17="",0,IF(INDEX($C17:$G17,$T17)="",0,$T17)) | AP17: =IF($U17="",0,IF(INDEX($C17:$G17,$U17)="",0,$U17)) | AQ17: =IF($V17="",0,IF(INDEX($C17:$G17,$V17)="",0,$V17)) | AR17: =IF($W17="",0,IF(INDEX($C17:$G17,$W17)="",0,$W17)) | AS17: =IF($X17="",0,IF(INDEX($C17:$G17,$X17)="",0,$X17)) | AT17: =IF($Y17="",0,IF(INDEX($C17:$G17,$Y17)="",0,$Y17)) | AU17: =IF($Z17="",0,IF(INDEX($C17:$G17,$Z17)="",0,$Z17)) | AV17: =IF($AA17="",0,IF(INDEX($C17:$G17,$AA17)="",0,$AA17)) | AW17: =IF($AB17="",0,IF(INDEX($C17:$G17,$AB17)="",0,$AB17)) | AX17: =IF($AC17="",0,IF(INDEX($C17:$G17,$AC17)="",0,$AC17)) | AY17: BI
A18: 재회 | B18: [재회 접촉] 몸의 중심 ★앉은 뒤 이름을 부르고 만질 때 | C18: 몸을 얹거나 무릎에 올라감 · 기대어 떨어지지 않음 | D18: 몸이 닿을 만큼 앞으로 붙임 | E18: 앞으로 살짝 기울여 손을 받음 | F18: 선 자리를 지킴 · 몸을 앞으로 옮기지 않음 | G18: 뒤로 물러남 · 옆으로 피함 · 등을 돌림 | H18: 친밀·애착 | I18: 양쪽·애착 | AD18: ATT | AE18: =IF($J18="",0,IF(INDEX($C18:$G18,$J18)="",0,$J18)) | AF18: =IF($K18="",0,IF(INDEX($C18:$G18,$K18)="",0,$K18)) | AG18: =IF($L18="",0,IF(INDEX($C18:$G18,$L18)="",0,$L18)) | AH18: =IF($M18="",0,IF(INDEX($C18:$G18,$M18)="",0,$M18)) | AI18: =IF($N18="",0,IF(INDEX($C18:$G18,$N18)="",0,$N18)) | AJ18: =IF($O18="",0,IF(INDEX($C18:$G18,$O18)="",0,$O18)) | AK18: =IF($P18="",0,IF(INDEX($C18:$G18,$P18)="",0,$P18)) | AL18: =IF($Q18="",0,IF(INDEX($C18:$G18,$Q18)="",0,$Q18)) | AM18: =IF($R18="",0,IF(INDEX($C18:$G18,$R18)="",0,$R18)) | AN18: =IF($S18="",0,IF(INDEX($C18:$G18,$S18)="",0,$S18)) | AO18: =IF($T18="",0,IF(INDEX($C18:$G18,$T18)="",0,$T18)) | AP18: =IF($U18="",0,IF(INDEX($C18:$G18,$U18)="",0,$U18)) | AQ18: =IF($V18="",0,IF(INDEX($C18:$G18,$V18)="",0,$V18)) | AR18: =IF($W18="",0,IF(INDEX($C18:$G18,$W18)="",0,$W18)) | AS18: =IF($X18="",0,IF(INDEX($C18:$G18,$X18)="",0,$X18)) | AT18: =IF($Y18="",0,IF(INDEX($C18:$G18,$Y18)="",0,$Y18)) | AU18: =IF($Z18="",0,IF(INDEX($C18:$G18,$Z18)="",0,$Z18)) | AV18: =IF($AA18="",0,IF(INDEX($C18:$G18,$AA18)="",0,$AA18)) | AW18: =IF($AB18="",0,IF(INDEX($C18:$G18,$AB18)="",0,$AB18)) | AX18: =IF($AC18="",0,IF(INDEX($C18:$G18,$AC18)="",0,$AC18)) | AY18: BI
A19: 재회 | B19: [재회 접촉] 꼬리 ★앉은 뒤 이름을 부르고 만질 때 | C19: 다리 사이로 말아 넣음 | D19: 아래로 늘어뜨린 채 거의 흔들지 않음 | E19: 등선 아래에서 부드럽게 흔듦 | F19: 등선 높이로 올려 크게 흔듦 | G19: 등선보다 높이 들고 빠르게 흔듦 · 온몸이 함께 흔들림 | H19: 친밀·애착 | I19: 양쪽·각성 | AD19: ATT | AE19: =IF($J19="",0,IF(INDEX($C19:$G19,$J19)="",0,$J19)) | AF19: =IF($K19="",0,IF(INDEX($C19:$G19,$K19)="",0,$K19)) | AG19: =IF($L19="",0,IF(INDEX($C19:$G19,$L19)="",0,$L19)) | AH19: =IF($M19="",0,IF(INDEX($C19:$G19,$M19)="",0,$M19)) | AI19: =IF($N19="",0,IF(INDEX($C19:$G19,$N19)="",0,$N19)) | AJ19: =IF($O19="",0,IF(INDEX($C19:$G19,$O19)="",0,$O19)) | AK19: =IF($P19="",0,IF(INDEX($C19:$G19,$P19)="",0,$P19)) | AL19: =IF($Q19="",0,IF(INDEX($C19:$G19,$Q19)="",0,$Q19)) | AM19: =IF($R19="",0,IF(INDEX($C19:$G19,$R19)="",0,$R19)) | AN19: =IF($S19="",0,IF(INDEX($C19:$G19,$S19)="",0,$S19)) | AO19: =IF($T19="",0,IF(INDEX($C19:$G19,$T19)="",0,$T19)) | AP19: =IF($U19="",0,IF(INDEX($C19:$G19,$U19)="",0,$U19)) | AQ19: =IF($V19="",0,IF(INDEX($C19:$G19,$V19)="",0,$V19)) | AR19: =IF($W19="",0,IF(INDEX($C19:$G19,$W19)="",0,$W19)) | AS19: =IF($X19="",0,IF(INDEX($C19:$G19,$X19)="",0,$X19)) | AT19: =IF($Y19="",0,IF(INDEX($C19:$G19,$Y19)="",0,$Y19)) | AU19: =IF($Z19="",0,IF(INDEX($C19:$G19,$Z19)="",0,$Z19)) | AV19: =IF($AA19="",0,IF(INDEX($C19:$G19,$AA19)="",0,$AA19)) | AW19: =IF($AB19="",0,IF(INDEX($C19:$G19,$AB19)="",0,$AB19)) | AX19: =IF($AC19="",0,IF(INDEX($C19:$G19,$AC19)="",0,$AC19)) | AY19: BI
A20: 재회 | B20: [재회] 접근의 일관성 ※횟수 · 점수가 아닙니다 | C20: 재회에서 다음이 몇 번 나왔는지 셉니다 — 다가오다 멈춤 · 다가오면서 고개를 돌림 · 보호자를 지나쳐 감 · 다가오다 돌아섬 · 그 자리에서 굳음. 하나라도 있으면 애착 유형이 「일관되지 않음」이 됩니다. | H20: — 참고 · 애착 유형 판정용 | I20: 참고 | AE20: 0 | AF20: 0 | AG20: 0 | AH20: 0 | AI20: 0 | AJ20: 0 | AK20: 0 | AL20: 0 | AM20: 0 | AN20: 0 | AO20: 0 | AP20: 0 | AQ20: 0 | AR20: 0 | AS20: 0 | AT20: 0 | AU20: 0 | AV20: 0 | AW20: 0 | AX20: 0
A21: 무시 | B21: [무시] 접촉 개시 — 먼저 다가가는가 ※만져 준 뒤 반응을 끊었을 때 | C21: 무릎에 올라감 · 몸을 얹고 떨어지지 않음 | D21: 몸이 닿는 거리로 붙어 있음 | E21: 주변 1 m 안에 있으며 가끔 확인 | F21: 떨어져 있고 가끔만 쳐다봄 | G21: 한 번도 쳐다보지 않음 · 혼자 다님 | H21: 친밀·애착 | I21: 양쪽·애착 | AD21: ATT | AE21: =IF($J21="",0,IF(INDEX($C21:$G21,$J21)="",0,$J21)) | AF21: =IF($K21="",0,IF(INDEX($C21:$G21,$K21)="",0,$K21)) | AG21: =IF($L21="",0,IF(INDEX($C21:$G21,$L21)="",0,$L21)) | AH21: =IF($M21="",0,IF(INDEX($C21:$G21,$M21)="",0,$M21)) | AI21: =IF($N21="",0,IF(INDEX($C21:$G21,$N21)="",0,$N21)) | AJ21: =IF($O21="",0,IF(INDEX($C21:$G21,$O21)="",0,$O21)) | AK21: =IF($P21="",0,IF(INDEX($C21:$G21,$P21)="",0,$P21)) | AL21: =IF($Q21="",0,IF(INDEX($C21:$G21,$Q21)="",0,$Q21)) | AM21: =IF($R21="",0,IF(INDEX($C21:$G21,$R21)="",0,$R21)) | AN21: =IF($S21="",0,IF(INDEX($C21:$G21,$S21)="",0,$S21)) | AO21: =IF($T21="",0,IF(INDEX($C21:$G21,$T21)="",0,$T21)) | AP21: =IF($U21="",0,IF(INDEX($C21:$G21,$U21)="",0,$U21)) | AQ21: =IF($V21="",0,IF(INDEX($C21:$G21,$V21)="",0,$V21)) | AR21: =IF($W21="",0,IF(INDEX($C21:$G21,$W21)="",0,$W21)) | AS21: =IF($X21="",0,IF(INDEX($C21:$G21,$X21)="",0,$X21)) | AT21: =IF($Y21="",0,IF(INDEX($C21:$G21,$Y21)="",0,$Y21)) | AU21: =IF($Z21="",0,IF(INDEX($C21:$G21,$Z21)="",0,$Z21)) | AV21: =IF($AA21="",0,IF(INDEX($C21:$G21,$AA21)="",0,$AA21)) | AW21: =IF($AB21="",0,IF(INDEX($C21:$G21,$AB21)="",0,$AB21)) | AX21: =IF($AC21="",0,IF(INDEX($C21:$G21,$AC21)="",0,$AC21)) | AY21: BI
A22: 무시 | B22: [무시] 각성 ※기준 때와 비교하면 「적응」이 나옵니다 | C22: 얼어붙어 움직이지 않음 | D22: 웅크리고 거의 움직이지 않음 | E22: 편안히 앉거나 서서 둘러봄 | F22: 계속 움직임 · 자리를 못 잡음 | G22: 한시도 가만있지 못함 · 심하게 안절부절 | H22: 친밀·애착 | I22: 양쪽·각성 | AD22: ATT | AE22: =IF($J22="",0,IF(INDEX($C22:$G22,$J22)="",0,$J22)) | AF22: =IF($K22="",0,IF(INDEX($C22:$G22,$K22)="",0,$K22)) | AG22: =IF($L22="",0,IF(INDEX($C22:$G22,$L22)="",0,$L22)) | AH22: =IF($M22="",0,IF(INDEX($C22:$G22,$M22)="",0,$M22)) | AI22: =IF($N22="",0,IF(INDEX($C22:$G22,$N22)="",0,$N22)) | AJ22: =IF($O22="",0,IF(INDEX($C22:$G22,$O22)="",0,$O22)) | AK22: =IF($P22="",0,IF(INDEX($C22:$G22,$P22)="",0,$P22)) | AL22: =IF($Q22="",0,IF(INDEX($C22:$G22,$Q22)="",0,$Q22)) | AM22: =IF($R22="",0,IF(INDEX($C22:$G22,$R22)="",0,$R22)) | AN22: =IF($S22="",0,IF(INDEX($C22:$G22,$S22)="",0,$S22)) | AO22: =IF($T22="",0,IF(INDEX($C22:$G22,$T22)="",0,$T22)) | AP22: =IF($U22="",0,IF(INDEX($C22:$G22,$U22)="",0,$U22)) | AQ22: =IF($V22="",0,IF(INDEX($C22:$G22,$V22)="",0,$V22)) | AR22: =IF($W22="",0,IF(INDEX($C22:$G22,$W22)="",0,$W22)) | AS22: =IF($X22="",0,IF(INDEX($C22:$G22,$X22)="",0,$X22)) | AT22: =IF($Y22="",0,IF(INDEX($C22:$G22,$Y22)="",0,$Y22)) | AU22: =IF($Z22="",0,IF(INDEX($C22:$G22,$Z22)="",0,$Z22)) | AV22: =IF($AA22="",0,IF(INDEX($C22:$G22,$AA22)="",0,$AA22)) | AW22: =IF($AB22="",0,IF(INDEX($C22:$G22,$AB22)="",0,$AB22)) | AX22: =IF($AC22="",0,IF(INDEX($C22:$G22,$AC22)="",0,$AC22)) | AY22: BI
A23: 걷기 | B23: [걷기] 거리 유지 | C23: 보호자 발에 걸릴 만큼 붙어 다님 | D23: 계속 몸이 닿을 거리로 따라다님 | E23: 1~2 m 간격을 유지 | F23: 3 m 이상 벌어짐 | G23: 평가 구역을 벗어남 · 보호자를 두고 감 | H23: 행동 동조 | I23: 양쪽·거리 | AD23: SYN | AE23: =IF($J23="",0,IF(INDEX($C23:$G23,$J23)="",0,$J23)) | AF23: =IF($K23="",0,IF(INDEX($C23:$G23,$K23)="",0,$K23)) | AG23: =IF($L23="",0,IF(INDEX($C23:$G23,$L23)="",0,$L23)) | AH23: =IF($M23="",0,IF(INDEX($C23:$G23,$M23)="",0,$M23)) | AI23: =IF($N23="",0,IF(INDEX($C23:$G23,$N23)="",0,$N23)) | AJ23: =IF($O23="",0,IF(INDEX($C23:$G23,$O23)="",0,$O23)) | AK23: =IF($P23="",0,IF(INDEX($C23:$G23,$P23)="",0,$P23)) | AL23: =IF($Q23="",0,IF(INDEX($C23:$G23,$Q23)="",0,$Q23)) | AM23: =IF($R23="",0,IF(INDEX($C23:$G23,$R23)="",0,$R23)) | AN23: =IF($S23="",0,IF(INDEX($C23:$G23,$S23)="",0,$S23)) | AO23: =IF($T23="",0,IF(INDEX($C23:$G23,$T23)="",0,$T23)) | AP23: =IF($U23="",0,IF(INDEX($C23:$G23,$U23)="",0,$U23)) | AQ23: =IF($V23="",0,IF(INDEX($C23:$G23,$V23)="",0,$V23)) | AR23: =IF($W23="",0,IF(INDEX($C23:$G23,$W23)="",0,$W23)) | AS23: =IF($X23="",0,IF(INDEX($C23:$G23,$X23)="",0,$X23)) | AT23: =IF($Y23="",0,IF(INDEX($C23:$G23,$Y23)="",0,$Y23)) | AU23: =IF($Z23="",0,IF(INDEX($C23:$G23,$Z23)="",0,$Z23)) | AV23: =IF($AA23="",0,IF(INDEX($C23:$G23,$AA23)="",0,$AA23)) | AW23: =IF($AB23="",0,IF(INDEX($C23:$G23,$AB23)="",0,$AB23)) | AX23: =IF($AC23="",0,IF(INDEX($C23:$G23,$AC23)="",0,$AC23)) | AY23: BI
A24: 걷기 | B24: [걷기] 보호자 확인 ※시선 | C24: 계속 올려다봄 · 앞을 보지 않음 | D24: 자주 올려다보며 걸음 | E24: 이동 중 여러 번 확인하고 다시 앞을 봄 | F24: 한두 번 힐끗 | G24: 한 번도 쳐다보지 않음 | H24: 행동 동조 | I24: 양쪽·거리 | AD24: SYN | AE24: =IF($J24="",0,IF(INDEX($C24:$G24,$J24)="",0,$J24)) | AF24: =IF($K24="",0,IF(INDEX($C24:$G24,$K24)="",0,$K24)) | AG24: =IF($L24="",0,IF(INDEX($C24:$G24,$L24)="",0,$L24)) | AH24: =IF($M24="",0,IF(INDEX($C24:$G24,$M24)="",0,$M24)) | AI24: =IF($N24="",0,IF(INDEX($C24:$G24,$N24)="",0,$N24)) | AJ24: =IF($O24="",0,IF(INDEX($C24:$G24,$O24)="",0,$O24)) | AK24: =IF($P24="",0,IF(INDEX($C24:$G24,$P24)="",0,$P24)) | AL24: =IF($Q24="",0,IF(INDEX($C24:$G24,$Q24)="",0,$Q24)) | AM24: =IF($R24="",0,IF(INDEX($C24:$G24,$R24)="",0,$R24)) | AN24: =IF($S24="",0,IF(INDEX($C24:$G24,$S24)="",0,$S24)) | AO24: =IF($T24="",0,IF(INDEX($C24:$G24,$T24)="",0,$T24)) | AP24: =IF($U24="",0,IF(INDEX($C24:$G24,$U24)="",0,$U24)) | AQ24: =IF($V24="",0,IF(INDEX($C24:$G24,$V24)="",0,$V24)) | AR24: =IF($W24="",0,IF(INDEX($C24:$G24,$W24)="",0,$W24)) | AS24: =IF($X24="",0,IF(INDEX($C24:$G24,$X24)="",0,$X24)) | AT24: =IF($Y24="",0,IF(INDEX($C24:$G24,$Y24)="",0,$Y24)) | AU24: =IF($Z24="",0,IF(INDEX($C24:$G24,$Z24)="",0,$Z24)) | AV24: =IF($AA24="",0,IF(INDEX($C24:$G24,$AA24)="",0,$AA24)) | AW24: =IF($AB24="",0,IF(INDEX($C24:$G24,$AB24)="",0,$AB24)) | AX24: =IF($AC24="",0,IF(INDEX($C24:$G24,$AC24)="",0,$AC24)) | AY24: BI
A25: 걷기 | B25: [걷기] 동조 국면 수 ※0~6 · 점수가 아닙니다 | C25: 보호자가 움직이거나 멈춘 6국면(이동 3 · 정지 3) 중, 개가 3초 안에 같은 상태가 된 횟수를 셉니다. | H25: — 참고 (영역 집계 제외) | I25: 참고 | AE25: 0 | AF25: 0 | AG25: 0 | AH25: 0 | AI25: 0 | AJ25: 0 | AK25: 0 | AL25: 0 | AM25: 0 | AN25: 0 | AO25: 0 | AP25: 0 | AQ25: 0 | AR25: 0 | AS25: 0 | AT25: 0 | AU25: 0 | AV25: 0 | AW25: 0 | AX25: 0
A26: 걷기 | B26: [걷기] 동조율 ※자동 계산 · 입력하지 마세요 | C26: 동조 국면 수 ÷ 6. 시행 유효성이 3점이면 「무효」로 표시됩니다. | H26: — 참고 (영역 집계 제외) | I26: 참고 | J26: =IF(J25="","",IF('3_보호자행동'!J13=3,"무효",J25/6)) | K26: =IF(K25="","",IF('3_보호자행동'!K13=3,"무효",K25/6)) | L26: =IF(L25="","",IF('3_보호자행동'!L13=3,"무효",L25/6)) | M26: =IF(M25="","",IF('3_보호자행동'!M13=3,"무효",M25/6)) | N26: =IF(N25="","",IF('3_보호자행동'!N13=3,"무효",N25/6)) | O26: =IF(O25="","",IF('3_보호자행동'!O13=3,"무효",O25/6)) | P26: =IF(P25="","",IF('3_보호자행동'!P13=3,"무효",P25/6)) | Q26: =IF(Q25="","",IF('3_보호자행동'!Q13=3,"무효",Q25/6)) | ... AC26: =IF(AC25="","",IF('3_보호자행동'!AC13=3,"무효",AC25/6)) | AE26: 0 | AF26: 0 | AG26: 0 | AH26: 0 | AI26: 0 | AJ26: 0 | AK26: 0 | AL26: 0 | AM26: 0 | AN26: 0 | AO26: 0 | AP26: 0 | AQ26: 0 | AR26: 0 | AS26: 0 | AT26: 0 | AU26: 0 | AV26: 0 | AW26: 0 | AX26: 0
A27: 퇴장 | B27: [퇴장] 방 문 통과 — 나가는 쪽으로 가는가 | C27: 나가지 않으려 버팀 | D27: 리드줄을 당겨야 나감 | E27: 보호자를 따라 자연스럽게 나감 | F27: 앞질러 나감 | G27: 문 쪽으로 끌고 감 | H27: 퇴장 — 환경 적응 | I27: 양쪽·각성 | AD27: EXIT | AE27: =IF($J27="",0,IF(INDEX($C27:$G27,$J27)="",0,$J27)) | AF27: =IF($K27="",0,IF(INDEX($C27:$G27,$K27)="",0,$K27)) | AG27: =IF($L27="",0,IF(INDEX($C27:$G27,$L27)="",0,$L27)) | AH27: =IF($M27="",0,IF(INDEX($C27:$G27,$M27)="",0,$M27)) | AI27: =IF($N27="",0,IF(INDEX($C27:$G27,$N27)="",0,$N27)) | AJ27: =IF($O27="",0,IF(INDEX($C27:$G27,$O27)="",0,$O27)) | AK27: =IF($P27="",0,IF(INDEX($C27:$G27,$P27)="",0,$P27)) | AL27: =IF($Q27="",0,IF(INDEX($C27:$G27,$Q27)="",0,$Q27)) | AM27: =IF($R27="",0,IF(INDEX($C27:$G27,$R27)="",0,$R27)) | AN27: =IF($S27="",0,IF(INDEX($C27:$G27,$S27)="",0,$S27)) | AO27: =IF($T27="",0,IF(INDEX($C27:$G27,$T27)="",0,$T27)) | AP27: =IF($U27="",0,IF(INDEX($C27:$G27,$U27)="",0,$U27)) | AQ27: =IF($V27="",0,IF(INDEX($C27:$G27,$V27)="",0,$V27)) | AR27: =IF($W27="",0,IF(INDEX($C27:$G27,$W27)="",0,$W27)) | AS27: =IF($X27="",0,IF(INDEX($C27:$G27,$X27)="",0,$X27)) | AT27: =IF($Y27="",0,IF(INDEX($C27:$G27,$Y27)="",0,$Y27)) | AU27: =IF($Z27="",0,IF(INDEX($C27:$G27,$Z27)="",0,$Z27)) | AV27: =IF($AA27="",0,IF(INDEX($C27:$G27,$AA27)="",0,$AA27)) | AW27: =IF($AB27="",0,IF(INDEX($C27:$G27,$AB27)="",0,$AB27)) | AX27: =IF($AC27="",0,IF(INDEX($C27:$G27,$AC27)="",0,$AC27)) | AY27: BI
A28: 퇴장 | B28: [퇴장] 냄새 — 나가면서 코를 쓰는가 | E28: 맡음 — 바닥이나 물체에 코를 댐 | G28: 안 맡음 | H28: — 참고 · 입장↔퇴장 비교용 | I28: 참고 | AE28: 0 | AF28: 0 | AG28: 0 | AH28: 0 | AI28: 0 | AJ28: 0 | AK28: 0 | AL28: 0 | AM28: 0 | AN28: 0 | AO28: 0 | AP28: 0 | AQ28: 0 | AR28: 0 | AS28: 0 | AT28: 0 | AU28: 0 | AV28: 0 | AW28: 0 | AX28: 0

Sheet 3_보호자행동
A1: 보호자행동
A2: 보호자가 개를 대하는 방식. 구간을 나누지 않고 전 구간을 통틀어 한 번만 적습니다. 1·2 = 방임(무심·놓아둠), 4·5 = 과함(과잉통제·과잉반응).
A3: J열부터 오른쪽으로 1번~20번 강아지 칸입니다. 각 칸에 1~5 중 하나를 넣습니다. ★ 3점이 안정이고 1과 5, 2와 4가 서로 대치됩니다. 축이 넷입니다 — 「애착」 1 과잉↔5 없음 / 「우호」 1 경계↔5 과한 우호 / 「사회화」 1 회피↔5 살피지 않음 / 「각성」 1 위축↔5 흥분. I열에 적어 두었습니다. 회색 칸은 해당 단계가 없으며, 그 번호를 넣으면 무효 처리됩니다.
A4: 구간 | B4: 관찰 항목 | C4: 1 | D4: 2 | E4: 3 | F4: 4 | G4: 5 | H4: 영역 | I4: 척도·축 | J4: 1번 | K4: 2번 | L4: 3번 | M4: 4번 | N4: 5번 | O4: 6번 | P4: 7번 | Q4: 8번 | R4: 9번 | S4: 10번 | T4: 11번 | U4: 12번 | V4: 13번 | W4: 14번 | X4: 15번 | Y4: 16번 | Z4: 17번 | AA4: 18번 | AB4: 19번 | AC4: 20번 | AD4: 영역코드 | AY4: 척도
A5: 전 구간 | B5: 목소리 톤 ※입장 · 기준 10초 · 재회 · 퇴장에서 봅니다 | C5: 거의 말이 없음 · 반응 없음 | D5: 드물게 짧게만 말함 | E5: 평이하고 낮은 톤 | F5: 높고 빠름 | G5: 커지거나 날카로움 · 꾸짖음 | H5: 교육태도 | I5: 양쪽 | AD5: EDU | AE5: =IF($J5="",0,IF(INDEX($C5:$G5,$J5)="",0,$J5)) | AF5: =IF($K5="",0,IF(INDEX($C5:$G5,$K5)="",0,$K5)) | AG5: =IF($L5="",0,IF(INDEX($C5:$G5,$L5)="",0,$L5)) | AH5: =IF($M5="",0,IF(INDEX($C5:$G5,$M5)="",0,$M5)) | AI5: =IF($N5="",0,IF(INDEX($C5:$G5,$N5)="",0,$N5)) | AJ5: =IF($O5="",0,IF(INDEX($C5:$G5,$O5)="",0,$O5)) | AK5: =IF($P5="",0,IF(INDEX($C5:$G5,$P5)="",0,$P5)) | AL5: =IF($Q5="",0,IF(INDEX($C5:$G5,$Q5)="",0,$Q5)) | AM5: =IF($R5="",0,IF(INDEX($C5:$G5,$R5)="",0,$R5)) | AN5: =IF($S5="",0,IF(INDEX($C5:$G5,$S5)="",0,$S5)) | AO5: =IF($T5="",0,IF(INDEX($C5:$G5,$T5)="",0,$T5)) | AP5: =IF($U5="",0,IF(INDEX($C5:$G5,$U5)="",0,$U5)) | AQ5: =IF($V5="",0,IF(INDEX($C5:$G5,$V5)="",0,$V5)) | AR5: =IF($W5="",0,IF(INDEX($C5:$G5,$W5)="",0,$W5)) | AS5: =IF($X5="",0,IF(INDEX($C5:$G5,$X5)="",0,$X5)) | AT5: =IF($Y5="",0,IF(INDEX($C5:$G5,$Y5)="",0,$Y5)) | AU5: =IF($Z5="",0,IF(INDEX($C5:$G5,$Z5)="",0,$Z5)) | AV5: =IF($AA5="",0,IF(INDEX($C5:$G5,$AA5)="",0,$AA5)) | AW5: =IF($AB5="",0,IF(INDEX($C5:$G5,$AB5)="",0,$AB5)) | AX5: =IF($AC5="",0,IF(INDEX($C5:$G5,$AC5)="",0,$AC5)) | AY5: BI
A6: 전 구간 | B6: 리드줄 ※입장·퇴장에서만 보입니다 | C6: 방치 — 개가 시야 밖으로 가도 무반응 | D6: 줄을 늘어뜨린 채 신경 쓰지 않음 | E6: 느슨함 (U자 유지) | F6: 가끔 당김 | G6: 지속적으로 당김 | H6: 교육태도 | I6: 양쪽 | AD6: EDU | AE6: =IF($J6="",0,IF(INDEX($C6:$G6,$J6)="",0,$J6)) | AF6: =IF($K6="",0,IF(INDEX($C6:$G6,$K6)="",0,$K6)) | AG6: =IF($L6="",0,IF(INDEX($C6:$G6,$L6)="",0,$L6)) | AH6: =IF($M6="",0,IF(INDEX($C6:$G6,$M6)="",0,$M6)) | AI6: =IF($N6="",0,IF(INDEX($C6:$G6,$N6)="",0,$N6)) | AJ6: =IF($O6="",0,IF(INDEX($C6:$G6,$O6)="",0,$O6)) | AK6: =IF($P6="",0,IF(INDEX($C6:$G6,$P6)="",0,$P6)) | AL6: =IF($Q6="",0,IF(INDEX($C6:$G6,$Q6)="",0,$Q6)) | AM6: =IF($R6="",0,IF(INDEX($C6:$G6,$R6)="",0,$R6)) | AN6: =IF($S6="",0,IF(INDEX($C6:$G6,$S6)="",0,$S6)) | AO6: =IF($T6="",0,IF(INDEX($C6:$G6,$T6)="",0,$T6)) | AP6: =IF($U6="",0,IF(INDEX($C6:$G6,$U6)="",0,$U6)) | AQ6: =IF($V6="",0,IF(INDEX($C6:$G6,$V6)="",0,$V6)) | AR6: =IF($W6="",0,IF(INDEX($C6:$G6,$W6)="",0,$W6)) | AS6: =IF($X6="",0,IF(INDEX($C6:$G6,$X6)="",0,$X6)) | AT6: =IF($Y6="",0,IF(INDEX($C6:$G6,$Y6)="",0,$Y6)) | AU6: =IF($Z6="",0,IF(INDEX($C6:$G6,$Z6)="",0,$Z6)) | AV6: =IF($AA6="",0,IF(INDEX($C6:$G6,$AA6)="",0,$AA6)) | AW6: =IF($AB6="",0,IF(INDEX($C6:$G6,$AB6)="",0,$AB6)) | AX6: =IF($AC6="",0,IF(INDEX($C6:$G6,$AC6)="",0,$AC6)) | AY6: BI
A7: 전 구간 | B7: 지시·말 반복 ※입장 · 기준 10초 · 재회 · 퇴장에서 봅니다 | C7: 개를 놓침 · 말도 안 함 (방치) | D7: 말을 걸지 않고 지켜보기만 함 | E7: 1회만 말하고 기다림 | F7: 2~3회 반복 | G7: 4회 이상 · 지시어 뒤섞임 · 쉼 없이 연발 | H7: 교육태도 | I7: 양쪽 | AD7: EDU | AE7: =IF($J7="",0,IF(INDEX($C7:$G7,$J7)="",0,$J7)) | AF7: =IF($K7="",0,IF(INDEX($C7:$G7,$K7)="",0,$K7)) | AG7: =IF($L7="",0,IF(INDEX($C7:$G7,$L7)="",0,$L7)) | AH7: =IF($M7="",0,IF(INDEX($C7:$G7,$M7)="",0,$M7)) | AI7: =IF($N7="",0,IF(INDEX($C7:$G7,$N7)="",0,$N7)) | AJ7: =IF($O7="",0,IF(INDEX($C7:$G7,$O7)="",0,$O7)) | AK7: =IF($P7="",0,IF(INDEX($C7:$G7,$P7)="",0,$P7)) | AL7: =IF($Q7="",0,IF(INDEX($C7:$G7,$Q7)="",0,$Q7)) | AM7: =IF($R7="",0,IF(INDEX($C7:$G7,$R7)="",0,$R7)) | AN7: =IF($S7="",0,IF(INDEX($C7:$G7,$S7)="",0,$S7)) | AO7: =IF($T7="",0,IF(INDEX($C7:$G7,$T7)="",0,$T7)) | AP7: =IF($U7="",0,IF(INDEX($C7:$G7,$U7)="",0,$U7)) | AQ7: =IF($V7="",0,IF(INDEX($C7:$G7,$V7)="",0,$V7)) | AR7: =IF($W7="",0,IF(INDEX($C7:$G7,$W7)="",0,$W7)) | AS7: =IF($X7="",0,IF(INDEX($C7:$G7,$X7)="",0,$X7)) | AT7: =IF($Y7="",0,IF(INDEX($C7:$G7,$Y7)="",0,$Y7)) | AU7: =IF($Z7="",0,IF(INDEX($C7:$G7,$Z7)="",0,$Z7)) | AV7: =IF($AA7="",0,IF(INDEX($C7:$G7,$AA7)="",0,$AA7)) | AW7: =IF($AB7="",0,IF(INDEX($C7:$G7,$AB7)="",0,$AB7)) | AX7: =IF($AC7="",0,IF(INDEX($C7:$G7,$AC7)="",0,$AC7)) | AY7: BI
A8: 전 구간 | B8: 시선 — 개를 보려 하는가 ※무시 15초와 걷기는 빼고 봅니다 — 안 보는 것이 지시입니다 | E8: 개를 보고 있음 | F8: 가끔 다른 곳을 봄 | G8: 개를 거의 보지 않음 | H8: 교육태도 | I8: 한쪽 | AD8: EDU | AE8: =IF($J8="",0,IF(INDEX($C8:$G8,$J8)="",0,$J8)) | AF8: =IF($K8="",0,IF(INDEX($C8:$G8,$K8)="",0,$K8)) | AG8: =IF($L8="",0,IF(INDEX($C8:$G8,$L8)="",0,$L8)) | AH8: =IF($M8="",0,IF(INDEX($C8:$G8,$M8)="",0,$M8)) | AI8: =IF($N8="",0,IF(INDEX($C8:$G8,$N8)="",0,$N8)) | AJ8: =IF($O8="",0,IF(INDEX($C8:$G8,$O8)="",0,$O8)) | AK8: =IF($P8="",0,IF(INDEX($C8:$G8,$P8)="",0,$P8)) | AL8: =IF($Q8="",0,IF(INDEX($C8:$G8,$Q8)="",0,$Q8)) | AM8: =IF($R8="",0,IF(INDEX($C8:$G8,$R8)="",0,$R8)) | AN8: =IF($S8="",0,IF(INDEX($C8:$G8,$S8)="",0,$S8)) | AO8: =IF($T8="",0,IF(INDEX($C8:$G8,$T8)="",0,$T8)) | AP8: =IF($U8="",0,IF(INDEX($C8:$G8,$U8)="",0,$U8)) | AQ8: =IF($V8="",0,IF(INDEX($C8:$G8,$V8)="",0,$V8)) | AR8: =IF($W8="",0,IF(INDEX($C8:$G8,$W8)="",0,$W8)) | AS8: =IF($X8="",0,IF(INDEX($C8:$G8,$X8)="",0,$X8)) | AT8: =IF($Y8="",0,IF(INDEX($C8:$G8,$Y8)="",0,$Y8)) | AU8: =IF($Z8="",0,IF(INDEX($C8:$G8,$Z8)="",0,$Z8)) | AV8: =IF($AA8="",0,IF(INDEX($C8:$G8,$AA8)="",0,$AA8)) | AW8: =IF($AB8="",0,IF(INDEX($C8:$G8,$AB8)="",0,$AB8)) | AX8: =IF($AC8="",0,IF(INDEX($C8:$G8,$AC8)="",0,$AC8)) | AY8: ONE
A9: 전 구간 | B9: 유도 방식 ※개가 안 가려 할 때 · 입장과 퇴장 | C9: 개를 두고 먼저 감 · 그냥 끌려오게 둠 | D9: 아무 말 없이 기다리기만 함 | E9: 기다려주고 부드럽게 격려 · 먹이나 장난감으로 유도 | F9: 가볍게 재촉 · 리드줄 살짝 당김 · 큰 소리로 재촉 | G9: 리드줄 확 잡아챔 · 몸으로 밀어 넣음 · 안아서 옮김 | H9: 교육태도 | I9: 양쪽 | AD9: EDU | AE9: =IF($J9="",0,IF(INDEX($C9:$G9,$J9)="",0,$J9)) | AF9: =IF($K9="",0,IF(INDEX($C9:$G9,$K9)="",0,$K9)) | AG9: =IF($L9="",0,IF(INDEX($C9:$G9,$L9)="",0,$L9)) | AH9: =IF($M9="",0,IF(INDEX($C9:$G9,$M9)="",0,$M9)) | AI9: =IF($N9="",0,IF(INDEX($C9:$G9,$N9)="",0,$N9)) | AJ9: =IF($O9="",0,IF(INDEX($C9:$G9,$O9)="",0,$O9)) | AK9: =IF($P9="",0,IF(INDEX($C9:$G9,$P9)="",0,$P9)) | AL9: =IF($Q9="",0,IF(INDEX($C9:$G9,$Q9)="",0,$Q9)) | AM9: =IF($R9="",0,IF(INDEX($C9:$G9,$R9)="",0,$R9)) | AN9: =IF($S9="",0,IF(INDEX($C9:$G9,$S9)="",0,$S9)) | AO9: =IF($T9="",0,IF(INDEX($C9:$G9,$T9)="",0,$T9)) | AP9: =IF($U9="",0,IF(INDEX($C9:$G9,$U9)="",0,$U9)) | AQ9: =IF($V9="",0,IF(INDEX($C9:$G9,$V9)="",0,$V9)) | AR9: =IF($W9="",0,IF(INDEX($C9:$G9,$W9)="",0,$W9)) | AS9: =IF($X9="",0,IF(INDEX($C9:$G9,$X9)="",0,$X9)) | AT9: =IF($Y9="",0,IF(INDEX($C9:$G9,$Y9)="",0,$Y9)) | AU9: =IF($Z9="",0,IF(INDEX($C9:$G9,$Z9)="",0,$Z9)) | AV9: =IF($AA9="",0,IF(INDEX($C9:$G9,$AA9)="",0,$AA9)) | AW9: =IF($AB9="",0,IF(INDEX($C9:$G9,$AB9)="",0,$AB9)) | AX9: =IF($AC9="",0,IF(INDEX($C9:$G9,$AC9)="",0,$AC9)) | AY9: BI
A10: 혼자 | B10: [분리] 나갈 때 ※참고 · 개 행동 해석용 | C10: 개를 보지도 않고 그냥 나감 | D10: 몰래 급히 나감 | E10: 차분히 나감 | F10: 과하게 인사하고 나감 | G10: 달래다 못 나감 · 여러 번 되돌아옴 | H10: — 참고 (영역 집계 제외) | I10: 참고 | AE10: 0 | AF10: 0 | AG10: 0 | AH10: 0 | AI10: 0 | AJ10: 0 | AK10: 0 | AL10: 0 | AM10: 0 | AN10: 0 | AO10: 0 | AP10: 0 | AQ10: 0 | AR10: 0 | AS10: 0 | AT10: 0 | AU10: 0 | AV10: 0 | AW10: 0 | AX10: 0
A11: 재회 | B11: [재회] 들어올 때 ※의자에 앉은 뒤 · 참고 | C11: 피하고 개가 뛰어오르면 밀어냄 · 통제 지시만 함 | D11: 수동적으로 인사를 받기만 함 | E11: 적극적으로 인사하고 친근한 톤으로 말함 | F11: 웃으며 들뜬 목소리로 인사 | G11: 크게 호들갑 · 개를 흥분시킴 | H11: — 참고 (영역 집계 제외) | I11: 참고 | AE11: 0 | AF11: 0 | AG11: 0 | AH11: 0 | AI11: 0 | AJ11: 0 | AK11: 0 | AL11: 0 | AM11: 0 | AN11: 0 | AO11: 0 | AP11: 0 | AQ11: 0 | AR11: 0 | AS11: 0 | AT11: 0 | AU11: 0 | AV11: 0 | AW11: 0 | AX11: 0
A12: 무시 | B12: [무시] 지시 준수 ※참고 · 조건 준수 확인 | C12: 15초 동안 말 · 시선 · 접촉 없음 — 유효 | D12: 한 번 보거나 말함 — 유효(주의) | E12: 두 번 이상 · 만짐 — 이 시행의 무시 항목 무효 | H12: — 참고 (영역 집계 제외) | I12: 참고 | AE12: 0 | AF12: 0 | AG12: 0 | AH12: 0 | AI12: 0 | AJ12: 0 | AK12: 0 | AL12: 0 | AM12: 0 | AN12: 0 | AO12: 0 | AP12: 0 | AQ12: 0 | AR12: 0 | AS12: 0 | AT12: 0 | AU12: 0 | AV12: 0 | AW12: 0 | AX12: 0
A13: 걷기 | B13: [걷기] 시행 유효성 ※참고 · 조건 준수 확인 | C13: 30초 동안 말·손짓 없음 — 유효 | D13: 한 번 부르거나 손짓함 — 유효(주의) | E13: 두 번 이상 — 이 시행의 걷기 항목과 동조율 무효 | H13: — 참고 (영역 집계 제외) | I13: 참고 | AE13: 0 | AF13: 0 | AG13: 0 | AH13: 0 | AI13: 0 | AJ13: 0 | AK13: 0 | AL13: 0 | AM13: 0 | AN13: 0 | AO13: 0 | AP13: 0 | AQ13: 0 | AR13: 0 | AS13: 0 | AT13: 0 | AU13: 0 | AV13: 0 | AW13: 0 | AX13: 0
AE14: 0 | AF14: 0 | AG14: 0 | AH14: 0 | AI14: 0 | AJ14: 0 | AK14: 0 | AL14: 0 | AM14: 0 | AN14: 0 | AO14: 0 | AP14: 0 | AQ14: 0 | AR14: 0 | AS14: 0 | AT14: 0 | AU14: 0 | AV14: 0 | AW14: 0 | AX14: 0
A15: ※ 3점이 안정입니다. 축이 넷입니다 — 애착(1 과잉↔5 없음) · 우호(1 경계↔5 과한 우호) · 사회화(1 회피↔5 살피지 않음) · 각성(1 위축↔5 흥분). 「한쪽」 항목은 1·2가 비어 있습니다. | AE15: 0 | AF15: 0 | AG15: 0 | AH15: 0 | AI15: 0 | AJ15: 0 | AK15: 0 | AL15: 0 | AM15: 0 | AN15: 0 | AO15: 0 | AP15: 0 | AQ15: 0 | AR15: 0 | AS15: 0 | AT15: 0 | AU15: 0 | AV15: 0 | AW15: 0 | AX15: 0
AE16: 0 | AF16: 0 | AG16: 0 | AH16: 0 | AI16: 0 | AJ16: 0 | AK16: 0 | AL16: 0 | AM16: 0 | AN16: 0 | AO16: 0 | AP16: 0 | AQ16: 0 | AR16: 0 | AS16: 0 | AT16: 0 | AU16: 0 | AV16: 0 | AW16: 0 | AX16: 0

Sheet 여러쌍비교
A1: 20마리 결과 한눈에 보기
A2: 기운 = 3점(안정)에서 어느 쪽으로 치우쳤나. 폭 = 3에서 가장 멀리 간 거리 (0~2). 정도 = 「한쪽」 항목의 평균. 친밀·애착과 사회성—사람은 기운 대신 유형이 나옵니다. 적응·회복·낯선 진정 = 3(안정)에서 떨어진 거리가 얼마나 줄었나. 양수면 안정 쪽으로 왔고, 음수면 위축이든 흥분이든 더 멀어진 것입니다. 총점은 만들지 않습니다.
A4: 번호 | B4: 반려견 이름 | C4: 견종 · 나이 | D4: 교육태도 | G4: 사회성 — 환경 | J4: 사회성 — 사람 | M4: 친밀·애착 | P4: 행동 동조 | S4: 퇴장 — 환경 적응 | V4: 적응 | W4: 회복 | X4: 낯선 진정 | Y4: 기준선 | Z4: 걷기 동조율 | AA4: 메모 · 주요 이슈
D5: 기운 | E5: 폭 | F5: 정도 | G5: 기운 | H5: 폭 | I5: 정도 | J5: 유형 | K5: 폭 | L5: 정도 | M5: 유형 | N5: 폭 | O5: 정도 | P5: 기운 | Q5: 폭 | R5: 정도 | S5: 기운 | T5: 폭 | U5: 정도 | V5: |기준−3|−|무시−3| | W5: |혼자−3|−|재회−3| | X5: |혼자−3|−|낯선−3| | Y5: 기준 각성
