Workbook

Sheet 0_안내
A1: 행동 채점표 — 2026-08-20 수정본 (55항목). AI 관측 가능 + 중복·저변별 항목 정리
A3: ■ 한 파일로 20마리까지
A4: 세 입력 시트 모두 J열부터 오른쪽으로 1번~20번 칸이 있습니다. 강아지마다 한 열을 쓰세요.
A5: 이름과 견종은 [여러쌍비교] 시트의 B·C열에 적으면 됩니다. 번호가 서로 연결되어 있습니다.
A7: ■ 고른 번호가 곧 점수입니다
A8: 1 = 양호(문제 없음) 3 = 중간 5 = 확실한 강한 문제
A9: 2점과 4점 칸은 마땅한 상태가 없으면 비워 두었습니다(회색). 현장에서 발견하면 직접 써 넣으세요.
A10: 빈 칸에 글을 넣는 즉시 20마리 전원에게 선택지로 적용되고 집계에도 반영됩니다.
A12: ■ 방향 태그
A13: 선택지 끝의 [A] = 과함(과흥분·과잉통제·불안), [B] = 위축(공포·방임·회피).
A14: 직접 칸을 채울 때도 라벨 끝에 [A] 또는 [B]를 붙이면 방향이 자동 판정됩니다. 없으면 방향 없음(-).
A16: ■ 시트 구성
... A39: · 입장 구간의 자극별 반응과 바디시그널이 같은 것을 두 번 재는 것은 아닌지 파일럿에서 확인 필요.

Sheet 1_바디시그널
A1: 바디시그널
A2: 개가 무의식적으로 내보내는 신체 신호. 해석하지 말고 보이는 상태 그대로 하나만 고른다. 구간마다 8부위를 한 번씩.
A3: J열부터 오른쪽으로 1번~20번 강아지 칸입니다. 각 칸에 1~5 중 하나를 입력하면 그 숫자가 곧 점수입니다. 1=양호, 5=확실한 강한 문제. 회색 빈 칸은 아직 정하지 않은 단계이니 직접 채워 넣으면 바로 반영됩니다.
A4: 구간 | B4: 관찰 항목 | C4: 1점 (양호) | D4: 2점 | E4: 3점 (중간) | F4: 4점 | G4: 5점 (강한 문제) | H4: 영역 | I4: 핵심 | J4: 1번 | K4: 2번 | L4: 3번 | M4: 4번 | N4: 5번 | O4: 6번 | P4: 7번 | Q4: 8번 | R4: 9번 | S4: 10번 | T4: 11번 | U4: 12번 | V4: 13번 | W4: 14번 | X4: 15번 | Y4: 16번 | Z4: 17번 | AA4: 18번 | AB4: 19번 | AC4: 20번 | AD4: 영역코드 | AE4: 점수1 | AF4: 점수2 | AG4: 점수3 | AH4: 점수4 | AI4: 점수5 | AJ4: 점수6 | AK4: 점수7 | AL4: 점수8 | AM4: 점수9 | AN4: 점수10 | AO4: 점수11 | AP4: 점수12 | AQ4: 점수13 | AR4: 점수14 | AS4: 점수15 | AT4: 점수16 | AU4: 점수17 | AV4: 점수18 | AW4: 점수19 | AX4: 점수20 | AY4: 방향1 | AZ4: 방향2 | BA4: 방향3 | BB4: 방향4 | BC4: 방향5 | BD4: 방향6 | BE4: 방향7 | BF4: 방향8 | BG4: 방향9 | BH4: 방향10 | BI4: 방향11 | BJ4: 방향12 | BK4: 방향13 | BL4: 방향14 | BM4: 방향15 | BN4: 방향16 | BO4: 방향17 | BP4: 방향18 | BQ4: 방향19 | BR4: 방향20
A5: 입장 | B5: 꼬리 | C5: 중립 높이·이완되어 있음 | D5: 평소보다 낮게 내림 [B] | E5: 높이 들고 경직·짧고 빠른 흔들림 [A] | G5: 다리 사이로 말아 넣음 [B] | H5: 사회성-환경 | I5: ★ | AD5: SOC_E | AE5: =IF($J5="","",IF(INDEX($C5:$G5,$J5)="","",$J5)) | AF5: =IF($K5="","",IF(INDEX($C5:$G5,$K5)="","",$K5)) | AG5: =IF($L5="","",IF(INDEX($C5:$G5,$L5)="","",$L5)) | AH5: =IF($M5="","",IF(INDEX($C5:$G5,$M5)="","",$M5)) | AI5: =IF($N5="","",IF(INDEX($C5:$G5,$N5)="","",$N5)) | AJ5: =IF($O5="","",IF(INDEX($C5:$G5,$O5)="","",$O5)) | AK5: =IF($P5="","",IF(INDEX($C5:$G5,$P5)="","",$P5)) | AL5: =IF($Q5="","",IF(INDEX($C5:$G5,$Q5)="","",$Q5)) | AM5: =IF($R5="","",IF(INDEX($C5:$G5,$R5)="","",$R5)) | AN5: =IF($S5="","",IF(INDEX($C5:$G5,$S5)="","",$S5)) | AO5: =IF($T5="","",IF(INDEX($C5:$G5,$T5)="","",$T5)) | AP5: =IF($U5="","",IF(INDEX($C5:$G5,$U5)="","",$U5)) | AQ5: =IF($V5="","",IF(INDEX($C5:$G5,$V5)="","",$V5)) | AR5: =IF($W5="","",IF(INDEX($C5:$G5,$W5)="","",$W5)) | AS5: =IF($X5="","",IF(INDEX($C5:$G5,$X5)="","",$X5)) | AT5: =IF($Y5="","",IF(INDEX($C5:$G5,$Y5)="","",$Y5)) | AU5: =IF($Z5="","",IF(INDEX($C5:$G5,$Z5)="","",$Z5)) | AV5: =IF($AA5="","",IF(INDEX($C5:$G5,$AA5)="","",$AA5)) | AW5: =IF($AB5="","",IF(INDEX($C5:$G5,$AB5)="","",$AB5)) | AX5: =IF($AC5="","",IF(INDEX($C5:$G5,$AC5)="","",$AC5)) | AY5: =IF($J5="","",IF(INDEX($C5:$G5,$J5)="","",IF(ISNUMBER(SEARCH("[A]",INDEX($C5:$G5,$J5))),"A",IF(ISNUMBER(SEARCH("[B]",INDEX($C5:$G5,$J5))),"B","-")))) | AZ5: =IF($K5="","",IF(INDEX($C5:$G5,$K5)="","",IF(ISNUMBER(SEARCH("[A]",INDEX($C5:$G5,$K5))),"A",IF(ISNUMBER(SEARCH("[B]",INDEX($C5:$G5,$K5))),"B","-")))) | BA5: =IF($L5="","",IF(INDEX($C5:$G5,$L5)="","",IF(ISNUMBER(SEARCH("[A]",INDEX($C5:$G5,$L5))),"A",IF(ISNUMBER(SEARCH("[B]",INDEX($C5:$G5,$L5))),"B","-")))) | BB5: =IF($M5="","",IF(INDEX($C5:$G5,$M5)="","",IF(ISNUMBER(SEARCH("[A]",INDEX($C5:$G5,$M5))),"A",IF(ISNUMBER(SEARCH("[B]",INDEX($C5:$G5,$M5))),"B","-")))) | BC5: =IF($N5="","",IF(INDEX($C5:$G5,$N5)="","",IF(ISNUMBER(SEARCH("[A]",INDEX($C5:$G5,$N5))),"A",IF(ISNUMBER(SEARCH("[B]",INDEX($C5:$G5,$N5))),"B","-")))) | BD5: =IF($O5="","",IF(INDEX($C5:$G5,$O5)="","",IF(ISNUMBER(SEARCH("[A]",INDEX($C5:$G5,$O5))),"A",IF(ISNUMBER(SEARCH("[B]",INDEX($C5:$G5,$O5))),"B","-")))) | BE5: =IF($P5="","",IF(INDEX($C5:$G5,$P5)="","",IF(ISNUMBER(SEARCH("[A]",INDEX($C5:$G5,$P5))),"A",IF(ISNUMBER(SEARCH("[B]",INDEX($C5:$G5,$P5))),"B","-")))) | BF5: =IF($Q5="","",IF(INDEX($C5:$G5,$Q5)="","",IF(ISNUMBER(SEARCH("[A]",INDEX($C5:$G5,$Q5))),"A",IF(ISNUMBER(SEARCH("[B]",INDEX($C5:$G5,$Q5))),"B","-")))) | BG5: =IF($R5="","",IF(INDEX($C5:$G5,$R5)="","",IF(ISNUMBER(SEARCH("[A]",INDEX($C5:$G5,$R5))),"A",IF(ISNUMBER(SEARCH("[B]",INDEX($C5:$G5,$R5))),"B","-")))) | BH5: =IF($S5="","",IF(INDEX($C5:$G5,$S5)="","",IF(ISNUMBER(SEARCH("[A]",INDEX($C5:$G5,$S5))),"A",IF(ISNUMBER(SEARCH("[B]",INDEX($C5:$G5,$S5))),"B","-")))) | BI5: =IF($T5="","",IF(INDEX($C5:$G5,$T5)="","",IF(ISNUMBER(SEARCH("[A]",INDEX($C5:$G5,$T5))),"A",IF(ISNUMBER(SEARCH("[B]",INDEX($C5:$G5,$T5))),"B","-")))) | BJ5: =IF($U5="","",IF(INDEX($C5:$G5,$U5)="","",IF(ISNUMBER(SEARCH("[A]",INDEX($C5:$G5,$U5))),"A",IF(ISNUMBER(SEARCH("[B]",INDEX($C5:$G5,$U5))),"B","-")))) | BK5: =IF($V5="","",IF(INDEX($C5:$G5,$V5)="","",IF(ISNUMBER(SEARCH("[A]",INDEX($C5:$G5,$V5))),"A",IF(ISNUMBER(SEARCH("[B]",INDEX($C5:$G5,$V5))),"B","-")))) | BL5: =IF($W5="","",IF(INDEX($C5:$G5,$W5)="","",IF(ISNUMBER(SEARCH("[A]",INDEX($C5:$G5,$W5))),"A",IF(ISNUMBER(SEARCH("[B]",INDEX($C5:$G5,$W5))),"B","-")))) | BM5: =IF($X5="","",IF(INDEX($C5:$G5,$X5)="","",IF(ISNUMBER(SEARCH("[A]",INDEX($C5:$G5,$X5))),"A",IF(ISNUMBER(SEARCH("[B]",INDEX($C5:$G5,$X5))),"B","-")))) | BN5: =IF($Y5="","",IF(INDEX($C5:$G5,$Y5)="","",IF(ISNUMBER(SEARCH("[A]",INDEX($C5:$G5,$Y5))),"A",IF(ISNUMBER(SEARCH("[B]",INDEX($C5:$G5,$Y5))),"B","-")))) | BO5: =IF($Z5="","",IF(INDEX($C5:$G5,$Z5)="","",IF(ISNUMBER(SEARCH("[A]",INDEX($C5:$G5,$Z5))),"A",IF(ISNUMBER(SEARCH("[B]",INDEX($C5:$G5,$Z5))),"B","-")))) | BP5: =IF($AA5="","",IF(INDEX($C5:$G5,$AA5)="","",IF(ISNUMBER(SEARCH("[A]",INDEX($C5:$G5,$AA5))),"A",IF(ISNUMBER(SEARCH("[B]",INDEX($C5:$G5,$AA5))),"B","-")))) | BQ5: =IF($AB5="","",IF(INDEX($C5:$G5,$AB5)="","",IF(ISNUMBER(SEARCH("[A]",INDEX($C5:$G5,$AB5))),"A",IF(ISNUMBER(SEARCH("[B]",INDEX($C5:$G5,$AB5))),"B","-")))) | BR5: =IF($AC5="","",IF(INDEX($C5:$G5,$AC5)="","",IF(ISNUMBER(SEARCH("[A]",INDEX($C5:$G5,$AC5))),"A",IF(ISNUMBER(SEARCH("[B]",INDEX($C5:$G5,$AC5))),"B","-"))))
A6: 입장 | B6: 자세·무게중심 | C6: 사지에 균등·중립 | E6: 무게중심 뒤·뒷걸음 자세 [B] | F6: 무게중심 앞·몸을 앞으로 기울임 [A] | G6: 몸 낮춤·웅크림·배 노출 [B] | H6: 사회성-환경 | I6: ★ | AD6: SOC_E | AE6: =IF($J6="","",IF(INDEX($C6:$G6,$J6)="","",$J6)) | AF6: =IF($K6="","",IF(INDEX($C6:$G6,$K6)="","",$K6)) | AG6: =IF($L6="","",IF(INDEX($C6:$G6,$L6)="","",$L6)) | AH6: =IF($M6="","",IF(INDEX($C6:$G6,$M6)="","",$M6)) | AI6: =IF($N6="","",IF(INDEX($C6:$G6,$N6)="","",$N6)) | AJ6: =IF($O6="","",IF(INDEX($C6:$G6,$O6)="","",$O6)) | AK6: =IF($P6="","",IF(INDEX($C6:$G6,$P6)="","",$P6)) | AL6: =IF($Q6="","",IF(INDEX($C6:$G6,$Q6)="","",$Q6)) | AM6: =IF($R6="","",IF(INDEX($C6:$G6,$R6)="","",$R6)) | AN6: =IF($S6="","",IF(INDEX($C6:$G6,$S6)="","",$S6)) | AO6: =IF($T6="","",IF(INDEX($C6:$G6,$T6)="","",$T6)) | AP6: =IF($U6="","",IF(INDEX($C6:$G6,$U6)="","",$U6)) | AQ6: =IF($V6="","",IF(INDEX($C6:$G6,$V6)="","",$V6)) | AR6: =IF($W6="","",IF(INDEX($C6:$G6,$W6)="","",$W6)) | AS6: =IF($X6="","",IF(INDEX($C6:$G6,$X6)="","",$X6)) | AT6: =IF($Y6="","",IF(INDEX($C6:$G6,$Y6)="","",$Y6)) | AU6: =IF($Z6="","",IF(INDEX($C6:$G6,$Z6)="","",$Z6)) | AV6: =IF($AA6="","",IF(INDEX($C6:$G6,$AA6)="","",$AA6)) | AW6: =IF($AB6="","",IF(INDEX($C6:$G6,$AB6)="","",$AB6)) | AX6: =IF($AC6="","",IF(INDEX($C6:$G6,$AC6)="","",$AC6)) | AY6: =IF($J6="","",IF(INDEX($C6:$G6,$J6)="","",IF(ISNUMBER(SEARCH("[A]",INDEX($C6:$G6,$J6))),"A",IF(ISNUMBER(SEARCH("[B]",INDEX($C6:$G6,$J6))),"B","-")))) | AZ6: =IF($K6="","",IF(INDEX($C6:$G6,$K6)="","",IF(ISNUMBER(SEARCH("[A]",INDEX($C6:$G6,$K6))),"A",IF(ISNUMBER(SEARCH("[B]",INDEX($C6:$G6,$K6))),"B","-")))) | BA6: =IF($L6="","",IF(INDEX($C6:$G6,$L6)="","",IF(ISNUMBER(SEARCH("[A]",INDEX($C6:$G6,$L6))),"A",IF(ISNUMBER(SEARCH("[B]",INDEX($C6:$G6,$L6))),"B","-")))) | BB6: =IF($M6="","",IF(INDEX($C6:$G6,$M6)="","",IF(ISNUMBER(SEARCH("[A]",INDEX($C6:$G6,$M6))),"A",IF(ISNUMBER(SEARCH("[B]",INDEX($C6:$G6,$M6))),"B","-")))) | BC6: =IF($N6="","",IF(INDEX($C6:$G6,$N6)="","",IF(ISNUMBER(SEARCH("[A]",INDEX($C6:$G6,$N6))),"A",IF(ISNUMBER(SEARCH("[B]",INDEX($C6:$G6,$N6))),"B","-")))) | BD6: =IF($O6="","",IF(INDEX($C6:$G6,$O6)="","",IF(ISNUMBER(SEARCH("[A]",INDEX($C6:$G6,$O6))),"A",IF(ISNUMBER(SEARCH("[B]",INDEX($C6:$G6,$O6))),"B","-")))) | BE6: =IF($P6="","",IF(INDEX($C6:$G6,$P6)="","",IF(ISNUMBER(SEARCH("[A]",INDEX($C6:$G6,$P6))),"A",IF(ISNUMBER(SEARCH("[B]",INDEX($C6:$G6,$P6))),"B","-")))) | BF6: =IF($Q6="","",IF(INDEX($C6:$G6,$Q6)="","",IF(ISNUMBER(SEARCH("[A]",INDEX($C6:$G6,$Q6))),"A",IF(ISNUMBER(SEARCH("[B]",INDEX($C6:$G6,$Q6))),"B","-")))) | BG6: =IF($R6="","",IF(INDEX($C6:$G6,$R6)="","",IF(ISNUMBER(SEARCH("[A]",INDEX($C6:$G6,$R6))),"A",IF(ISNUMBER(SEARCH("[B]",INDEX($C6:$G6,$R6))),"B","-")))) | BH6: =IF($S6="","",IF(INDEX($C6:$G6,$S6)="","",IF(ISNUMBER(SEARCH("[A]",INDEX($C6:$G6,$S6))),"A",IF(ISNUMBER(SEARCH("[B]",INDEX($C6:$G6,$S6))),"B","-")))) | BI6: =IF($T6="","",IF(INDEX($C6:$G6,$T6)="","",IF(ISNUMBER(SEARCH("[A]",INDEX($C6:$G6,$T6))),"A",IF(ISNUMBER(SEARCH("[B]",INDEX($C6:$G6,$T6))),"B","-")))) | BJ6: =IF($U6="","",IF(INDEX($C6:$G6,$U6)="","",IF(ISNUMBER(SEARCH("[A]",INDEX($C6:$G6,$U6))),"A",IF(ISNUMBER(SEARCH("[B]",INDEX($C6:$G6,$U6))),"B","-")))) | BK6: =IF($V6="","",IF(INDEX($C6:$G6,$V6)="","",IF(ISNUMBER(SEARCH("[A]",INDEX($C6:$G6,$V6))),"A",IF(ISNUMBER(SEARCH("[B]",INDEX($C6:$G6,$V6))),"B","-")))) | BL6: =IF($W6="","",IF(INDEX($C6:$G6,$W6)="","",IF(ISNUMBER(SEARCH("[A]",INDEX($C6:$G6,$W6))),"A",IF(ISNUMBER(SEARCH("[B]",INDEX($C6:$G6,$W6))),"B","-")))) | BM6: =IF($X6="","",IF(INDEX($C6:$G6,$X6)="","",IF(ISNUMBER(SEARCH("[A]",INDEX($C6:$G6,$X6))),"A",IF(ISNUMBER(SEARCH("[B]",INDEX($C6:$G6,$X6))),"B","-")))) | BN6: =IF($Y6="","",IF(INDEX($C6:$G6,$Y6)="","",IF(ISNUMBER(SEARCH("[A]",INDEX($C6:$G6,$Y6))),"A",IF(ISNUMBER(SEARCH("[B]",INDEX($C6:$G6,$Y6))),"B","-")))) | BO6: =IF($Z6="","",IF(INDEX($C6:$G6,$Z6)="","",IF(ISNUMBER(SEARCH("[A]",INDEX($C6:$G6,$Z6))),"A",IF(ISNUMBER(SEARCH("[B]",INDEX($C6:$G6,$Z6))),"B","-")))) | BP6: =IF($AA6="","",IF(INDEX($C6:$G6,$AA6)="","",IF(ISNUMBER(SEARCH("[A]",INDEX($C6:$G6,$AA6))),"A",IF(ISNUMBER(SEARCH("[B]",INDEX($C6:$G6,$AA6))),"B","-")))) | BQ6: =IF($AB6="","",IF(INDEX($C6:$G6,$AB6)="","",IF(ISNUMBER(SEARCH("[A]",INDEX($C6:$G6,$AB6))),"A",IF(ISNUMBER(SEARCH("[B]",INDEX($C6:$G6,$AB6))),"B","-")))) | BR6: =IF($AC6="","",IF(INDEX($C6:$G6,$AC6)="","",IF(ISNUMBER(SEARCH("[A]",INDEX($C6:$G6,$AC6))),"A",IF(ISNUMBER(SEARCH("[B]",INDEX($C6:$G6,$AC6))),"B","-"))))
A7: 입장 | B7: 이동 | C7: 자발적 접근 또는 중립 유지 | E7: 회피·후퇴 [B] | F7: 자극 향해 돌진·리드줄 당김 [A] | G7: 프리징(2초 이상 정지)·보호자 뒤로 숨음 [B] | H7: 사회성-환경 | I7: ★ | AD7: SOC_E | AE7: =IF($J7="","",IF(INDEX($C7:$G7,$J7)="","",$J7)) | AF7: =IF($K7="","",IF(INDEX($C7:$G7,$K7)="","",$K7)) | AG7: =IF($L7="","",IF(INDEX($C7:$G7,$L7)="","",$L7)) | AH7: =IF($M7="","",IF(INDEX($C7:$G7,$M7)="","",$M7)) | AI7: =IF($N7="","",IF(INDEX($C7:$G7,$N7)="","",$N7)) | AJ7: =IF($O7="","",IF(INDEX($C7:$G7,$O7)="","",$O7)) | AK7: =IF($P7="","",IF(INDEX($C7:$G7,$P7)="","",$P7)) | AL7: =IF($Q7="","",IF(INDEX($C7:$G7,$Q7)="","",$Q7)) | AM7: =IF($R7="","",IF(INDEX($C7:$G7,$R7)="","",$R7)) | AN7: =IF($S7="","",IF(INDEX($C7:$G7,$S7)="","",$S7)) | AO7: =IF($T7="","",IF(INDEX($C7:$G7,$T7)="","",$T7)) | AP7: =IF($U7="","",IF(INDEX($C7:$G7,$U7)="","",$U7)) | AQ7: =IF($V7="","",IF(INDEX($C7:$G7,$V7)="","",$V7)) | AR7: =IF($W7="","",IF(INDEX($C7:$G7,$W7)="","",$W7)) | AS7: =IF($X7="","",IF(INDEX($C7:$G7,$X7)="","",$X7)) | AT7: =IF($Y7="","",IF(INDEX($C7:$G7,$Y7)="","",$Y7)) | AU7: =IF($Z7="","",IF(INDEX($C7:$G7,$Z7)="","",$Z7)) | AV7: =IF($AA7="","",IF(INDEX($C7:$G7,$AA7)="","",$AA7)) | AW7: =IF($AB7="","",IF(INDEX($C7:$G7,$AB7)="","",$AB7)) | AX7: =IF($AC7="","",IF(INDEX($C7:$G7,$AC7)="","",$AC7)) | AY7: =IF($J7="","",IF(INDEX($C7:$G7,$J7)="","",IF(ISNUMBER(SEARCH("[A]",INDEX($C7:$G7,$J7))),"A",IF(ISNUMBER(SEARCH("[B]",INDEX($C7:$G7,$J7))),"B","-")))) | AZ7: =IF($K7="","",IF(INDEX($C7:$G7,$K7)="","",IF(ISNUMBER(SEARCH("[A]",INDEX($C7:$G7,$K7))),"A",IF(ISNUMBER(SEARCH("[B]",INDEX($C7:$G7,$K7))),"B","-")))) | BA7: =IF($L7="","",IF(INDEX($C7:$G7,$L7)="","",IF(ISNUMBER(SEARCH("[A]",INDEX($C7:$G7,$L7))),"A",IF(ISNUMBER(SEARCH("[B]",INDEX($C7:$G7,$L7))),"B","-")))) | BB7: =IF($M7="","",IF(INDEX($C7:$G7,$M7)="","",IF(ISNUMBER(SEARCH("[A]",INDEX($C7:$G7,$M7))),"A",IF(ISNUMBER(SEARCH("[B]",INDEX($C7:$G7,$M7))),"B","-")))) | BC7: =IF($N7="","",IF(INDEX($C7:$G7,$N7)="","",IF(ISNUMBER(SEARCH("[A]",INDEX($C7:$G7,$N7))),"A",IF(ISNUMBER(SEARCH("[B]",INDEX($C7:$G7,$N7))),"B","-")))) | BD7: =IF($O7="","",IF(INDEX($C7:$G7,$O7)="","",IF(ISNUMBER(SEARCH("[A]",INDEX($C7:$G7,$O7))),"A",IF(ISNUMBER(SEARCH("[B]",INDEX($C7:$G7,$O7))),"B","-")))) | BE7: =IF($P7="","",IF(INDEX($C7:$G7,$P7)="","",IF(ISNUMBER(SEARCH("[A]",INDEX($C7:$G7,$P7))),"A",IF(ISNUMBER(SEARCH("[B]",INDEX($C7:$G7,$P7))),"B","-")))) | BF7: =IF($Q7="","",IF(INDEX($C7:$G7,$Q7)="","",IF(ISNUMBER(SEARCH("[A]",INDEX($C7:$G7,$Q7))),"A",IF(ISNUMBER(SEARCH("[B]",INDEX($C7:$G7,$Q7))),"B","-")))) | BG7: =IF($R7="","",IF(INDEX($C7:$G7,$R7)="","",IF(ISNUMBER(SEARCH("[A]",INDEX($C7:$G7,$R7))),"A",IF(ISNUMBER(SEARCH("[B]",INDEX($C7:$G7,$R7))),"B","-")))) | BH7: =IF($S7="","",IF(INDEX($C7:$G7,$S7)="","",IF(ISNUMBER(SEARCH("[A]",INDEX($C7:$G7,$S7))),"A",IF(ISNUMBER(SEARCH("[B]",INDEX($C7:$G7,$S7))),"B","-")))) | BI7: =IF($T7="","",IF(INDEX($C7:$G7,$T7)="","",IF(ISNUMBER(SEARCH("[A]",INDEX($C7:$G7,$T7))),"A",IF(ISNUMBER(SEARCH("[B]",INDEX($C7:$G7,$T7))),"B","-")))) | BJ7: =IF($U7="","",IF(INDEX($C7:$G7,$U7)="","",IF(ISNUMBER(SEARCH("[A]",INDEX($C7:$G7,$U7))),"A",IF(ISNUMBER(SEARCH("[B]",INDEX($C7:$G7,$U7))),"B","-")))) | BK7: =IF($V7="","",IF(INDEX($C7:$G7,$V7)="","",IF(ISNUMBER(SEARCH("[A]",INDEX($C7:$G7,$V7))),"A",IF(ISNUMBER(SEARCH("[B]",INDEX($C7:$G7,$V7))),"B","-")))) | BL7: =IF($W7="","",IF(INDEX($C7:$G7,$W7)="","",IF(ISNUMBER(SEARCH("[A]",INDEX($C7:$G7,$W7))),"A",IF(ISNUMBER(SEARCH("[B]",INDEX($C7:$G7,$W7))),"B","-")))) | BM7: =IF($X7="","",IF(INDEX($C7:$G7,$X7)="","",IF(ISNUMBER(SEARCH("[A]",INDEX($C7:$G7,$X7))),"A",IF(ISNUMBER(SEARCH("[B]",INDEX($C7:$G7,$X7))),"B","-")))) | BN7: =IF($Y7="","",IF(INDEX($C7:$G7,$Y7)="","",IF(ISNUMBER(SEARCH("[A]",INDEX($C7:$G7,$Y7))),"A",IF(ISNUMBER(SEARCH("[B]",INDEX($C7:$G7,$Y7))),"B","-")))) | BO7: =IF($Z7="","",IF(INDEX($C7:$G7,$Z7)="","",IF(ISNUMBER(SEARCH("[A]",INDEX($C7:$G7,$Z7))),"A",IF(ISNUMBER(SEARCH("[B]",INDEX($C7:$G7,$Z7))),"B","-")))) | BP7: =IF($AA7="","",IF(INDEX($C7:$G7,$AA7)="","",IF(ISNUMBER(SEARCH("[A]",INDEX($C7:$G7,$AA7))),"A",IF(ISNUMBER(SEARCH("[B]",INDEX($C7:$G7,$AA7))),"B","-")))) | BQ7: =IF($AB7="","",IF(INDEX($C7:$G7,$AB7)="","",IF(ISNUMBER(SEARCH("[A]",INDEX($C7:$G7,$AB7))),"A",IF(ISNUMBER(SEARCH("[B]",INDEX($C7:$G7,$AB7))),"B","-")))) | BR7: =IF($AC7="","",IF(INDEX($C7:$G7,$AC7)="","",IF(ISNUMBER(SEARCH("[A]",INDEX($C7:$G7,$AC7))),"A",IF(ISNUMBER(SEARCH("[B]",INDEX($C7:$G7,$AC7))),"B","-"))))
A8: 입장 | B8: 발성 ※전 구간 통틀어 | C8: 없음 | E8: 낑낑·하울링 [B] | F8: 짖음 [A] | G8: 으르렁 [A] | H8: 사회성-환경 | AD8: SOC_E | AE8: =IF($J8="","",IF(INDEX($C8:$G8,$J8)="","",$J8)) | AF8: =IF($K8="","",IF(INDEX($C8:$G8,$K8)="","",$K8)) | AG8: =IF($L8="","",IF(INDEX($C8:$G8,$L8)="","",$L8)) | AH8: =IF($M8="","",IF(INDEX($C8:$G8,$M8)="","",$M8)) | AI8: =IF($N8="","",IF(INDEX($C8:$G8,$N8)="","",$N8)) | AJ8: =IF($O8="","",IF(INDEX($C8:$G8,$O8)="","",$O8)) | AK8: =IF($P8="","",IF(INDEX($C8:$G8,$P8)="","",$P8)) | AL8: =IF($Q8="","",IF(INDEX($C8:$G8,$Q8)="","",$Q8)) | AM8: =IF($R8="","",IF(INDEX($C8:$G8,$R8)="","",$R8)) | AN8: =IF($S8="","",IF(INDEX($C8:$G8,$S8)="","",$S8)) | AO8: =IF($T8="","",IF(INDEX($C8:$G8,$T8)="","",$T8)) | AP8: =IF($U8="","",IF(INDEX($C8:$G8,$U8)="","",$U8)) | AQ8: =IF($V8="","",IF(INDEX($C8:$G8,$V8)="","",$V8)) | AR8: =IF($W8="","",IF(INDEX($C8:$G8,$W8)="","",$W8)) | AS8: =IF($X8="","",IF(INDEX($C8:$G8,$X8)="","",$X8)) | AT8: =IF($Y8="","",IF(INDEX($C8:$G8,$Y8)="","",$Y8)) | AU8: =IF($Z8="","",IF(INDEX($C8:$G8,$Z8)="","",$Z8)) | AV8: =IF($AA8="","",IF(INDEX($C8:$G8,$AA8)="","",$AA8)) | AW8: =IF($AB8="","",IF(INDEX($C8:$G8,$AB8)="","",$AB8)) | AX8: =IF($AC8="","",IF(INDEX($C8:$G8,$AC8)="","",$AC8)) | AY8: =IF($J8="","",IF(INDEX($C8:$G8,$J8)="","",IF(ISNUMBER(SEARCH("[A]",INDEX($C8:$G8,$J8))),"A",IF(ISNUMBER(SEARCH("[B]",INDEX($C8:$G8,$J8))),"B","-")))) | AZ8: =IF($K8="","",IF(INDEX($C8:$G8,$K8)="","",IF(ISNUMBER(SEARCH("[A]",INDEX($C8:$G8,$K8))),"A",IF(ISNUMBER(SEARCH("[B]",INDEX($C8:$G8,$K8))),"B","-")))) | BA8: =IF($L8="","",IF(INDEX($C8:$G8,$L8)="","",IF(ISNUMBER(SEARCH("[A]",INDEX($C8:$G8,$L8))),"A",IF(ISNUMBER(SEARCH("[B]",INDEX($C8:$G8,$L8))),"B","-")))) | BB8: =IF($M8="","",IF(INDEX($C8:$G8,$M8)="","",IF(ISNUMBER(SEARCH("[A]",INDEX($C8:$G8,$M8))),"A",IF(ISNUMBER(SEARCH("[B]",INDEX($C8:$G8,$M8))),"B","-")))) | BC8: =IF($N8="","",IF(INDEX($C8:$G8,$N8)="","",IF(ISNUMBER(SEARCH("[A]",INDEX($C8:$G8,$N8))),"A",IF(ISNUMBER(SEARCH("[B]",INDEX($C8:$G8,$N8))),"B","-")))) | BD8: =IF($O8="","",IF(INDEX($C8:$G8,$O8)="","",IF(ISNUMBER(SEARCH("[A]",INDEX($C8:$G8,$O8))),"A",IF(ISNUMBER(SEARCH("[B]",INDEX($C8:$G8,$O8))),"B","-")))) | BE8: =IF($P8="","",IF(INDEX($C8:$G8,$P8)="","",IF(ISNUMBER(SEARCH("[A]",INDEX($C8:$G8,$P8))),"A",IF(ISNUMBER(SEARCH("[B]",INDEX($C8:$G8,$P8))),"B","-")))) | BF8: =IF($Q8="","",IF(INDEX($C8:$G8,$Q8)="","",IF(ISNUMBER(SEARCH("[A]",INDEX($C8:$G8,$Q8))),"A",IF(ISNUMBER(SEARCH("[B]",INDEX($C8:$G8,$Q8))),"B","-")))) | BG8: =IF($R8="","",IF(INDEX($C8:$G8,$R8)="","",IF(ISNUMBER(SEARCH("[A]",INDEX($C8:$G8,$R8))),"A",IF(ISNUMBER(SEARCH("[B]",INDEX($C8:$G8,$R8))),"B","-")))) | BH8: =IF($S8="","",IF(INDEX($C8:$G8,$S8)="","",IF(ISNUMBER(SEARCH("[A]",INDEX($C8:$G8,$S8))),"A",IF(ISNUMBER(SEARCH("[B]",INDEX($C8:$G8,$S8))),"B","-")))) | BI8: =IF($T8="","",IF(INDEX($C8:$G8,$T8)="","",IF(ISNUMBER(SEARCH("[A]",INDEX($C8:$G8,$T8))),"A",IF(ISNUMBER(SEARCH("[B]",INDEX($C8:$G8,$T8))),"B","-")))) | BJ8: =IF($U8="","",IF(INDEX($C8:$G8,$U8)="","",IF(ISNUMBER(SEARCH("[A]",INDEX($C8:$G8,$U8))),"A",IF(ISNUMBER(SEARCH("[B]",INDEX($C8:$G8,$U8))),"B","-")))) | BK8: =IF($V8="","",IF(INDEX($C8:$G8,$V8)="","",IF(ISNUMBER(SEARCH("[A]",INDEX($C8:$G8,$V8))),"A",IF(ISNUMBER(SEARCH("[B]",INDEX($C8:$G8,$V8))),"B","-")))) | BL8: =IF($W8="","",IF(INDEX($C8:$G8,$W8)="","",IF(ISNUMBER(SEARCH("[A]",INDEX($C8:$G8,$W8))),"A",IF(ISNUMBER(SEARCH("[B]",INDEX($C8:$G8,$W8))),"B","-")))) | BM8: =IF($X8="","",IF(INDEX($C8:$G8,$X8)="","",IF(ISNUMBER(SEARCH("[A]",INDEX($C8:$G8,$X8))),"A",IF(ISNUMBER(SEARCH("[B]",INDEX($C8:$G8,$X8))),"B","-")))) | BN8: =IF($Y8="","",IF(INDEX($C8:$G8,$Y8)="","",IF(ISNUMBER(SEARCH("[A]",INDEX($C8:$G8,$Y8))),"A",IF(ISNUMBER(SEARCH("[B]",INDEX($C8:$G8,$Y8))),"B","-")))) | BO8: =IF($Z8="","",IF(INDEX($C8:$G8,$Z8)="","",IF(ISNUMBER(SEARCH("[A]",INDEX($C8:$G8,$Z8))),"A",IF(ISNUMBER(SEARCH("[B]",INDEX($C8:$G8,$Z8))),"B","-")))) | BP8: =IF($AA8="","",IF(INDEX($C8:$G8,$AA8)="","",IF(ISNUMBER(SEARCH("[A]",INDEX($C8:$G8,$AA8))),"A",IF(ISNUMBER(SEARCH("[B]",INDEX($C8:$G8,$AA8))),"B","-")))) | BQ8: =IF($AB8="","",IF(INDEX($C8:$G8,$AB8)="","",IF(ISNUMBER(SEARCH("[A]",INDEX($C8:$G8,$AB8))),"A",IF(ISNUMBER(SEARCH("[B]",INDEX($C8:$G8,$AB8))),"B","-")))) | BR8: =IF($AC8="","",IF(INDEX($C8:$G8,$AC8)="","",IF(ISNUMBER(SEARCH("[A]",INDEX($C8:$G8,$AC8))),"A",IF(ISNUMBER(SEARCH("[B]",INDEX($C8:$G8,$AC8))),"B","-"))))
A9: 입장 | B9: 전위행동 (3종) | C9: 없음 | D9: 1종이 1~2회 [B] | E9: 2종 이상 또는 1종 지속 반복 [B] | G9: 3종 이상 지속 반복 [B] | H9: 사회성-환경 | I9: ★ | AD9: SOC_E | AE9: =IF($J9="","",IF(INDEX($C9:$G9,$J9)="","",$J9)) | AF9: =IF($K9="","",IF(INDEX($C9:$G9,$K9)="","",$K9)) | AG9: =IF($L9="","",IF(INDEX($C9:$G9,$L9)="","",$L9)) | AH9: =IF($M9="","",IF(INDEX($C9:$G9,$M9)="","",$M9)) | AI9: =IF($N9="","",IF(INDEX($C9:$G9,$N9)="","",$N9)) | AJ9: =IF($O9="","",IF(INDEX($C9:$G9,$O9)="","",$O9)) | AK9: =IF($P9="","",IF(INDEX($C9:$G9,$P9)="","",$P9)) | AL9: =IF($Q9="","",IF(INDEX($C9:$G9,$Q9)="","",$Q9)) | AM9: =IF($R9="","",IF(INDEX($C9:$G9,$R9)="","",$R9)) | AN9: =IF($S9="","",IF(INDEX($C9:$G9,$S9)="","",$S9)) | AO9: =IF($T9="","",IF(INDEX($C9:$G9,$T9)="","",$T9)) | AP9: =IF($U9="","",IF(INDEX($C9:$G9,$U9)="","",$U9)) | AQ9: =IF($V9="","",IF(INDEX($C9:$G9,$V9)="","",$V9)) | AR9: =IF($W9="","",IF(INDEX($C9:$G9,$W9)="","",$W9)) | AS9: =IF($X9="","",IF(INDEX($C9:$G9,$X9)="","",$X9)) | AT9: =IF($Y9="","",IF(INDEX($C9:$G9,$Y9)="","",$Y9)) | AU9: =IF($Z9="","",IF(INDEX($C9:$G9,$Z9)="","",$Z9)) | AV9: =IF($AA9="","",IF(INDEX($C9:$G9,$AA9)="","",$AA9)) | AW9: =IF($AB9="","",IF(INDEX($C9:$G9,$AB9)="","",$AB9)) | AX9: =IF($AC9="","",IF(INDEX($C9:$G9,$AC9)="","",$AC9)) | AY9: =IF($J9="","",IF(INDEX($C9:$G9,$J9)="","",IF(ISNUMBER(SEARCH("[A]",INDEX($C9:$G9,$J9))),"A",IF(ISNUMBER(SEARCH("[B]",INDEX($C9:$G9,$J9))),"B","-")))) | AZ9: =IF($K9="","",IF(INDEX($C9:$G9,$K9)="","",IF(ISNUMBER(SEARCH("[A]",INDEX($C9:$G9,$K9))),"A",IF(ISNUMBER(SEARCH("[B]",INDEX($C9:$G9,$K9))),"B","-")))) | BA9: =IF($L9="","",IF(INDEX($C9:$G9,$L9)="","",IF(ISNUMBER(SEARCH("[A]",INDEX($C9:$G9,$L9))),"A",IF(ISNUMBER(SEARCH("[B]",INDEX($C9:$G9,$L9))),"B","-")))) | BB9: =IF($M9="","",IF(INDEX($C9:$G9,$M9)="","",IF(ISNUMBER(SEARCH("[A]",INDEX($C9:$G9,$M9))),"A",IF(ISNUMBER(SEARCH("[B]",INDEX($C9:$G9,$M9))),"B","-")))) | BC9: =IF($N9="","",IF(INDEX($C9:$G9,$N9)="","",IF(ISNUMBER(SEARCH("[A]",INDEX($C9:$G9,$N9))),"A",IF(ISNUMBER(SEARCH("[B]",INDEX($C9:$G9,$N9))),"B","-")))) | BD9: =IF($O9="","",IF(INDEX($C9:$G9,$O9)="","",IF(ISNUMBER(SEARCH("[A]",INDEX($C9:$G9,$O9))),"A",IF(ISNUMBER(SEARCH("[B]",INDEX($C9:$G9,$O9))),"B","-")))) | BE9: =IF($P9="","",IF(INDEX($C9:$G9,$P9)="","",IF(ISNUMBER(SEARCH("[A]",INDEX($C9:$G9,$P9))),"A",IF(ISNUMBER(SEARCH("[B]",INDEX($C9:$G9,$P9))),"B","-")))) | BF9: =IF($Q9="","",IF(INDEX($C9:$G9,$Q9)="","",IF(ISNUMBER(SEARCH("[A]",INDEX($C9:$G9,$Q9))),"A",IF(ISNUMBER(SEARCH("[B]",INDEX($C9:$G9,$Q9))),"B","-")))) | BG9: =IF($R9="","",IF(INDEX($C9:$G9,$R9)="","",IF(ISNUMBER(SEARCH("[A]",INDEX($C9:$G9,$R9))),"A",IF(ISNUMBER(SEARCH("[B]",INDEX($C9:$G9,$R9))),"B","-")))) | BH9: =IF($S9="","",IF(INDEX($C9:$G9,$S9)="","",IF(ISNUMBER(SEARCH("[A]",INDEX($C9:$G9,$S9))),"A",IF(ISNUMBER(SEARCH("[B]",INDEX($C9:$G9,$S9))),"B","-")))) | BI9: =IF($T9="","",IF(INDEX($C9:$G9,$T9)="","",IF(ISNUMBER(SEARCH("[A]",INDEX($C9:$G9,$T9))),"A",IF(ISNUMBER(SEARCH("[B]",INDEX($C9:$G9,$T9))),"B","-")))) | BJ9: =IF($U9="","",IF(INDEX($C9:$G9,$U9)="","",IF(ISNUMBER(SEARCH("[A]",INDEX($C9:$G9,$U9))),"A",IF(ISNUMBER(SEARCH("[B]",INDEX($C9:$G9,$U9))),"B","-")))) | BK9: =IF($V9="","",IF(INDEX($C9:$G9,$V9)="","",IF(ISNUMBER(SEARCH("[A]",INDEX($C9:$G9,$V9))),"A",IF(ISNUMBER(SEARCH("[B]",INDEX($C9:$G9,$V9))),"B","-")))) | BL9: =IF($W9="","",IF(INDEX($C9:$G9,$W9)="","",IF(ISNUMBER(SEARCH("[A]",INDEX($C9:$G9,$W9))),"A",IF(ISNUMBER(SEARCH("[B]",INDEX($C9:$G9,$W9))),"B","-")))) | BM9: =IF($X9="","",IF(INDEX($C9:$G9,$X9)="","",IF(ISNUMBER(SEARCH("[A]",INDEX($C9:$G9,$X9))),"A",IF(ISNUMBER(SEARCH("[B]",INDEX($C9:$G9,$X9))),"B","-")))) | BN9: =IF($Y9="","",IF(INDEX($C9:$G9,$Y9)="","",IF(ISNUMBER(SEARCH("[A]",INDEX($C9:$G9,$Y9))),"A",IF(ISNUMBER(SEARCH("[B]",INDEX($C9:$G9,$Y9))),"B","-")))) | BO9: =IF($Z9="","",IF(INDEX($C9:$G9,$Z9)="","",IF(ISNUMBER(SEARCH("[A]",INDEX($C9:$G9,$Z9))),"A",IF(ISNUMBER(SEARCH("[B]",INDEX($C9:$G9,$Z9))),"B","-")))) | BP9: =IF($AA9="","",IF(INDEX($C9:$G9,$AA9)="","",IF(ISNUMBER(SEARCH("[A]",INDEX($C9:$G9,$AA9))),"A",IF(ISNUMBER(SEARCH("[B]",INDEX($C9:$G9,$AA9))),"B","-")))) | BQ9: =IF($AB9="","",IF(INDEX($C9:$G9,$AB9)="","",IF(ISNUMBER(SEARCH("[A]",INDEX($C9:$G9,$AB9))),"A",IF(ISNUMBER(SEARCH("[B]",INDEX($C9:$G9,$AB9))),"B","-")))) | BR9: =IF($AC9="","",IF(INDEX($C9:$G9,$AC9)="","",IF(ISNUMBER(SEARCH("[A]",INDEX($C9:$G9,$AC9))),"A",IF(ISNUMBER(SEARCH("[B]",INDEX($C9:$G9,$AC9))),"B","-"))))
A10: 분리 | B10: 꼬리 | C10: 중립 높이·이완되어 있음 | D10: 평소보다 낮게 내림 [B] | E10: 높이 들고 경직·짧고 빠른 흔들림 [A] | G10: 다리 사이로 말아 넣음 [B] | H10: 친밀·애착 | I10: ★ | AD10: ATT | AE10: =IF($J10="","",IF(INDEX($C10:$G10,$J10)="","",$J10)) | AF10: =IF($K10="","",IF(INDEX($C10:$G10,$K10)="","",$K10)) | AG10: =IF($L10="","",IF(INDEX($C10:$G10,$L10)="","",$L10)) | AH10: =IF($M10="","",IF(INDEX($C10:$G10,$M10)="","",$M10)) | AI10: =IF($N10="","",IF(INDEX($C10:$G10,$N10)="","",$N10)) | AJ10: =IF($O10="","",IF(INDEX($C10:$G10,$O10)="","",$O10)) | AK10: =IF($P10="","",IF(INDEX($C10:$G10,$P10)="","",$P10)) | AL10: =IF($Q10="","",IF(INDEX($C10:$G10,$Q10)="","",$Q10)) | AM10: =IF($R10="","",IF(INDEX($C10:$G10,$R10)="","",$R10)) | AN10: =IF($S10="","",IF(INDEX($C10:$G10,$S10)="","",$S10)) | AO10: =IF($T10="","",IF(INDEX($C10:$G10,$T10)="","",$T10)) | AP10: =IF($U10="","",IF(INDEX($C10:$G10,$U10)="","",$U10)) | AQ10: =IF($V10="","",IF(INDEX($C10:$G10,$V10)="","",$V10)) | AR10: =IF($W10="","",IF(INDEX($C10:$G10,$W10)="","",$W10)) | AS10: =IF($X10="","",IF(INDEX($C10:$G10,$X10)="","",$X10)) | AT10: =IF($Y10="","",IF(INDEX($C10:$G10,$Y10)="","",$Y10)) | AU10: =IF($Z10="","",IF(INDEX($C10:$G10,$Z10)="","",$Z10)) | AV10: =IF($AA10="","",IF(INDEX($C10:$G10,$AA10)="","",$AA10)) | AW10: =IF($AB10="","",IF(INDEX($C10:$G10,$AB10)="","",$AB10)) | AX10: =IF($AC10="","",IF(INDEX($C10:$G10,$AC10)="","",$AC10)) | AY10: =IF($J10="","",IF(INDEX($C10:$G10,$J10)="","",IF(ISNUMBER(SEARCH("[A]",INDEX($C10:$G10,$J10))),"A",IF(ISNUMBER(SEARCH("[B]",INDEX($C10:$G10,$J10))),"B","-")))) | AZ10: =IF($K10="","",IF(INDEX($C10:$G10,$K10)="","",IF(ISNUMBER(SEARCH("[A]",INDEX($C10:$G10,$K10))),"A",IF(ISNUMBER(SEARCH("[B]",INDEX($C10:$G10,$K10))),"B","-")))) | BA10: =IF($L10="","",IF(INDEX($C10:$G10,$L10)="","",IF(ISNUMBER(SEARCH("[A]",INDEX($C10:$G10,$L10))),"A",IF(ISNUMBER(SEARCH("[B]",INDEX($C10:$G10,$L10))),"B","-")))) | BB10: =IF($M10="","",IF(INDEX($C10:$G10,$M10)="","",IF(ISNUMBER(SEARCH("[A]",INDEX($C10:$G10,$M10))),"A",IF(ISNUMBER(SEARCH("[B]",INDEX($C10:$G10,$M10))),"B","-")))) | BC10: =IF($N10="","",IF(INDEX($C10:$G10,$N10)="","",IF(ISNUMBER(SEARCH("[A]",INDEX($C10:$G10,$N10))),"A",IF(ISNUMBER(SEARCH("[B]",INDEX($C10:$G10,$N10))),"B","-")))) | BD10: =IF($O10="","",IF(INDEX($C10:$G10,$O10)="","",IF(ISNUMBER(SEARCH("[A]",INDEX($C10:$G10,$O10))),"A",IF(ISNUMBER(SEARCH("[B]",INDEX($C10:$G10,$O10))),"B","-")))) | BE10: =IF($P10="","",IF(INDEX($C10:$G10,$P10)="","",IF(ISNUMBER(SEARCH("[A]",INDEX($C10:$G10,$P10))),"A",IF(ISNUMBER(SEARCH("[B]",INDEX($C10:$G10,$P10))),"B","-")))) | BF10: =IF($Q10="","",IF(INDEX($C10:$G10,$Q10)="","",IF(ISNUMBER(SEARCH("[A]",INDEX($C10:$G10,$Q10))),"A",IF(ISNUMBER(SEARCH("[B]",INDEX($C10:$G10,$Q10))),"B","-")))) | BG10: =IF($R10="","",IF(INDEX($C10:$G10,$R10)="","",IF(ISNUMBER(SEARCH("[A]",INDEX($C10:$G10,$R10))),"A",IF(ISNUMBER(SEARCH("[B]",INDEX($C10:$G10,$R10))),"B","-")))) | BH10: =IF($S10="","",IF(INDEX($C10:$G10,$S10)="","",IF(ISNUMBER(SEARCH("[A]",INDEX($C10:$G10,$S10))),"A",IF(ISNUMBER(SEARCH("[B]",INDEX($C10:$G10,$S10))),"B","-")))) | BI10: =IF($T10="","",IF(INDEX($C10:$G10,$T10)="","",IF(ISNUMBER(SEARCH("[A]",INDEX($C10:$G10,$T10))),"A",IF(ISNUMBER(SEARCH("[B]",INDEX($C10:$G10,$T10))),"B","-")))) | BJ10: =IF($U10="","",IF(INDEX($C10:$G10,$U10)="","",IF(ISNUMBER(SEARCH("[A]",INDEX($C10:$G10,$U10))),"A",IF(ISNUMBER(SEARCH("[B]",INDEX($C10:$G10,$U10))),"B","-")))) | BK10: =IF($V10="","",IF(INDEX($C10:$G10,$V10)="","",IF(ISNUMBER(SEARCH("[A]",INDEX($C10:$G10,$V10))),"A",IF(ISNUMBER(SEARCH("[B]",INDEX($C10:$G10,$V10))),"B","-")))) | BL10: =IF($W10="","",IF(INDEX($C10:$G10,$W10)="","",IF(ISNUMBER(SEARCH("[A]",INDEX($C10:$G10,$W10))),"A",IF(ISNUMBER(SEARCH("[B]",INDEX($C10:$G10,$W10))),"B","-")))) | BM10: =IF($X10="","",IF(INDEX($C10:$G10,$X10)="","",IF(ISNUMBER(SEARCH("[A]",INDEX($C10:$G10,$X10))),"A",IF(ISNUMBER(SEARCH("[B]",INDEX($C10:$G10,$X10))),"B","-")))) | BN10: =IF($Y10="","",IF(INDEX($C10:$G10,$Y10)="","",IF(ISNUMBER(SEARCH("[A]",INDEX($C10:$G10,$Y10))),"A",IF(ISNUMBER(SEARCH("[B]",INDEX($C10:$G10,$Y10))),"B","-")))) | BO10: =IF($Z10="","",IF(INDEX($C10:$G10,$Z10)="","",IF(ISNUMBER(SEARCH("[A]",INDEX($C10:$G10,$Z10))),"A",IF(ISNUMBER(SEARCH("[B]",INDEX($C10:$G10,$Z10))),"B","-")))) | BP10: =IF($AA10="","",IF(INDEX($C10:$G10,$AA10)="","",IF(ISNUMBER(SEARCH("[A]",INDEX($C10:$G10,$AA10))),"A",IF(ISNUMBER(SEARCH("[B]",INDEX($C10:$G10,$AA10))),"B","-")))) | BQ10: =IF($AB10="","",IF(INDEX($C10:$G10,$AB10)="","",IF(ISNUMBER(SEARCH("[A]",INDEX($C10:$G10,$AB10))),"A",IF(ISNUMBER(SEARCH("[B]",INDEX($C10:$G10,$AB10))),"B","-")))) | BR10: =IF($AC10="","",IF(INDEX($C10:$G10,$AC10)="","",IF(ISNUMBER(SEARCH("[A]",INDEX($C10:$G10,$AC10))),"A",IF(ISNUMBER(SEARCH("[B]",INDEX($C10:$G10,$AC10))),"B","-"))))
A11: 분리 | B11: 자세·무게중심 | C11: 사지에 균등·중립 | E11: 무게중심 뒤·뒷걸음 자세 [B] | F11: 무게중심 앞·몸을 앞으로 기울임 [A] | G11: 몸 낮춤·웅크림·배 노출 [B] | H11: 친밀·애착 | I11: ★ | AD11: ATT | AE11: =IF($J11="","",IF(INDEX($C11:$G11,$J11)="","",$J11)) | AF11: =IF($K11="","",IF(INDEX($C11:$G11,$K11)="","",$K11)) | AG11: =IF($L11="","",IF(INDEX($C11:$G11,$L11)="","",$L11)) | AH11: =IF($M11="","",IF(INDEX($C11:$G11,$M11)="","",$M11)) | AI11: =IF($N11="","",IF(INDEX($C11:$G11,$N11)="","",$N11)) | AJ11: =IF($O11="","",IF(INDEX($C11:$G11,$O11)="","",$O11)) | AK11: =IF($P11="","",IF(INDEX($C11:$G11,$P11)="","",$P11)) | AL11: =IF($Q11="","",IF(INDEX($C11:$G11,$Q11)="","",$Q11)) | AM11: =IF($R11="","",IF(INDEX($C11:$G11,$R11)="","",$R11)) | AN11: =IF($S11="","",IF(INDEX($C11:$G11,$S11)="","",$S11)) | AO11: =IF($T11="","",IF(INDEX($C11:$G11,$T11)="","",$T11)) | AP11: =IF($U11="","",IF(INDEX($C11:$G11,$U11)="","",$U11)) | AQ11: =IF($V11="","",IF(INDEX($C11:$G11,$V11)="","",$V11)) | AR11: =IF($W11="","",IF(INDEX($C11:$G11,$W11)="","",$W11)) | AS11: =IF($X11="","",IF(INDEX($C11:$G11,$X11)="","",$X11)) | AT11: =IF($Y11="","",IF(INDEX($C11:$G11,$Y11)="","",$Y11)) | AU11: =IF($Z11="","",IF(INDEX($C11:$G11,$Z11)="","",$Z11)) | AV11: =IF($AA11="","",IF(INDEX($C11:$G11,$AA11)="","",$AA11)) | AW11: =IF($AB11="","",IF(INDEX($C11:$G11,$AB11)="","",$AB11)) | AX11: =IF($AC11="","",IF(INDEX($C11:$G11,$AC11)="","",$AC11)) | AY11: =IF($J11="","",IF(INDEX($C11:$G11,$J11)="","",IF(ISNUMBER(SEARCH("[A]",INDEX($C11:$G11,$J11))),"A",IF(ISNUMBER(SEARCH("[B]",INDEX($C11:$G11,$J11))),"B","-")))) | AZ11: =IF($K11="","",IF(INDEX($C11:$G11,$K11)="","",IF(ISNUMBER(SEARCH("[A]",INDEX($C11:$G11,$K11))),"A",IF(ISNUMBER(SEARCH("[B]",INDEX($C11:$G11,$K11))),"B","-")))) | BA11: =IF($L11="","",IF(INDEX($C11:$G11,$L11)="","",IF(ISNUMBER(SEARCH("[A]",INDEX($C11:$G11,$L11))),"A",IF(ISNUMBER(SEARCH("[B]",INDEX($C11:$G11,$L11))),"B","-")))) | BB11: =IF($M11="","",IF(INDEX($C11:$G11,$M11)="","",IF(ISNUMBER(SEARCH("[A]",INDEX($C11:$G11,$M11))),"A",IF(ISNUMBER(SEARCH("[B]",INDEX($C11:$G11,$M11))),"B","-")))) | BC11: =IF($N11="","",IF(INDEX($C11:$G11,$N11)="","",IF(ISNUMBER(SEARCH("[A]",INDEX($C11:$G11,$N11))),"A",IF(ISNUMBER(SEARCH("[B]",INDEX($C11:$G11,$N11))),"B","-")))) | BD11: =IF($O11="","",IF(INDEX($C11:$G11,$O11)="","",IF(ISNUMBER(SEARCH("[A]",INDEX($C11:$G11,$O11))),"A",IF(ISNUMBER(SEARCH("[B]",INDEX($C11:$G11,$O11))),"B","-")))) | BE11: =IF($P11="","",IF(INDEX($C11:$G11,$P11)="","",IF(ISNUMBER(SEARCH("[A]",INDEX($C11:$G11,$P11))),"A",IF(ISNUMBER(SEARCH("[B]",INDEX($C11:$G11,$P11))),"B","-")))) | BF11: =IF($Q11="","",IF(INDEX($C11:$G11,$Q11)="","",IF(ISNUMBER(SEARCH("[A]",INDEX($C11:$G11,$Q11))),"A",IF(ISNUMBER(SEARCH("[B]",INDEX($C11:$G11,$Q11))),"B","-")))) | BG11: =IF($R11="","",IF(INDEX($C11:$G11,$R11)="","",IF(ISNUMBER(SEARCH("[A]",INDEX($C11:$G11,$R11))),"A",IF(ISNUMBER(SEARCH("[B]",INDEX($C11:$G11,$R11))),"B","-")))) | BH11: =IF($S11="","",IF(INDEX($C11:$G11,$S11)="","",IF(ISNUMBER(SEARCH("[A]",INDEX($C11:$G11,$S11))),"A",IF(ISNUMBER(SEARCH("[B]",INDEX($C11:$G11,$S11))),"B","-")))) | BI11: =IF($T11="","",IF(INDEX($C11:$G11,$T11)="","",IF(ISNUMBER(SEARCH("[A]",INDEX($C11:$G11,$T11))),"A",IF(ISNUMBER(SEARCH("[B]",INDEX($C11:$G11,$T11))),"B","-")))) | BJ11: =IF($U11="","",IF(INDEX($C11:$G11,$U11)="","",IF(ISNUMBER(SEARCH("[A]",INDEX($C11:$G11,$U11))),"A",IF(ISNUMBER(SEARCH("[B]",INDEX($C11:$G11,$U11))),"B","-")))) | BK11: =IF($V11="","",IF(INDEX($C11:$G11,$V11)="","",IF(ISNUMBER(SEARCH("[A]",INDEX($C11:$G11,$V11))),"A",IF(ISNUMBER(SEARCH("[B]",INDEX($C11:$G11,$V11))),"B","-")))) | BL11: =IF($W11="","",IF(INDEX($C11:$G11,$W11)="","",IF(ISNUMBER(SEARCH("[A]",INDEX($C11:$G11,$W11))),"A",IF(ISNUMBER(SEARCH("[B]",INDEX($C11:$G11,$W11))),"B","-")))) | BM11: =IF($X11="","",IF(INDEX($C11:$G11,$X11)="","",IF(ISNUMBER(SEARCH("[A]",INDEX($C11:$G11,$X11))),"A",IF(ISNUMBER(SEARCH("[B]",INDEX($C11:$G11,$X11))),"B","-")))) | BN11: =IF($Y11="","",IF(INDEX($C11:$G11,$Y11)="","",IF(ISNUMBER(SEARCH("[A]",INDEX($C11:$G11,$Y11))),"A",IF(ISNUMBER(SEARCH("[B]",INDEX($C11:$G11,$Y11))),"B","-")))) | BO11: =IF($Z11="","",IF(INDEX($C11:$G11,$Z11)="","",IF(ISNUMBER(SEARCH("[A]",INDEX($C11:$G11,$Z11))),"A",IF(ISNUMBER(SEARCH("[B]",INDEX($C11:$G11,$Z11))),"B","-")))) | BP11: =IF($AA11="","",IF(INDEX($C11:$G11,$AA11)="","",IF(ISNUMBER(SEARCH("[A]",INDEX($C11:$G11,$AA11))),"A",IF(ISNUMBER(SEARCH("[B]",INDEX($C11:$G11,$AA11))),"B","-")))) | BQ11: =IF($AB11="","",IF(INDEX($C11:$G11,$AB11)="","",IF(ISNUMBER(SEARCH("[A]",INDEX($C11:$G11,$AB11))),"A",IF(ISNUMBER(SEARCH("[B]",INDEX($C11:$G11,$AB11))),"B","-")))) | BR11: =IF($AC11="","",IF(INDEX($C11:$G11,$AC11)="","",IF(ISNUMBER(SEARCH("[A]",INDEX($C11:$G11,$AC11))),"A",IF(ISNUMBER(SEARCH("[B]",INDEX($C11:$G11,$AC11))),"B","-"))))
A12: 분리 | B12: 이동 | C12: 자발적 접근 또는 중립 유지 | E12: 회피·후퇴 [B] | F12: 자극 향해 돌진·리드줄 당김 [A] | G12: 프리징(2초 이상 정지)·보호자 뒤로 숨음 [B] | H12: 친밀·애착 | I12: ★ | AD12: ATT | AE12: =IF($J12="","",IF(INDEX($C12:$G12,$J12)="","",$J12)) | AF12: =IF($K12="","",IF(INDEX($C12:$G12,$K12)="","",$K12)) | AG12: =IF($L12="","",IF(INDEX($C12:$G12,$L12)="","",$L12)) | AH12: =IF($M12="","",IF(INDEX($C12:$G12,$M12)="","",$M12)) | AI12: =IF($N12="","",IF(INDEX($C12:$G12,$N12)="","",$N12)) | AJ12: =IF($O12="","",IF(INDEX($C12:$G12,$O12)="","",$O12)) | AK12: =IF($P12="","",IF(INDEX($C12:$G12,$P12)="","",$P12)) | AL12: =IF($Q12="","",IF(INDEX($C12:$G12,$Q12)="","",$Q12)) | AM12: =IF($R12="","",IF(INDEX($C12:$G12,$R12)="","",$R12)) | AN12: =IF($S12="","",IF(INDEX($C12:$G12,$S12)="","",$S12)) | AO12: =IF($T12="","",IF(INDEX($C12:$G12,$T12)="","",$T12)) | AP12: =IF($U12="","",IF(INDEX($C12:$G12,$U12)="","",$U12)) | AQ12: =IF($V12="","",IF(INDEX($C12:$G12,$V12)="","",$V12)) | AR12: =IF($W12="","",IF(INDEX($C12:$G12,$W12)="","",$W12)) | AS12: =IF($X12="","",IF(INDEX($C12:$G12,$X12)="","",$X12)) | AT12: =IF($Y12="","",IF(INDEX($C12:$G12,$Y12)="","",$Y12)) | AU12: =IF($Z12="","",IF(INDEX($C12:$G12,$Z12)="","",$Z12)) | AV12: =IF($AA12="","",IF(INDEX($C12:$G12,$AA12)="","",$AA12)) | AW12: =IF($AB12="","",IF(INDEX($C12:$G12,$AB12)="","",$AB12)) | AX12: =IF($AC12="","",IF(INDEX($C12:$G12,$AC12)="","",$AC12)) | AY12: =IF($J12="","",IF(INDEX($C12:$G12,$J12)="","",IF(ISNUMBER(SEARCH("[A]",INDEX($C12:$G12,$J12))),"A",IF(ISNUMBER(SEARCH("[B]",INDEX($C12:$G12,$J12))),"B","-")))) | AZ12: =IF($K12="","",IF(INDEX($C12:$G12,$K12)="","",IF(ISNUMBER(SEARCH("[A]",INDEX($C12:$G12,$K12))),"A",IF(ISNUMBER(SEARCH("[B]",INDEX($C12:$G12,$K12))),"B","-")))) | BA12: =IF($L12="","",IF(INDEX($C12:$G12,$L12)="","",IF(ISNUMBER(SEARCH("[A]",INDEX($C12:$G12,$L12))),"A",IF(ISNUMBER(SEARCH("[B]",INDEX($C12:$G12,$L12))),"B","-")))) | BB12: =IF($M12="","",IF(INDEX($C12:$G12,$M12)="","",IF(ISNUMBER(SEARCH("[A]",INDEX($C12:$G12,$M12))),"A",IF(ISNUMBER(SEARCH("[B]",INDEX($C12:$G12,$M12))),"B","-")))) | BC12: =IF($N12="","",IF(INDEX($C12:$G12,$N12)="","",IF(ISNUMBER(SEARCH("[A]",INDEX($C12:$G12,$N12))),"A",IF(ISNUMBER(SEARCH("[B]",INDEX($C12:$G12,$N12))),"B","-")))) | BD12: =IF($O12="","",IF(INDEX($C12:$G12,$O12)="","",IF(ISNUMBER(SEARCH("[A]",INDEX($C12:$G12,$O12))),"A",IF(ISNUMBER(SEARCH("[B]",INDEX($C12:$G12,$O12))),"B","-")))) | BE12: =IF($P12="","",IF(INDEX($C12:$G12,$P12)="","",IF(ISNUMBER(SEARCH("[A]",INDEX($C12:$G12,$P12))),"A",IF(ISNUMBER(SEARCH("[B]",INDEX($C12:$G12,$P12))),"B","-")))) | BF12: =IF($Q12="","",IF(INDEX($C12:$G12,$Q12)="","",IF(ISNUMBER(SEARCH("[A]",INDEX($C12:$G12,$Q12))),"A",IF(ISNUMBER(SEARCH("[B]",INDEX($C12:$G12,$Q12))),"B","-")))) | BG12: =IF($R12="","",IF(INDEX($C12:$G12,$R12)="","",IF(ISNUMBER(SEARCH("[A]",INDEX($C12:$G12,$R12))),"A",IF(ISNUMBER(SEARCH("[B]",INDEX($C12:$G12,$R12))),"B","-")))) | BH12: =IF($S12="","",IF(INDEX($C12:$G12,$S12)="","",IF(ISNUMBER(SEARCH("[A]",INDEX($C12:$G12,$S12))),"A",IF(ISNUMBER(SEARCH("[B]",INDEX($C12:$G12,$S12))),"B","-")))) | BI12: =IF($T12="","",IF(INDEX($C12:$G12,$T12)="","",IF(ISNUMBER(SEARCH("[A]",INDEX($C12:$G12,$T12))),"A",IF(ISNUMBER(SEARCH("[B]",INDEX($C12:$G12,$T12))),"B","-")))) | BJ12: =IF($U12="","",IF(INDEX($C12:$G12,$U12)="","",IF(ISNUMBER(SEARCH("[A]",INDEX($C12:$G12,$U12))),"A",IF(ISNUMBER(SEARCH("[B]",INDEX($C12:$G12,$U12))),"B","-")))) | BK12: =IF($V12="","",IF(INDEX($C12:$G12,$V12)="","",IF(ISNUMBER(SEARCH("[A]",INDEX($C12:$G12,$V12))),"A",IF(ISNUMBER(SEARCH("[B]",INDEX($C12:$G12,$V12))),"B","-")))) | BL12: =IF($W12="","",IF(INDEX($C12:$G12,$W12)="","",IF(ISNUMBER(SEARCH("[A]",INDEX($C12:$G12,$W12))),"A",IF(ISNUMBER(SEARCH("[B]",INDEX($C12:$G12,$W12))),"B","-")))) | BM12: =IF($X12="","",IF(INDEX($C12:$G12,$X12)="","",IF(ISNUMBER(SEARCH("[A]",INDEX($C12:$G12,$X12))),"A",IF(ISNUMBER(SEARCH("[B]",INDEX($C12:$G12,$X12))),"B","-")))) | BN12: =IF($Y12="","",IF(INDEX($C12:$G12,$Y12)="","",IF(ISNUMBER(SEARCH("[A]",INDEX($C12:$G12,$Y12))),"A",IF(ISNUMBER(SEARCH("[B]",INDEX($C12:$G12,$Y12))),"B","-")))) | BO12: =IF($Z12="","",IF(INDEX($C12:$G12,$Z12)="","",IF(ISNUMBER(SEARCH("[A]",INDEX($C12:$G12,$Z12))),"A",IF(ISNUMBER(SEARCH("[B]",INDEX($C12:$G12,$Z12))),"B","-")))) | BP12: =IF($AA12="","",IF(INDEX($C12:$G12,$AA12)="","",IF(ISNUMBER(SEARCH("[A]",INDEX($C12:$G12,$AA12))),"A",IF(ISNUMBER(SEARCH("[B]",INDEX($C12:$G12,$AA12))),"B","-")))) | BQ12: =IF($AB12="","",IF(INDEX($C12:$G12,$AB12)="","",IF(ISNUMBER(SEARCH("[A]",INDEX($C12:$G12,$AB12))),"A",IF(ISNUMBER(SEARCH("[B]",INDEX($C12:$G12,$AB12))),"B","-")))) | BR12: =IF($AC12="","",IF(INDEX($C12:$G12,$AC12)="","",IF(ISNUMBER(SEARCH("[A]",INDEX($C12:$G12,$AC12))),"A",IF(ISNUMBER(SEARCH("[B]",INDEX($C12:$G12,$AC12))),"B","-"))))
A13: 훈련 | B13: 꼬리 | C13: 중립 높이·이완되어 있음 | D13: 평소보다 낮게 내림 [B] | E13: 높이 들고 경직·짧고 빠른 흔들림 [A] | G13: 다리 사이로 말아 넣음 [B] | H13: 훈련 수행(개) | I13: ★ | AD13: TRN | AE13: =IF($J13="","",IF(INDEX($C13:$G13,$J13)="","",$J13)) | AF13: =IF($K13="","",IF(INDEX($C13:$G13,$K13)="","",$K13)) | AG13: =IF($L13="","",IF(INDEX($C13:$G13,$L13)="","",$L13)) | AH13: =IF($M13="","",IF(INDEX($C13:$G13,$M13)="","",$M13)) | AI13: =IF($N13="","",IF(INDEX($C13:$G13,$N13)="","",$N13)) | AJ13: =IF($O13="","",IF(INDEX($C13:$G13,$O13)="","",$O13)) | AK13: =IF($P13="","",IF(INDEX($C13:$G13,$P13)="","",$P13)) | AL13: =IF($Q13="","",IF(INDEX($C13:$G13,$Q13)="","",$Q13)) | AM13: =IF($R13="","",IF(INDEX($C13:$G13,$R13)="","",$R13)) | AN13: =IF($S13="","",IF(INDEX($C13:$G13,$S13)="","",$S13)) | AO13: =IF($T13="","",IF(INDEX($C13:$G13,$T13)="","",$T13)) | AP13: =IF($U13="","",IF(INDEX($C13:$G13,$U13)="","",$U13)) | AQ13: =IF($V13="","",IF(INDEX($C13:$G13,$V13)="","",$V13)) | AR13: =IF($W13="","",IF(INDEX($C13:$G13,$W13)="","",$W13)) | AS13: =IF($X13="","",IF(INDEX($C13:$G13,$X13)="","",$X13)) | AT13: =IF($Y13="","",IF(INDEX($C13:$G13,$Y13)="","",$Y13)) | AU13: =IF($Z13="","",IF(INDEX($C13:$G13,$Z13)="","",$Z13)) | AV13: =IF($AA13="","",IF(INDEX($C13:$G13,$AA13)="","",$AA13)) | AW13: =IF($AB13="","",IF(INDEX($C13:$G13,$AB13)="","",$AB13)) | AX13: =IF($AC13="","",IF(INDEX($C13:$G13,$AC13)="","",$AC13)) | AY13: =IF($J13="","",IF(INDEX($C13:$G13,$J13)="","",IF(ISNUMBER(SEARCH("[A]",INDEX($C13:$G13,$J13))),"A",IF(ISNUMBER(SEARCH("[B]",INDEX($C13:$G13,$J13))),"B","-")))) | AZ13: =IF($K13="","",IF(INDEX($C13:$G13,$K13)="","",IF(ISNUMBER(SEARCH("[A]",INDEX($C13:$G13,$K13))),"A",IF(ISNUMBER(SEARCH("[B]",INDEX($C13:$G13,$K13))),"B","-")))) | BA13: =IF($L13="","",IF(INDEX($C13:$G13,$L13)="","",IF(ISNUMBER(SEARCH("[A]",INDEX($C13:$G13,$L13))),"A",IF(ISNUMBER(SEARCH("[B]",INDEX($C13:$G13,$L13))),"B","-")))) | BB13: =IF($M13="","",IF(INDEX($C13:$G13,$M13)="","",IF(ISNUMBER(SEARCH("[A]",INDEX($C13:$G13,$M13))),"A",IF(ISNUMBER(SEARCH("[B]",INDEX($C13:$G13,$M13))),"B","-")))) | BC13: =IF($N13="","",IF(INDEX($C13:$G13,$N13)="","",IF(ISNUMBER(SEARCH("[A]",INDEX($C13:$G13,$N13))),"A",IF(ISNUMBER(SEARCH("[B]",INDEX($C13:$G13,$N13))),"B","-")))) | BD13: =IF($O13="","",IF(INDEX($C13:$G13,$O13)="","",IF(ISNUMBER(SEARCH("[A]",INDEX($C13:$G13,$O13))),"A",IF(ISNUMBER(SEARCH("[B]",INDEX($C13:$G13,$O13))),"B","-")))) | BE13: =IF($P13="","",IF(INDEX($C13:$G13,$P13)="","",IF(ISNUMBER(SEARCH("[A]",INDEX($C13:$G13,$P13))),"A",IF(ISNUMBER(SEARCH("[B]",INDEX($C13:$G13,$P13))),"B","-")))) | BF13: =IF($Q13="","",IF(INDEX($C13:$G13,$Q13)="","",IF(ISNUMBER(SEARCH("[A]",INDEX($C13:$G13,$Q13))),"A",IF(ISNUMBER(SEARCH("[B]",INDEX($C13:$G13,$Q13))),"B","-")))) | BG13: =IF($R13="","",IF(INDEX($C13:$G13,$R13)="","",IF(ISNUMBER(SEARCH("[A]",INDEX($C13:$G13,$R13))),"A",IF(ISNUMBER(SEARCH("[B]",INDEX($C13:$G13,$R13))),"B","-")))) | BH13: =IF($S13="","",IF(INDEX($C13:$G13,$S13)="","",IF(ISNUMBER(SEARCH("[A]",INDEX($C13:$G13,$S13))),"A",IF(ISNUMBER(SEARCH("[B]",INDEX($C13:$G13,$S13))),"B","-")))) | BI13: =IF($T13="","",IF(INDEX($C13:$G13,$T13)="","",IF(ISNUMBER(SEARCH("[A]",INDEX($C13:$G13,$T13))),"A",IF(ISNUMBER(SEARCH("[B]",INDEX($C13:$G13,$T13))),"B","-")))) | BJ13: =IF($U13="","",IF(INDEX($C13:$G13,$U13)="","",IF(ISNUMBER(SEARCH("[A]",INDEX($C13:$G13,$U13))),"A",IF(ISNUMBER(SEARCH("[B]",INDEX($C13:$G13,$U13))),"B","-")))) | BK13: =IF($V13="","",IF(INDEX($C13:$G13,$V13)="","",IF(ISNUMBER(SEARCH("[A]",INDEX($C13:$G13,$V13))),"A",IF(ISNUMBER(SEARCH("[B]",INDEX($C13:$G13,$V13))),"B","-")))) | BL13: =IF($W13="","",IF(INDEX($C13:$G13,$W13)="","",IF(ISNUMBER(SEARCH("[A]",INDEX($C13:$G13,$W13))),"A",IF(ISNUMBER(SEARCH("[B]",INDEX($C13:$G13,$W13))),"B","-")))) | BM13: =IF($X13="","",IF(INDEX($C13:$G13,$X13)="","",IF(ISNUMBER(SEARCH("[A]",INDEX($C13:$G13,$X13))),"A",IF(ISNUMBER(SEARCH("[B]",INDEX($C13:$G13,$X13))),"B","-")))) | BN13: =IF($Y13="","",IF(INDEX($C13:$G13,$Y13)="","",IF(ISNUMBER(SEARCH("[A]",INDEX($C13:$G13,$Y13))),"A",IF(ISNUMBER(SEARCH("[B]",INDEX($C13:$G13,$Y13))),"B","-")))) | BO13: =IF($Z13="","",IF(INDEX($C13:$G13,$Z13)="","",IF(ISNUMBER(SEARCH("[A]",INDEX($C13:$G13,$Z13))),"A",IF(ISNUMBER(SEARCH("[B]",INDEX($C13:$G13,$Z13))),"B","-")))) | BP13: =IF($AA13="","",IF(INDEX($C13:$G13,$AA13)="","",IF(ISNUMBER(SEARCH("[A]",INDEX($C13:$G13,$AA13))),"A",IF(ISNUMBER(SEARCH("[B]",INDEX($C13:$G13,$AA13))),"B","-")))) | BQ13: =IF($AB13="","",IF(INDEX($C13:$G13,$AB13)="","",IF(ISNUMBER(SEARCH("[A]",INDEX($C13:$G13,$AB13))),"A",IF(ISNUMBER(SEARCH("[B]",INDEX($C13:$G13,$AB13))),"B","-")))) | BR13: =IF($AC13="","",IF(INDEX($C13:$G13,$AC13)="","",IF(ISNUMBER(SEARCH("[A]",INDEX($C13:$G13,$AC13))),"A",IF(ISNUMBER(SEARCH("[B]",INDEX($C13:$G13,$AC13))),"B","-"))))
A14: 놀이 | B14: 꼬리 | C14: 중립 높이·이완되어 있음 | D14: 평소보다 낮게 내림 [B] | E14: 높이 들고 경직·짧고 빠른 흔들림 [A] | G14: 다리 사이로 말아 넣음 [B] | H14: 친밀·애착 | I14: ★ | AD14: ATT | AE14: =IF($J14="","",IF(INDEX($C14:$G14,$J14)="","",$J14)) | AF14: =IF($K14="","",IF(INDEX($C14:$G14,$K14)="","",$K14)) | AG14: =IF($L14="","",IF(INDEX($C14:$G14,$L14)="","",$L14)) | AH14: =IF($M14="","",IF(INDEX($C14:$G14,$M14)="","",$M14)) | AI14: =IF($N14="","",IF(INDEX($C14:$G14,$N14)="","",$N14)) | AJ14: =IF($O14="","",IF(INDEX($C14:$G14,$O14)="","",$O14)) | AK14: =IF($P14="","",IF(INDEX($C14:$G14,$P14)="","",$P14)) | AL14: =IF($Q14="","",IF(INDEX($C14:$G14,$Q14)="","",$Q14)) | AM14: =IF($R14="","",IF(INDEX($C14:$G14,$R14)="","",$R14)) | AN14: =IF($S14="","",IF(INDEX($C14:$G14,$S14)="","",$S14)) | AO14: =IF($T14="","",IF(INDEX($C14:$G14,$T14)="","",$T14)) | AP14: =IF($U14="","",IF(INDEX($C14:$G14,$U14)="","",$U14)) | AQ14: =IF($V14="","",IF(INDEX($C14:$G14,$V14)="","",$V14)) | AR14: =IF($W14="","",IF(INDEX($C14:$G14,$W14)="","",$W14)) | AS14: =IF($X14="","",IF(INDEX($C14:$G14,$X14)="","",$X14)) | AT14: =IF($Y14="","",IF(INDEX($C14:$G14,$Y14)="","",$Y14)) | AU14: =IF($Z14="","",IF(INDEX($C14:$G14,$Z14)="","",$Z14)) | AV14: =IF($AA14="","",IF(INDEX($C14:$G14,$AA14)="","",$AA14)) | AW14: =IF($AB14="","",IF(INDEX($C14:$G14,$AB14)="","",$AB14)) | AX14: =IF($AC14="","",IF(INDEX($C14:$G14,$AC14)="","",$AC14)) | AY14: =IF($J14="","",IF(INDEX($C14:$G14,$J14)="","",IF(ISNUMBER(SEARCH("[A]",INDEX($C14:$G14,$J14))),"A",IF(ISNUMBER(SEARCH("[B]",INDEX($C14:$G14,$J14))),"B","-")))) | AZ14: =IF($K14="","",IF(INDEX($C14:$G14,$K14)="","",IF(ISNUMBER(SEARCH("[A]",INDEX($C14:$G14,$K14))),"A",IF(ISNUMBER(SEARCH("[B]",INDEX($C14:$G14,$K14))),"B","-")))) | BA14: =IF($L14="","",IF(INDEX($C14:$G14,$L14)="","",IF(ISNUMBER(SEARCH("[A]",INDEX($C14:$G14,$L14))),"A",IF(ISNUMBER(SEARCH("[B]",INDEX($C14:$G14,$L14))),"B","-")))) | BB14: =IF($M14="","",IF(INDEX($C14:$G14,$M14)="","",IF(ISNUMBER(SEARCH("[A]",INDEX($C14:$G14,$M14))),"A",IF(ISNUMBER(SEARCH("[B]",INDEX($C14:$G14,$M14))),"B","-")))) | BC14: =IF($N14="","",IF(INDEX($C14:$G14,$N14)="","",IF(ISNUMBER(SEARCH("[A]",INDEX($C14:$G14,$N14))),"A",IF(ISNUMBER(SEARCH("[B]",INDEX($C14:$G14,$N14))),"B","-")))) | BD14: =IF($O14="","",IF(INDEX($C14:$G14,$O14)="","",IF(ISNUMBER(SEARCH("[A]",INDEX($C14:$G14,$O14))),"A",IF(ISNUMBER(SEARCH("[B]",INDEX($C14:$G14,$O14))),"B","-")))) | BE14: =IF($P14="","",IF(INDEX($C14:$G14,$P14)="","",IF(ISNUMBER(SEARCH("[A]",INDEX($C14:$G14,$P14))),"A",IF(ISNUMBER(SEARCH("[B]",INDEX($C14:$G14,$P14))),"B","-")))) | BF14: =IF($Q14="","",IF(INDEX($C14:$G14,$Q14)="","",IF(ISNUMBER(SEARCH("[A]",INDEX($C14:$G14,$Q14))),"A",IF(ISNUMBER(SEARCH("[B]",INDEX($C14:$G14,$Q14))),"B","-")))) | BG14: =IF($R14="","",IF(INDEX($C14:$G14,$R14)="","",IF(ISNUMBER(SEARCH("[A]",INDEX($C14:$G14,$R14))),"A",IF(ISNUMBER(SEARCH("[B]",INDEX($C14:$G14,$R14))),"B","-")))) | BH14: =IF($S14="","",IF(INDEX($C14:$G14,$S14)="","",IF(ISNUMBER(SEARCH("[A]",INDEX($C14:$G14,$S14))),"A",IF(ISNUMBER(SEARCH("[B]",INDEX($C14:$G14,$S14))),"B","-")))) | BI14: =IF($T14="","",IF(INDEX($C14:$G14,$T14)="","",IF(ISNUMBER(SEARCH("[A]",INDEX($C14:$G14,$T14))),"A",IF(ISNUMBER(SEARCH("[B]",INDEX($C14:$G14,$T14))),"B","-")))) | BJ14: =IF($U14="","",IF(INDEX($C14:$G14,$U14)="","",IF(ISNUMBER(SEARCH("[A]",INDEX($C14:$G14,$U14))),"A",IF(ISNUMBER(SEARCH("[B]",INDEX($C14:$G14,$U14))),"B","-")))) | BK14: =IF($V14="","",IF(INDEX($C14:$G14,$V14)="","",IF(ISNUMBER(SEARCH("[A]",INDEX($C14:$G14,$V14))),"A",IF(ISNUMBER(SEARCH("[B]",INDEX($C14:$G14,$V14))),"B","-")))) | BL14: =IF($W14="","",IF(INDEX($C14:$G14,$W14)="","",IF(ISNUMBER(SEARCH("[A]",INDEX($C14:$G14,$W14))),"A",IF(ISNUMBER(SEARCH("[B]",INDEX($C14:$G14,$W14))),"B","-")))) | BM14: =IF($X14="","",IF(INDEX($C14:$G14,$X14)="","",IF(ISNUMBER(SEARCH("[A]",INDEX($C14:$G14,$X14))),"A",IF(ISNUMBER(SEARCH("[B]",INDEX($C14:$G14,$X14))),"B","-")))) | BN14: =IF($Y14="","",IF(INDEX($C14:$G14,$Y14)="","",IF(ISNUMBER(SEARCH("[A]",INDEX($C14:$G14,$Y14))),"A",IF(ISNUMBER(SEARCH("[B]",INDEX($C14:$G14,$Y14))),"B","-")))) | BO14: =IF($Z14="","",IF(INDEX($C14:$G14,$Z14)="","",IF(ISNUMBER(SEARCH("[A]",INDEX($C14:$G14,$Z14))),"A",IF(ISNUMBER(SEARCH("[B]",INDEX($C14:$G14,$Z14))),"B","-")))) | BP14: =IF($AA14="","",IF(INDEX($C14:$G14,$AA14)="","",IF(ISNUMBER(SEARCH("[A]",INDEX($C14:$G14,$AA14))),"A",IF(ISNUMBER(SEARCH("[B]",INDEX($C14:$G14,$AA14))),"B","-")))) | BQ14: =IF($AB14="","",IF(INDEX($C14:$G14,$AB14)="","",IF(ISNUMBER(SEARCH("[A]",INDEX($C14:$G14,$AB14))),"A",IF(ISNUMBER(SEARCH("[B]",INDEX($C14:$G14,$AB14))),"B","-")))) | BR14: =IF($AC14="","",IF(INDEX($C14:$G14,$AC14)="","",IF(ISNUMBER(SEARCH("[A]",INDEX($C14:$G14,$AC14))),"A",IF(ISNUMBER(SEARCH("[B]",INDEX($C14:$G14,$AC14))),"B","-"))))
A15: 놀이 | B15: 자세·무게중심 | C15: 사지에 균등·중립 | E15: 무게중심 뒤·뒷걸음 자세 [B] | F15: 무게중심 앞·몸을 앞으로 기울임 [A] | G15: 몸 낮춤·웅크림·배 노출 [B] | H15: 친밀·애착 | I15: ★ | AD15: ATT | AE15: =IF($J15="","",IF(INDEX($C15:$G15,$J15)="","",$J15)) | AF15: =IF($K15="","",IF(INDEX($C15:$G15,$K15)="","",$K15)) | AG15: =IF($L15="","",IF(INDEX($C15:$G15,$L15)="","",$L15)) | AH15: =IF($M15="","",IF(INDEX($C15:$G15,$M15)="","",$M15)) | AI15: =IF($N15="","",IF(INDEX($C15:$G15,$N15)="","",$N15)) | AJ15: =IF($O15="","",IF(INDEX($C15:$G15,$O15)="","",$O15)) | AK15: =IF($P15="","",IF(INDEX($C15:$G15,$P15)="","",$P15)) | AL15: =IF($Q15="","",IF(INDEX($C15:$G15,$Q15)="","",$Q15)) | AM15: =IF($R15="","",IF(INDEX($C15:$G15,$R15)="","",$R15)) | AN15: =IF($S15="","",IF(INDEX($C15:$G15,$S15)="","",$S15)) | AO15: =IF($T15="","",IF(INDEX($C15:$G15,$T15)="","",$T15)) | AP15: =IF($U15="","",IF(INDEX($C15:$G15,$U15)="","",$U15)) | AQ15: =IF($V15="","",IF(INDEX($C15:$G15,$V15)="","",$V15)) | AR15: =IF($W15="","",IF(INDEX($C15:$G15,$W15)="","",$W15)) | AS15: =IF($X15="","",IF(INDEX($C15:$G15,$X15)="","",$X15)) | AT15: =IF($Y15="","",IF(INDEX($C15:$G15,$Y15)="","",$Y15)) | AU15: =IF($Z15="","",IF(INDEX($C15:$G15,$Z15)="","",$Z15)) | AV15: =IF($AA15="","",IF(INDEX($C15:$G15,$AA15)="","",$AA15)) | AW15: =IF($AB15="","",IF(INDEX($C15:$G15,$AB15)="","",$AB15)) | AX15: =IF($AC15="","",IF(INDEX($C15:$G15,$AC15)="","",$AC15)) | AY15: =IF($J15="","",IF(INDEX($C15:$G15,$J15)="","",IF(ISNUMBER(SEARCH("[A]",INDEX($C15:$G15,$J15))),"A",IF(ISNUMBER(SEARCH("[B]",INDEX($C15:$G15,$J15))),"B","-")))) | AZ15: =IF($K15="","",IF(INDEX($C15:$G15,$K15)="","",IF(ISNUMBER(SEARCH("[A]",INDEX($C15:$G15,$K15))),"A",IF(ISNUMBER(SEARCH("[B]",INDEX($C15:$G15,$K15))),"B","-")))) | BA15: =IF($L15="","",IF(INDEX($C15:$G15,$L15)="","",IF(ISNUMBER(SEARCH("[A]",INDEX($C15:$G15,$L15))),"A",IF(ISNUMBER(SEARCH("[B]",INDEX($C15:$G15,$L15))),"B","-")))) | BB15: =IF($M15="","",IF(INDEX($C15:$G15,$M15)="","",IF(ISNUMBER(SEARCH("[A]",INDEX($C15:$G15,$M15))),"A",IF(ISNUMBER(SEARCH("[B]",INDEX($C15:$G15,$M15))),"B","-")))) | BC15: =IF($N15="","",IF(INDEX($C15:$G15,$N15)="","",IF(ISNUMBER(SEARCH("[A]",INDEX($C15:$G15,$N15))),"A",IF(ISNUMBER(SEARCH("[B]",INDEX($C15:$G15,$N15))),"B","-")))) | BD15: =IF($O15="","",IF(INDEX($C15:$G15,$O15)="","",IF(ISNUMBER(SEARCH("[A]",INDEX($C15:$G15,$O15))),"A",IF(ISNUMBER(SEARCH("[B]",INDEX($C15:$G15,$O15))),"B","-")))) | BE15: =IF($P15="","",IF(INDEX($C15:$G15,$P15)="","",IF(ISNUMBER(SEARCH("[A]",INDEX($C15:$G15,$P15))),"A",IF(ISNUMBER(SEARCH("[B]",INDEX($C15:$G15,$P15))),"B","-")))) | BF15: =IF($Q15="","",IF(INDEX($C15:$G15,$Q15)="","",IF(ISNUMBER(SEARCH("[A]",INDEX($C15:$G15,$Q15))),"A",IF(ISNUMBER(SEARCH("[B]",INDEX($C15:$G15,$Q15))),"B","-")))) | BG15: =IF($R15="","",IF(INDEX($C15:$G15,$R15)="","",IF(ISNUMBER(SEARCH("[A]",INDEX($C15:$G15,$R15))),"A",IF(ISNUMBER(SEARCH("[B]",INDEX($C15:$G15,$R15))),"B","-")))) | BH15: =IF($S15="","",IF(INDEX($C15:$G15,$S15)="","",IF(ISNUMBER(SEARCH("[A]",INDEX($C15:$G15,$S15))),"A",IF(ISNUMBER(SEARCH("[B]",INDEX($C15:$G15,$S15))),"B","-")))) | BI15: =IF($T15="","",IF(INDEX($C15:$G15,$T15)="","",IF(ISNUMBER(SEARCH("[A]",INDEX($C15:$G15,$T15))),"A",IF(ISNUMBER(SEARCH("[B]",INDEX($C15:$G15,$T15))),"B","-")))) | BJ15: =IF($U15="","",IF(INDEX($C15:$G15,$U15)="","",IF(ISNUMBER(SEARCH("[A]",INDEX($C15:$G15,$U15))),"A",IF(ISNUMBER(SEARCH("[B]",INDEX($C15:$G15,$U15))),"B","-")))) | BK15: =IF($V15="","",IF(INDEX($C15:$G15,$V15)="","",IF(ISNUMBER(SEARCH("[A]",INDEX($C15:$G15,$V15))),"A",IF(ISNUMBER(SEARCH("[B]",INDEX($C15:$G15,$V15))),"B","-")))) | BL15: =IF($W15="","",IF(INDEX($C15:$G15,$W15)="","",IF(ISNUMBER(SEARCH("[A]",INDEX($C15:$G15,$W15))),"A",IF(ISNUMBER(SEARCH("[B]",INDEX($C15:$G15,$W15))),"B","-")))) | BM15: =IF($X15="","",IF(INDEX($C15:$G15,$X15)="","",IF(ISNUMBER(SEARCH("[A]",INDEX($C15:$G15,$X15))),"A",IF(ISNUMBER(SEARCH("[B]",INDEX($C15:$G15,$X15))),"B","-")))) | BN15: =IF($Y15="","",IF(INDEX($C15:$G15,$Y15)="","",IF(ISNUMBER(SEARCH("[A]",INDEX($C15:$G15,$Y15))),"A",IF(ISNUMBER(SEARCH("[B]",INDEX($C15:$G15,$Y15))),"B","-")))) | BO15: =IF($Z15="","",IF(INDEX($C15:$G15,$Z15)="","",IF(ISNUMBER(SEARCH("[A]",INDEX($C15:$G15,$Z15))),"A",IF(ISNUMBER(SEARCH("[B]",INDEX($C15:$G15,$Z15))),"B","-")))) | BP15: =IF($AA15="","",IF(INDEX($C15:$G15,$AA15)="","",IF(ISNUMBER(SEARCH("[A]",INDEX($C15:$G15,$AA15))),"A",IF(ISNUMBER(SEARCH("[B]",INDEX($C15:$G15,$AA15))),"B","-")))) | BQ15: =IF($AB15="","",IF(INDEX($C15:$G15,$AB15)="","",IF(ISNUMBER(SEARCH("[A]",INDEX($C15:$G15,$AB15))),"A",IF(ISNUMBER(SEARCH("[B]",INDEX($C15:$G15,$AB15))),"B","-")))) | BR15: =IF($AC15="","",IF(INDEX($C15:$G15,$AC15)="","",IF(ISNUMBER(SEARCH("[A]",INDEX($C15:$G15,$AC15))),"A",IF(ISNUMBER(SEARCH("[B]",INDEX($C15:$G15,$AC15))),"B","-"))))
A16: 놀이 | B16: 이동 | C16: 자발적 접근 또는 중립 유지 | E16: 회피·후퇴 [B] | F16: 자극 향해 돌진·리드줄 당김 [A] | G16: 프리징(2초 이상 정지)·보호자 뒤로 숨음 [B] | H16: 친밀·애착 | I16: ★ | AD16: ATT | AE16: =IF($J16="","",IF(INDEX($C16:$G16,$J16)="","",$J16)) | AF16: =IF($K16="","",IF(INDEX($C16:$G16,$K16)="","",$K16)) | AG16: =IF($L16="","",IF(INDEX($C16:$G16,$L16)="","",$L16)) | AH16: =IF($M16="","",IF(INDEX($C16:$G16,$M16)="","",$M16)) | AI16: =IF($N16="","",IF(INDEX($C16:$G16,$N16)="","",$N16)) | AJ16: =IF($O16="","",IF(INDEX($C16:$G16,$O16)="","",$O16)) | AK16: =IF($P16="","",IF(INDEX($C16:$G16,$P16)="","",$P16)) | AL16: =IF($Q16="","",IF(INDEX($C16:$G16,$Q16)="","",$Q16)) | AM16: =IF($R16="","",IF(INDEX($C16:$G16,$R16)="","",$R16)) | AN16: =IF($S16="","",IF(INDEX($C16:$G16,$S16)="","",$S16)) | AO16: =IF($T16="","",IF(INDEX($C16:$G16,$T16)="","",$T16)) | AP16: =IF($U16="","",IF(INDEX($C16:$G16,$U16)="","",$U16)) | AQ16: =IF($V16="","",IF(INDEX($C16:$G16,$V16)="","",$V16)) | AR16: =IF($W16="","",IF(INDEX($C16:$G16,$W16)="","",$W16)) | AS16: =IF($X16="","",IF(INDEX($C16:$G16,$X16)="","",$X16)) | AT16: =IF($Y16="","",IF(INDEX($C16:$G16,$Y16)="","",$Y16)) | AU16: =IF($Z16="","",IF(INDEX($C16:$G16,$Z16)="","",$Z16)) | AV16: =IF($AA16="","",IF(INDEX($C16:$G16,$AA16)="","",$AA16)) | AW16: =IF($AB16="","",IF(INDEX($C16:$G16,$AB16)="","",$AB16)) | AX16: =IF($AC16="","",IF(INDEX($C16:$G16,$AC16)="","",$AC16)) | AY16: =IF($J16="","",IF(INDEX($C16:$G16,$J16)="","",IF(ISNUMBER(SEARCH("[A]",INDEX($C16:$G16,$J16))),"A",IF(ISNUMBER(SEARCH("[B]",INDEX($C16:$G16,$J16))),"B","-")))) | AZ16: =IF($K16="","",IF(INDEX($C16:$G16,$K16)="","",IF(ISNUMBER(SEARCH("[A]",INDEX($C16:$G16,$K16))),"A",IF(ISNUMBER(SEARCH("[B]",INDEX($C16:$G16,$K16))),"B","-")))) | BA16: =IF($L16="","",IF(INDEX($C16:$G16,$L16)="","",IF(ISNUMBER(SEARCH("[A]",INDEX($C16:$G16,$L16))),"A",IF(ISNUMBER(SEARCH("[B]",INDEX($C16:$G16,$L16))),"B","-")))) | BB16: =IF($M16="","",IF(INDEX($C16:$G16,$M16)="","",IF(ISNUMBER(SEARCH("[A]",INDEX($C16:$G16,$M16))),"A",IF(ISNUMBER(SEARCH("[B]",INDEX($C16:$G16,$M16))),"B","-")))) | BC16: =IF($N16="","",IF(INDEX($C16:$G16,$N16)="","",IF(ISNUMBER(SEARCH("[A]",INDEX($C16:$G16,$N16))),"A",IF(ISNUMBER(SEARCH("[B]",INDEX($C16:$G16,$N16))),"B","-")))) | BD16: =IF($O16="","",IF(INDEX($C16:$G16,$O16)="","",IF(ISNUMBER(SEARCH("[A]",INDEX($C16:$G16,$O16))),"A",IF(ISNUMBER(SEARCH("[B]",INDEX($C16:$G16,$O16))),"B","-")))) | BE16: =IF($P16="","",IF(INDEX($C16:$G16,$P16)="","",IF(ISNUMBER(SEARCH("[A]",INDEX($C16:$G16,$P16))),"A",IF(ISNUMBER(SEARCH("[B]",INDEX($C16:$G16,$P16))),"B","-")))) | BF16: =IF($Q16="","",IF(INDEX($C16:$G16,$Q16)="","",IF(ISNUMBER(SEARCH("[A]",INDEX($C16:$G16,$Q16))),"A",IF(ISNUMBER(SEARCH("[B]",INDEX($C16:$G16,$Q16))),"B","-")))) | BG16: =IF($R16="","",IF(INDEX($C16:$G16,$R16)="","",IF(ISNUMBER(SEARCH("[A]",INDEX($C16:$G16,$R16))),"A",IF(ISNUMBER(SEARCH("[B]",INDEX($C16:$G16,$R16))),"B","-")))) | BH16: =IF($S16="","",IF(INDEX($C16:$G16,$S16)="","",IF(ISNUMBER(SEARCH("[A]",INDEX($C16:$G16,$S16))),"A",IF(ISNUMBER(SEARCH("[B]",INDEX($C16:$G16,$S16))),"B","-")))) | BI16: =IF($T16="","",IF(INDEX($C16:$G16,$T16)="","",IF(ISNUMBER(SEARCH("[A]",INDEX($C16:$G16,$T16))),"A",IF(ISNUMBER(SEARCH("[B]",INDEX($C16:$G16,$T16))),"B","-")))) | BJ16: =IF($U16="","",IF(INDEX($C16:$G16,$U16)="","",IF(ISNUMBER(SEARCH("[A]",INDEX($C16:$G16,$U16))),"A",IF(ISNUMBER(SEARCH("[B]",INDEX($C16:$G16,$U16))),"B","-")))) | BK16: =IF($V16="","",IF(INDEX($C16:$G16,$V16)="","",IF(ISNUMBER(SEARCH("[A]",INDEX($C16:$G16,$V16))),"A",IF(ISNUMBER(SEARCH("[B]",INDEX($C16:$G16,$V16))),"B","-")))) | BL16: =IF($W16="","",IF(INDEX($C16:$G16,$W16)="","",IF(ISNUMBER(SEARCH("[A]",INDEX($C16:$G16,$W16))),"A",IF(ISNUMBER(SEARCH("[B]",INDEX($C16:$G16,$W16))),"B","-")))) | BM16: =IF($X16="","",IF(INDEX($C16:$G16,$X16)="","",IF(ISNUMBER(SEARCH("[A]",INDEX($C16:$G16,$X16))),"A",IF(ISNUMBER(SEARCH("[B]",INDEX($C16:$G16,$X16))),"B","-")))) | BN16: =IF($Y16="","",IF(INDEX($C16:$G16,$Y16)="","",IF(ISNUMBER(SEARCH("[A]",INDEX($C16:$G16,$Y16))),"A",IF(ISNUMBER(SEARCH("[B]",INDEX($C16:$G16,$Y16))),"B","-")))) | BO16: =IF($Z16="","",IF(INDEX($C16:$G16,$Z16)="","",IF(ISNUMBER(SEARCH("[A]",INDEX($C16:$G16,$Z16))),"A",IF(ISNUMBER(SEARCH("[B]",INDEX($C16:$G16,$Z16))),"B","-")))) | BP16: =IF($AA16="","",IF(INDEX($C16:$G16,$AA16)="","",IF(ISNUMBER(SEARCH("[A]",INDEX($C16:$G16,$AA16))),"A",IF(ISNUMBER(SEARCH("[B]",INDEX($C16:$G16,$AA16))),"B","-")))) | BQ16: =IF($AB16="","",IF(INDEX($C16:$G16,$AB16)="","",IF(ISNUMBER(SEARCH("[A]",INDEX($C16:$G16,$AB16))),"A",IF(ISNUMBER(SEARCH("[B]",INDEX($C16:$G16,$AB16))),"B","-")))) | BR16: =IF($AC16="","",IF(INDEX($C16:$G16,$AC16)="","",IF(ISNUMBER(SEARCH("[A]",INDEX($C16:$G16,$AC16))),"A",IF(ISNUMBER(SEARCH("[B]",INDEX($C16:$G16,$AC16))),"B","-"))))
